Workbook

Sheet Call Stats
B4: Call event type

Sheet Summary
A1: Musters | B1: 3 | C1: 4 | D1: 4 | E1: 5 | F1: 4 | G1: 4 | H1: 4 | I1: 2 | J1: =SUM(B1:I1) -> 30 | K1: 2023 | L1: 3 | M1: 4 | N1: 4 | O1: 5 | P1: 4 | Q1: 4 | R1: 5 | S1: 5 | T1: 5 | U1: 4 | V1: 4 | W1: 3 | X1: 50 | Y1: 2024 | Z1: 3 | AA1: 4 | AB1: 4 | AC1: 5 | AD1: 4 | AE1: 4 | AF1: 5 | AG1: 5 | AH1: 5 | AI1: 4 | AJ1: 4 | AK1: 3 | AL1: 50 | AM1: 2025 | AN1: =(Musters!AN1) -> 4 | AO1: =(Musters!AO1) -> 4 | AP1: =(Musters!AP1) -> 2 | AQ1: =(Musters!AQ1) -> 0 | AR1: =(Musters!AR1) -> 0 | AS1: =(Musters!AS1) -> 0 | AT1: =(Musters!AT1) -> 0 | AU1: =(Musters!AU1) -> 0 | ... AY1: =(Musters!AY1) -> 0 | AZ1: =SUM(AN1:AY1) -> 10 | BA1: 2026 | BB1: Total Calls | BC1: Total
A2: Monthly Call Count | B2: 32 | C2: 46 | D2: 47 | E2: 28 | F2: 38 | G2: 46 | H2: 43 | I2: 44 | J2: =SUM(B2:I2) -> 324 | L2: 58 | M2: 48 | N2: 47 | O2: 38 | P2: 55 | Q2: 43 | R2: 44 | S2: 49 | T2: 36 | U2: 42 | V2: 47 | W2: 52 | X2: =SUM($L$2:$W$2) -> 559 | Z2: 57 | AA2: 48 | AB2: 70 | AC2: 42 | AD2: 68 | AE2: 35 | AF2: 56 | AG2: 53 | AH2: 47 | AI2: 39 | AJ2: 58 | AK2: 79 | AL2: 652 | AN2: =AllCalls26!$D$3 -> 60 | AO2: =AllCalls26!$D$4 -> 44 | AP2: =AllCalls26!$D$5 -> 29 | AQ2: =AllCalls26!$D$6 -> 0 | AR2: =AllCalls26!$D$7 -> 0 | AS2: =AllCalls26!$D$8 -> 0 | AT2: =AllCalls26!$D$9 -> 0 | AU2: =AllCalls26!$D$10 -> 0 | AV2: =AllCalls26!$D$11 -> 0 | AW2: =AllCalls26!$D$12 -> 0 | AX2: =AllCalls26!$D$13 -> 0 | AY2: =AllCalls26!$D$14 -> 0 | AZ2: =SUM(AN2:AY2) -> 133 | BB2: =SUM($J2,$X2,AZ2) -> 1016
A3: Month | B3: May | C3: June | D3: July | E3: August | F3: September | G3: October | H3: November | I3: December | J3: Sum | K3: Totals | L3: January | M3: Febuary | N3: March | O3: April | P3: May | Q3: June | R3: July | S3: August | T3: September | U3: October | V3: November | W3: December | X3: Sum | Y3: Totals | Z3: January | AA3: Febuary | AB3: March | AC3: April | AD3: May | AE3: June | AF3: July | AG3: August | AH3: September | AI3: October | AJ3: November | AK3: December | AL3: Sum | AM3: Totals | AN3: January | AO3: Febuary | AP3: March | AQ3: April | AR3: May | AS3: June | AT3: July | AU3: August | AV3: September | AW3: October | AX3: November | AY3: December | AZ3: Sum | BA3: Totals | BB3: Total Calls | BC3: Average Call Attendance
A4: CFO John Robinson | B4: 21 | C4: 25 | D4: 16 | E4: 15 | F4: 11 | G4: 20 | H4: 18 | I4: 25 | J4: =SUM($B4:$I4) -> 151 | K4: =(J4/$J$2) -> 0.46604938 | L4: 34 | M4: 22 | N4: 22 | O4: 19 | P4: 24 | Q4: 19 | R4: 27 | S4: 18 | T4: 18 | U4: 17 | V4: 16 | W4: 21 | X4: 257 | Y4: 0.46206116 | Z4: 35 | AA4: 27 | AB4: 36 | AC4: 20 | AD4: 29 | AE4: 16 | AF4: 21 | AG4: 18 | AH4: 22 | AI4: 9 | AJ4: 24 | AK4: 50 | AL4: 307 | AM4: 0.4708589 | AN4: =COUNTIFS((AllCalls26!$X$15:$X$5112),"I",(AllCalls26!$K$15:$K$5112),"1") -> 29 | AO4: =COUNTIFS((AllCalls26!$X$15:$X$5112),"I",(AllCalls26!$K$15:$K$5112),"2") -> 25 | AP4: =COUNTIFS((AllCalls26!$X$15:$X$5112),"I",(AllCalls26!$K$15:$K$5112),"3") -> 8 | AQ4: =COUNTIFS((AllCalls26!$X$15:$X$5112),"I",(AllCalls26!$K$15:$K$5112),"4") -> 0 | AR4: =COUNTIFS((AllCalls26!$X$15:$X$5112),"I",(AllCalls26!$K$15:$K$5112),"5") -> 0 | AS4: =COUNTIFS((AllCalls26!$X$15:$X$5112),"I",(AllCalls26!$K$15:$K$5112),"6") -> 0 | AT4: =COUNTIFS((AllCalls26!$X$15:$X$5112),"I",(AllCalls26!$K$15:$K$5112),"7") -> 0 | AU4: =COUNTIFS((AllCalls26!$X$15:$X$5112),"I",(AllCalls26!$K$15:$K$5112),"8") -> 0 | AV4: =COUNTIFS((AllCalls26!$X$15:$X$5112),"I",(AllCalls26!$K$15:$K$5112),"9") -> 0 | AW4: =COUNTIFS((AllCalls26!$X$15:$X$5112),"I",(AllCalls26!$K$15:$K$5112),"10") -> 0 | AX4: =COUNTIFS((AllCalls26!$X$15:$X$5112),"I",(AllCalls26!$K$15:$K$5112),"11") -> 0 | AY4: =COUNTIFS((AllCalls26!$X$15:$X$5112),"I",(AllCalls26!$K$15:$K$5112),"12") -> 0 | AZ4: =SUM($AN4:$AY4) -> 62 | BA4: =(SUM($AZ4))/SUM($AZ$2) -> 0.46616541 | BB4: =SUM($J4,$X4,$AZ4) -> 470 | BC4: =(SUM(BB4))/SUM($BB$2) -> 0.46259843 | BD4: OF
A5: DCFO Bharat Ravji | B5: 14 | C5: 13 | D5: 21 | E5: 15 | F5: 2 | G5: 14 | H5: 26 | I5: 20 | J5: =SUM($B5:$I5) -> 125 | K5: =(J5/$J$2) -> 0.38580247 | L5: 40 | M5: 24 | N5: 17 | O5: 26 | P5: 29 | Q5: 14 | R5: 29 | S5: 24 | T5: 2 | U5: 17 | V5: 19 | W5: 2 | X5: 243 | Y5: 0.41676104 | Z5: 21 | AA5: 32 | AB5: 43 | AC5: 26 | AD5: 37 | AE5: 18 | AF5: 35 | AG5: 33 | AH5: 0 | AI5: 19 | AJ5: 39 | AK5: 57 | AL5: 360 | AM5: 0.55214724 | AN5: =COUNTIFS((AllCalls26!$Y$15:$Y$5112),"I",(AllCalls26!$K$15:$K$5112),"1") -> 32 | AO5: =COUNTIFS((AllCalls26!$Y$15:$Y$5112),"I",(AllCalls26!$K$15:$K$5112),"2") -> 22 | AP5: =COUNTIFS((AllCalls26!$Y$15:$Y$5112),"I",(AllCalls26!$K$15:$K$5112),"3") -> 17 | AQ5: =COUNTIFS((AllCalls26!$Y$15:$Y$5112),"I",(AllCalls26!$K$15:$K$5112),"4") -> 0 | AR5: =COUNTIFS((AllCalls26!$Y$15:$Y$5112),"I",(AllCalls26!$K$15:$K$5112),"5") -> 0 | AS5: =COUNTIFS((AllCalls26!$Y$15:$Y$5112),"I",(AllCalls26!$K$15:$K$5112),"6") -> 0 | AT5: =COUNTIFS((AllCalls26!$Y$15:$Y$5112),"I",(AllCalls26!$K$15:$K$5112),"7") -> 0 | AU5: =COUNTIFS((AllCalls26!$Y$15:$Y$5112),"I",(AllCalls26!$K$15:$K$5112),"8") -> 0 | AV5: =COUNTIFS((AllCalls26!$Y$15:$Y$5112),"I",(AllCalls26!$K$15:$K$5112),"9") -> 0 | AW5: =COUNTIFS((AllCalls26!$Y$15:$Y$5112),"I",(AllCalls26!$K$15:$K$5112),"10") -> 0 | AX5: =COUNTIFS((AllCalls26!$Y$15:$Y$5112),"I",(AllCalls26!$K$15:$K$5112),"11") -> 0 | AY5: =COUNTIFS((AllCalls26!$Y$15:$Y$5112),"I",(AllCalls26!$K$15:$K$5112),"12") -> 0 | AZ5: =SUM($AN5:$AY5) -> 71 | BA5: =(SUM($AZ5))/SUM($AZ$2) -> 0.53383459 | BB5: =SUM($J5,$X5,$AZ5) -> 439 | BC5: =(SUM(BB5))/SUM($BB$2) -> 0.43208661 | BD5: OF
A6: SSO Darcy Hart | B6: 4 | C6: 10 | D6: 10 | E6: 9 | F6: 12 | G6: 18 | H6: 12 | I6: 16 | J6: =SUM($B6:$I6) -> 91 | K6: =(J6/$J$2) -> 0.2808642 | L6: 18 | M6: 13 | N6: 8 | O6: 8 | P6: 10 | Q6: 5 | R6: 17 | S6: 21 | T6: 11 | U6: 17 | V6: 7 | W6: 30 | X6: 165 | Y6: 0.28992072 | Z6: 16 | AA6: 13 | AB6: 11 | AC6: 18 | AD6: 21 | AE6: 6 | AF6: 19 | AG6: 13 | AH6: 12 | AI6: 11 | AJ6: 13 | AK6: 16 | AL6: 169 | AM6: 0.25920245 | AN6: =COUNTIFS((AllCalls26!$Z$15:$Z$5112),"I",(AllCalls26!$K$15:$K$5112),"1") -> 16 | AO6: =COUNTIFS((AllCalls26!$Z$15:$Z$5112),"I",(AllCalls26!$K$15:$K$5112),"2") -> 7 | AP6: =COUNTIFS((AllCalls26!$Z$15:$Z$5112),"I",(AllCalls26!$K$15:$K$5112),"3") -> 6 | AQ6: =COUNTIFS((AllCalls26!$Z$15:$Z$5112),"I",(AllCalls26!$K$15:$K$5112),"4") -> 0 | AR6: =COUNTIFS((AllCalls26!$Z$15:$Z$5112),"I",(AllCalls26!$K$15:$K$5112),"5") -> 0 | AS6: =COUNTIFS((AllCalls26!$Z$15:$Z$5112),"I",(AllCalls26!$K$15:$K$5112),"6") -> 0 | AT6: =COUNTIFS((AllCalls26!$Z$15:$Z$5112),"I",(AllCalls26!$K$15:$K$5112),"7") -> 0 | AU6: =COUNTIFS((AllCalls26!$Z$15:$Z$5112),"I",(AllCalls26!$K$15:$K$5112),"8") -> 0 | AV6: =COUNTIFS((AllCalls26!$Z$15:$Z$5112),"I",(AllCalls26!$K$15:$K$5112),"9") -> 0 | AW6: =COUNTIFS((AllCalls26!$Z$15:$Z$5112),"I",(AllCalls26!$K$15:$K$5112),"10") -> 0 | AX6: =COUNTIFS((AllCalls26!$Z$15:$Z$5112),"I",(AllCalls26!$K$15:$K$5112),"11") -> 0 | AY6: =COUNTIFS((AllCalls26!$Z$15:$Z$5112),"I",(AllCalls26!$K$15:$K$5112),"12") -> 0 | AZ6: =SUM($AN6:$AY6) -> 29 | BA6: =(SUM($AZ6))/SUM($AZ$2) -> 0.21804511 | BB6: =SUM($J6,$X6,$AZ6) -> 285 | BC6: =(SUM(BB6))/SUM($BB$2) -> 0.28051181 | BD6: OF
A7: SSO Vaughan Wood | B7: 21 | C7: 15 | D7: 34 | E7: 9 | F7: 13 | G7: 14 | H7: 26 | I7: 22 | J7: =SUM($B7:$I7) -> 154 | K7: =(J7/$J$2) -> 0.47530864 | L7: 50 | M7: 27 | N7: 17 | O7: 26 | P7: 27 | Q7: 23 | R7: 36 | S7: 27 | T7: 20 | U7: 20 | V7: 30 | W7: 34 | X7: 337 | Y7: 0.55605889 | Z7: 30 | AA7: 33 | AB7: 39 | AC7: 24 | AD7: 21 | AE7: 21 | AF7: 43 | AG7: 33 | AH7: 39 | AI7: 29 | AJ7: 49 | AK7: 70 | AL7: 431 | AM7: 0.66104294 | AN7: =COUNTIFS((AllCalls26!$AA$15:$AA$5112),"I",(AllCalls26!$K$15:$K$5112),"1") -> 49 | AO7: =COUNTIFS((AllCalls26!$AA$15:$AA$5112),"I",(AllCalls26!$K$15:$K$5112),"2") -> 28 | AP7: =COUNTIFS((AllCalls26!$AA$15:$AA$5112),"I",(AllCalls26!$K$15:$K$5112),"3") -> 20 | AQ7: =COUNTIFS((AllCalls26!$AA$15:$AA$5112),"I",(AllCalls26!$K$15:$K$5112),"4") -> 0 | AR7: =COUNTIFS((AllCalls26!$AA$15:$AA$5112),"I",(AllCalls26!$K$15:$K$5112),"5") -> 0 | AS7: =COUNTIFS((AllCalls26!$AA$15:$AA$5112),"I",(AllCalls26!$K$15:$K$5112),"6") -> 0 | AT7: =COUNTIFS((AllCalls26!$AA$15:$AA$5112),"I",(AllCalls26!$K$15:$K$5112),"7") -> 0 | AU7: =COUNTIFS((AllCalls26!$AA$15:$AA$5112),"I",(AllCalls26!$K$15:$K$5112),"8") -> 0 | AV7: =COUNTIFS((AllCalls26!$AA$15:$AA$5112),"I",(AllCalls26!$K$15:$K$5112),"9") -> 0 | AW7: =COUNTIFS((AllCalls26!$AA$15:$AA$5112),"I",(AllCalls26!$K$15:$K$5112),"10") -> 0 | AX7: =COUNTIFS((AllCalls26!$AA$15:$AA$5112),"I",(AllCalls26!$K$15:$K$5112),"11") -> 0 | AY7: =COUNTIFS((AllCalls26!$AA$15:$AA$5112),"I",(AllCalls26!$K$15:$K$5112),"12") -> 0 | AZ7: =SUM($AN7:$AY7) -> 97 | BA7: =(SUM($AZ7))/SUM($AZ$2) -> 0.72932331 | BB7: =SUM($J7,$X7,$AZ7) -> 588 | BC7: =(SUM(BB7))/SUM($BB$2) -> 0.57874016 | BD7: OF
A8: SO Richard Jellyman | B8: 8 | C8: 23 | D8: 22 | E8: 10 | F8: 10 | G8: 25 | H8: 13 | I8: 10 | J8: =SUM($B8:$I8) -> 121 | K8: =(J8/$J$2) -> 0.37345679 | L8: 3 | M8: 11 | N8: 19 | O8: 8 | P8: 12 | Q8: 2 | R8: 14 | S8: 20 | T8: 6 | U8: 6 | V8: 21 | W8: 23 | X8: 145 | Y8: 0.30124575 | Z8: 19 | AA8: 15 | AB8: 26 | AC8: 26 | AD8: 40 | AE8: 18 | AF8: 29 | AG8: 0 | AH8: 16 | AI8: 9 | AJ8: 8 | AK8: 28 | AL8: 234 | AM8: 0.35889571 | AN8: =COUNTIFS((AllCalls26!$AB$15:$AB$5112),"I",(AllCalls26!$K$15:$K$5112),"1") -> 16 | AO8: =COUNTIFS((AllCalls26!$AB$15:$AB$5112),"I",(AllCalls26!$K$15:$K$5112),"2") -> 18 | AP8: =COUNTIFS((AllCalls26!$AB$15:$AB$5112),"I",(AllCalls26!$K$15:$K$5112),"3") -> 16 | AQ8: =COUNTIFS((AllCalls26!$AB$15:$AB$5112),"I",(AllCalls26!$K$15:$K$5112),"4") -> 0 | AR8: =COUNTIFS((AllCalls26!$AB$15:$AB$5112),"I",(AllCalls26!$K$15:$K$5112),"5") -> 0 | AS8: =COUNTIFS((AllCalls26!$AB$15:$AB$5112),"I",(AllCalls26!$K$15:$K$5112),"6") -> 0 | AT8: =COUNTIFS((AllCalls26!$AB$15:$AB$5112),"I",(AllCalls26!$K$15:$K$5112),"7") -> 0 | AU8: =COUNTIFS((AllCalls26!$AB$15:$AB$5112),"I",(AllCalls26!$K$15:$K$5112),"8") -> 0 | AV8: =COUNTIFS((AllCalls26!$AB$15:$AB$5112),"I",(AllCalls26!$K$15:$K$5112),"9") -> 0 | AW8: =COUNTIFS((AllCalls26!$AB$15:$AB$5112),"I",(AllCalls26!$K$15:$K$5112),"10") -> 0 | AX8: =COUNTIFS((AllCalls26!$AB$15:$AB$5112),"I",(AllCalls26!$K$15:$K$5112),"11") -> 0 | AY8: =COUNTIFS((AllCalls26!$AB$15:$AB$5112),"I",(AllCalls26!$K$15:$K$5112),"12") -> 0 | AZ8: =SUM($AN8:$AY8) -> 50 | BA8: =(SUM($AZ8))/SUM($AZ$2) -> 0.37593985 | BB8: =SUM($J8,$X8,$AZ8) -> 316 | BC8: =(SUM(BB8))/SUM($BB$2) -> 0.31102362 | BD8: OF
A9: SO Richard Irving | B9: 18 | C9: 17 | D9: 21 | E9: 7 | F9: 18 | G9: 10 | H9: 7 | I9: 7 | J9: =SUM($B9:$I9) -> 105 | K9: =(J9/$J$2) -> 0.32407407 | L9: 12 | M9: 13 | N9: 2 | O9: 10 | P9: 32 | Q9: 3 | R9: 4 | S9: 12 | T9: 14 | U9: 4 | V9: 5 | W9: 25 | X9: 136 | Y9: 0.27293318 | Z9: 13 | AA9: 7 | AB9: 11 | AC9: 8 | AD9: 19 | AE9: 12 | AF9: 18 | AG9: 5 | AH9: 8 | AI9: 2 | AJ9: 19 | AK9: 6 | AL9: 128 | AM9: 0.19631902 | AN9: =COUNTIFS((AllCalls26!$AC$15:$AC$5112),"I",(AllCalls26!$K$15:$K$5112),"1") -> 13 | AO9: =COUNTIFS((AllCalls26!$AC$15:$AC$5112),"I",(AllCalls26!$K$15:$K$5112),"2") -> 17 | AP9: =COUNTIFS((AllCalls26!$AC$15:$AC$5112),"I",(AllCalls26!$K$15:$K$5112),"3") -> 4 | AQ9: =COUNTIFS((AllCalls26!$AC$15:$AC$5112),"I",(AllCalls26!$K$15:$K$5112),"4") -> 0 | AR9: =COUNTIFS((AllCalls26!$AC$15:$AC$5112),"I",(AllCalls26!$K$15:$K$5112),"5") -> 0 | AS9: =COUNTIFS((AllCalls26!$AC$15:$AC$5112),"I",(AllCalls26!$K$15:$K$5112),"6") -> 0 | AT9: =COUNTIFS((AllCalls26!$AC$15:$AC$5112),"I",(AllCalls26!$K$15:$K$5112),"7") -> 0 | AU9: =COUNTIFS((AllCalls26!$AC$15:$AC$5112),"I",(AllCalls26!$K$15:$K$5112),"8") -> 0 | AV9: =COUNTIFS((AllCalls26!$AC$15:$AC$5112),"I",(AllCalls26!$K$15:$K$5112),"9") -> 0 | AW9: =COUNTIFS((AllCalls26!$AC$15:$AC$5112),"I",(AllCalls26!$K$15:$K$5112),"10") -> 0 | AX9: =COUNTIFS((AllCalls26!$AC$15:$AC$5112),"I",(AllCalls26!$K$15:$K$5112),"11") -> 0 | AY9: =COUNTIFS((AllCalls26!$AC$15:$AC$5112),"I",(AllCalls26!$K$15:$K$5112),"12") -> 0 | AZ9: =SUM($AN9:$AY9) -> 34 | BA9: =(SUM($AZ9))/SUM($AZ$2) -> 0.2556391 | BB9: =SUM($J9,$X9,$AZ9) -> 275 | BC9: =(SUM(BB9))/SUM($BB$2) -> 0.27066929 | BD9: OF
A10: SO Jon White | B10: 7 | C10: 0 | D10: 13 | E10: 11 | F10: 14 | G10: 30 | H10: 14 | I10: 22 | J10: =SUM($B10:$I10) -> 111 | K10: =(J10/$J$2) -> 0.34259259 | L10: 27 | M10: 21 | N10: 19 | O10: 17 | P10: 20 | Q10: 18 | R10: 18 | S10: 20 | T10: 14 | U10: 21 | V10: 17 | W10: 18 | X10: 230 | Y10: 0.38618347 | Z10: 13 | AA10: 0 | AB10: 3 | AC10: 8 | AD10: 28 | AE10: 14 | AF10: 14 | AG10: 23 | AH10: 16 | AI10: 11 | AJ10: 18 | AK10: 39 | AL10: 187 | AM10: 0.28680982 | AN10: =COUNTIFS((AllCalls26!$AD$15:$AD$5112),"I",(AllCalls26!$K$15:$K$5112),"1") -> 20 | AO10: =COUNTIFS((AllCalls26!$AD$15:$AD$5112),"I",(AllCalls26!$K$15:$K$5112),"2") -> 18 | AP10: =COUNTIFS((AllCalls26!$AD$15:$AD$5112),"I",(AllCalls26!$K$15:$K$5112),"3") -> 12 | AQ10: =COUNTIFS((AllCalls26!$AD$15:$AD$5112),"I",(AllCalls26!$K$15:$K$5112),"4") -> 0 | AR10: =COUNTIFS((AllCalls26!$AD$15:$AD$5112),"I",(AllCalls26!$K$15:$K$5112),"5") -> 0 | AS10: =COUNTIFS((AllCalls26!$AD$15:$AD$5112),"I",(AllCalls26!$K$15:$K$5112),"6") -> 0 | AT10: =COUNTIFS((AllCalls26!$AD$15:$AD$5112),"I",(AllCalls26!$K$15:$K$5112),"7") -> 0 | AU10: =COUNTIFS((AllCalls26!$AD$15:$AD$5112),"I",(AllCalls26!$K$15:$K$5112),"8") -> 0 | AV10: =COUNTIFS((AllCalls26!$AD$15:$AD$5112),"I",(AllCalls26!$K$15:$K$5112),"9") -> 0 | AW10: =COUNTIFS((AllCalls26!$AD$15:$AD$5112),"I",(AllCalls26!$K$15:$K$5112),"10") -> 0 | AX10: =COUNTIFS((AllCalls26!$AD$15:$AD$5112),"I",(AllCalls26!$K$15:$K$5112),"11") -> 0 | AY10: =COUNTIFS((AllCalls26!$AD$15:$AD$5112),"I",(AllCalls26!$K$15:$K$5112),"12") -> 0 | AZ10: =SUM($AN10:$AY10) -> 50 | BA10: =(SUM($AZ10))/SUM($AZ$2) -> 0.37593985 | BB10: =SUM($J10,$X10,$AZ10) -> 391 | BC10: =(SUM(BB10))/SUM($BB$2) -> 0.38484252 | BD10: OF
A11: SO William O'Connell | B11: 9 | C11: 11 | D11: 13 | E11: 9 | F11: 13 | G11: 12 | H11: 7 | I11: 13 | J11: =SUM($B11:$I11) -> 87 | K11: =(J11/$J$2) -> 0.26851852 | L11: 15 | M11: 20 | N11: 11 | O11: 6 | P11: 15 | Q11: 12 | R11: 12 | S11: 16 | T11: 12 | U11: 15 | V11: 26 | W11: 19 | X11: 179 | Y11: 0.30124575 | Z11: 23 | AA11: 14 | AB11: 19 | AC11: 12 | AD11: 19 | AE11: 13 | AF11: 8 | AG11: 25 | AH11: 10 | AI11: 17 | AJ11: 11 | AK11: 47 | AL11: 218 | AM11: 0.33435583 | AN11: =COUNTIFS((AllCalls26!$AE$15:$AE$5112),"I",(AllCalls26!$K$15:$K$5112),"1") -> 23 | AO11: =COUNTIFS((AllCalls26!$AE$15:$AE$5112),"I",(AllCalls26!$K$15:$K$5112),"2") -> 13 | AP11: =COUNTIFS((AllCalls26!$AE$15:$AE$5112),"I",(AllCalls26!$K$15:$K$5112),"3") -> 7 | AQ11: =COUNTIFS((AllCalls26!$AE$15:$AE$5112),"I",(AllCalls26!$K$15:$K$5112),"4") -> 0 | AR11: =COUNTIFS((AllCalls26!$AE$15:$AE$5112),"I",(AllCalls26!$K$15:$K$5112),"5") -> 0 | AS11: =COUNTIFS((AllCalls26!$AE$15:$AE$5112),"I",(AllCalls26!$K$15:$K$5112),"6") -> 0 | AT11: =COUNTIFS((AllCalls26!$AE$15:$AE$5112),"I",(AllCalls26!$K$15:$K$5112),"7") -> 0 | AU11: =COUNTIFS((AllCalls26!$AE$15:$AE$5112),"I",(AllCalls26!$K$15:$K$5112),"8") -> 0 | AV11: =COUNTIFS((AllCalls26!$AE$15:$AE$5112),"I",(AllCalls26!$K$15:$K$5112),"9") -> 0 | AW11: =COUNTIFS((AllCalls26!$AE$15:$AE$5112),"I",(AllCalls26!$K$15:$K$5112),"10") -> 0 | AX11: =COUNTIFS((AllCalls26!$AE$15:$AE$5112),"I",(AllCalls26!$K$15:$K$5112),"11") -> 0 | AY11: =COUNTIFS((AllCalls26!$AE$15:$AE$5112),"I",(AllCalls26!$K$15:$K$5112),"12") -> 0 | AZ11: =SUM($AN11:$AY11) -> 43 | BA11: =(SUM($AZ11))/SUM($AZ$2) -> 0.32330827 | BB11: =SUM($J11,$X11,$AZ11) -> 309 | BC11: =(SUM(BB11))/SUM($BB$2) -> 0.30413386 | BD11: OF
A12: SFF Brent Reynolds | B12: 7 | C12: 11 | D12: 11 | E12: 11 | F12: 6 | G12: 9 | H12: 5 | I12: 10 | J12: =SUM($B12:$I12) -> 70 | K12: =(J12/$J$2) -> 0.21604938 | L12: 12 | M12: 11 | N12: 5 | O12: 10 | P12: 9 | Q12: 4 | R12: 10 | S12: 4 | T12: 5 | U12: 21 | V12: 25 | W12: 27 | X12: 143 | Y12: 0.2412231 | Z12: 14 | AA12: 4 | AB12: 15 | AC12: 17 | AD12: 22 | AE12: 9 | AF12: 17 | AG12: 7 | AH12: 3 | AI12: 8 | AJ12: 14 | AK12: 3 | AL12: 133 | AM12: 0.20398773 | AN12: =COUNTIFS((AllCalls26!$AF$15:$AF$5112),"I",(AllCalls26!$K$15:$K$5112),"1") -> 5 | AO12: =COUNTIFS((AllCalls26!$AF$15:$AF$5112),"I",(AllCalls26!$K$15:$K$5112),"2") -> 5 | AP12: =COUNTIFS((AllCalls26!$AF$15:$AF$5112),"I",(AllCalls26!$K$15:$K$5112),"3") -> 4 | AQ12: =COUNTIFS((AllCalls26!$AF$15:$AF$5112),"I",(AllCalls26!$K$15:$K$5112),"4") -> 0 | AR12: =COUNTIFS((AllCalls26!$AF$15:$AF$5112),"I",(AllCalls26!$K$15:$K$5112),"5") -> 0 | AS12: =COUNTIFS((AllCalls26!$AF$15:$AF$5112),"I",(AllCalls26!$K$15:$K$5112),"6") -> 0 | AT12: =COUNTIFS((AllCalls26!$AF$15:$AF$5112),"I",(AllCalls26!$K$15:$K$5112),"7") -> 0 | AU12: =COUNTIFS((AllCalls26!$AF$15:$AF$5112),"I",(AllCalls26!$K$15:$K$5112),"8") -> 0 | AV12: =COUNTIFS((AllCalls26!$AF$15:$AF$5112),"I",(AllCalls26!$K$15:$K$5112),"9") -> 0 | AW12: =COUNTIFS((AllCalls26!$AF$15:$AF$5112),"I",(AllCalls26!$K$15:$K$5112),"10") -> 0 | AX12: =COUNTIFS((AllCalls26!$AF$15:$AF$5112),"I",(AllCalls26!$K$15:$K$5112),"11") -> 0 | AY12: =COUNTIFS((AllCalls26!$AF$15:$AF$5112),"I",(AllCalls26!$K$15:$K$5112),"12") -> 0 | AZ12: =SUM($AN12:$AY12) -> 14 | BA12: =(SUM($AZ12))/SUM($AZ$2) -> 0.10526316 | BB12: =SUM($J12,$X12,$AZ12) -> 227 | BC12: =(SUM(BB12))/SUM($BB$2) -> 0.2234252 | BD12: DR*
A13: SFF Joseph O'Neill-Gregory | B13: 8 | C13: 17 | D13: 19 | E13: 4 | F13: 1 | G13: 22 | H13: 14 | I13: 12 | J13: =SUM($B13:$I13) -> 97 | K13: =(J13/$J$2) -> 0.29938272 | L13: 21 | M13: 13 | N13: 3 | O13: 15 | P13: 16 | Q13: 12 | R13: 5 | S13: 0 | T13: 3 | U13: 13 | V13: 14 | W13: 19 | X13: 134 | Y13: 0.26160815 | Z13: 16 | AA13: 11 | AB13: 8 | AC13: 5 | AD13: 14 | AE13: 10 | AF13: 11 | AG13: 13 | AH13: 3 | AI13: 6 | AJ13: 8 | AK13: 37 | AL13: 142 | AM13: 0.21779141 | AN13: =COUNTIFS((AllCalls26!$AG$15:$AG$5112),"I",(AllCalls26!$K$15:$K$5112),"1") -> 4 | AO13: =COUNTIFS((AllCalls26!$AG$15:$AG$5112),"I",(AllCalls26!$K$15:$K$5112),"2") -> 4 | AP13: =COUNTIFS((AllCalls26!$AG$15:$AG$5112),"I",(AllCalls26!$K$15:$K$5112),"3") -> 2 | AQ13: =COUNTIFS((AllCalls26!$AG$15:$AG$5112),"I",(AllCalls26!$K$15:$K$5112),"4") -> 0 | AR13: =COUNTIFS((AllCalls26!$AG$15:$AG$5112),"I",(AllCalls26!$K$15:$K$5112),"5") -> 0 | AS13: =COUNTIFS((AllCalls26!$AG$15:$AG$5112),"I",(AllCalls26!$K$15:$K$5112),"6") -> 0 | AT13: =COUNTIFS((AllCalls26!$AG$15:$AG$5112),"I",(AllCalls26!$K$15:$K$5112),"7") -> 0 | AU13: =COUNTIFS((AllCalls26!$AG$15:$AG$5112),"I",(AllCalls26!$K$15:$K$5112),"8") -> 0 | AV13: =COUNTIFS((AllCalls26!$AG$15:$AG$5112),"I",(AllCalls26!$K$15:$K$5112),"9") -> 0 | AW13: =COUNTIFS((AllCalls26!$AG$15:$AG$5112),"I",(AllCalls26!$K$15:$K$5112),"10") -> 0 | AX13: =COUNTIFS((AllCalls26!$AG$15:$AG$5112),"I",(AllCalls26!$K$15:$K$5112),"11") -> 0 | AY13: =COUNTIFS((AllCalls26!$AG$15:$AG$5112),"I",(AllCalls26!$K$15:$K$5112),"12") -> 0 | AZ13: =SUM($AN13:$AY13) -> 10 | BA13: =(SUM($AZ13))/SUM($AZ$2) -> 0.07518797 | BB13: =SUM($J13,$X13,$AZ13) -> 241 | BC13: =(SUM(BB13))/SUM($BB$2) -> 0.23720472 | BD13: DR
A14: SFF Grant Robertson | B14: 22 | C14: 33 | D14: 27 | E14: 12 | F14: 18 | G14: 21 | H14: 11 | I14: 16 | J14: =SUM($B14:$I14) -> 160 | K14: =(J14/$J$2) -> 0.49382716 | L14: 24 | M14: 20 | N14: 24 | O14: 23 | P14: 33 | Q14: 21 | R14: 27 | S14: 28 | T14: 25 | U14: 29 | V14: 21 | W14: 24 | X14: 299 | Y14: 0.5198188 | Z14: 32 | AA14: 32 | AB14: 33 | AC14: 30 | AD14: 31 | AE14: 12 | AF14: 40 | AG14: 38 | AH14: 32 | AI14: 28 | AJ14: 38 | AK14: 61 | AL14: 407 | AM14: 0.62423313 | AN14: =COUNTIFS((AllCalls26!$AH$15:$AH$5112),"I",(AllCalls26!$K$15:$K$5112),"1") -> 43 | AO14: =COUNTIFS((AllCalls26!$AH$15:$AH$5112),"I",(AllCalls26!$K$15:$K$5112),"2") -> 23 | AP14: =COUNTIFS((AllCalls26!$AH$15:$AH$5112),"I",(AllCalls26!$K$15:$K$5112),"3") -> 17 | AQ14: =COUNTIFS((AllCalls26!$AH$15:$AH$5112),"I",(AllCalls26!$K$15:$K$5112),"4") -> 0 | AR14: =COUNTIFS((AllCalls26!$AH$15:$AH$5112),"I",(AllCalls26!$K$15:$K$5112),"5") -> 0 | AS14: =COUNTIFS((AllCalls26!$AH$15:$AH$5112),"I",(AllCalls26!$K$15:$K$5112),"6") -> 0 | AT14: =COUNTIFS((AllCalls26!$AH$15:$AH$5112),"I",(AllCalls26!$K$15:$K$5112),"7") -> 0 | AU14: =COUNTIFS((AllCalls26!$AH$15:$AH$5112),"I",(AllCalls26!$K$15:$K$5112),"8") -> 0 | AV14: =COUNTIFS((AllCalls26!$AH$15:$AH$5112),"I",(AllCalls26!$K$15:$K$5112),"9") -> 0 | AW14: =COUNTIFS((AllCalls26!$AH$15:$AH$5112),"I",(AllCalls26!$K$15:$K$5112),"10") -> 0 | AX14: =COUNTIFS((AllCalls26!$AH$15:$AH$5112),"I",(AllCalls26!$K$15:$K$5112),"11") -> 0 | AY14: =COUNTIFS((AllCalls26!$AH$15:$AH$5112),"I",(AllCalls26!$K$15:$K$5112),"12") -> 0 | AZ14: =SUM($AN14:$AY14) -> 83 | BA14: =(SUM($AZ14))/SUM($AZ$2) -> 0.62406015 | BB14: =SUM($J14,$X14,$AZ14) -> 542 | BC14: =(SUM(BB14))/SUM($BB$2) -> 0.53346457 | BD14: DR*
A15: SFF William O'Connell | B15: 9 | C15: 11 | D15: 13 | E15: 9 | F15: 13 | G15: 12 | H15: 7 | I15: 13 | J15: =SUM($B15:$I15) -> 87 | K15: =(J15/$J$2) -> 0.26851852 | L15: 15 | M15: 20 | N15: 11 | O15: 6 | P15: 15 | Q15: 12 | R15: 12 | S15: 16 | T15: 12 | U15: 15 | V15: 26 | W15: 19 | X15: 179 | Y15: 0.30124575 | Z15: 23 | AA15: 14 | AB15: 19 | AC15: 12 | AD15: 19 | AE15: 13 | AF15: 8 | AG15: 25 | AH15: 10 | AI15: 17 | AJ15: 11 | AK15: 47 | AL15: 218 | AM15: 0.33435583 | AN15: =COUNTIFS((AllCalls26!$AI$15:$AI$5112),"I",(AllCalls26!$K$15:$K$5112),"1") -> 23 | AO15: =COUNTIFS((AllCalls26!$AI$15:$AI$5112),"I",(AllCalls26!$K$15:$K$5112),"2") -> 13 | AP15: =COUNTIFS((AllCalls26!$AI$15:$AI$5112),"I",(AllCalls26!$K$15:$K$5112),"3") -> 7 | AQ15: =COUNTIFS((AllCalls26!$AI$15:$AI$5112),"I",(AllCalls26!$K$15:$K$5112),"4") -> 0 | AR15: =COUNTIFS((AllCalls26!$AI$15:$AI$5112),"I",(AllCalls26!$K$15:$K$5112),"5") -> 0 | AS15: =COUNTIFS((AllCalls26!$AI$15:$AI$5112),"I",(AllCalls26!$K$15:$K$5112),"6") -> 0 | AT15: =COUNTIFS((AllCalls26!$AI$15:$AI$5112),"I",(AllCalls26!$K$15:$K$5112),"7") -> 0 | AU15: =COUNTIFS((AllCalls26!$AI$15:$AI$5112),"I",(AllCalls26!$K$15:$K$5112),"8") -> 0 | AV15: =COUNTIFS((AllCalls26!$AI$15:$AI$5112),"I",(AllCalls26!$K$15:$K$5112),"9") -> 0 | AW15: =COUNTIFS((AllCalls26!$AI$15:$AI$5112),"I",(AllCalls26!$K$15:$K$5112),"10") -> 0 | AX15: =COUNTIFS((AllCalls26!$AI$15:$AI$5112),"I",(AllCalls26!$K$15:$K$5112),"11") -> 0 | AY15: =COUNTIFS((AllCalls26!$AI$15:$AI$5112),"I",(AllCalls26!$K$15:$K$5112),"12") -> 0 | AZ15: =SUM($AN15:$AY15) -> 43 | BA15: =(SUM($AZ15))/SUM($AZ$2) -> 0.32330827 | BB15: =SUM($J15,$X15,$AZ15) -> 309 | BC15: =(SUM(BB15))/SUM($BB$2) -> 0.30413386 | BD15: DR*
A16: SFF Robert Mayo | B16: 9 | C16: 15 | D16: 13 | E16: 12 | F16: 12 | G16: 11 | H16: 17 | I16: 3 | J16: =SUM($B16:$I16) -> 92 | K16: =(J16/$J$2) -> 0.28395062 | L16: 20 | M16: 15 | N16: 16 | O16: 14 | P16: 27 | Q16: 17 | R16: 10 | S16: 15 | T16: 13 | U16: 9 | V16: 16 | W16: 17 | X16: 189 | Y16: 0.3182333 | Z16: 30 | AA16: 31 | AB16: 38 | AC16: 24 | AD16: 41 | AE16: 25 | AF16: 33 | AG16: 37 | AH16: 32 | AI16: 22 | AJ16: 46 | AK16: 33 | AL16: 392 | AM16: 0.60122699 | AN16: =COUNTIFS((AllCalls26!$AJ$15:$AJ$5112),"I",(AllCalls26!$K$15:$K$5112),"1") -> 35 | AO16: =COUNTIFS((AllCalls26!$AJ$15:$AJ$5112),"I",(AllCalls26!$K$15:$K$5112),"2") -> 32 | AP16: =COUNTIFS((AllCalls26!$AJ$15:$AJ$5112),"I",(AllCalls26!$K$15:$K$5112),"3") -> 19 | AQ16: =COUNTIFS((AllCalls26!$AJ$15:$AJ$5112),"I",(AllCalls26!$K$15:$K$5112),"4") -> 0 | AR16: =COUNTIFS((AllCalls26!$AJ$15:$AJ$5112),"I",(AllCalls26!$K$15:$K$5112),"5") -> 0 | AS16: =COUNTIFS((AllCalls26!$AJ$15:$AJ$5112),"I",(AllCalls26!$K$15:$K$5112),"6") -> 0 | AT16: =COUNTIFS((AllCalls26!$AJ$15:$AJ$5112),"I",(AllCalls26!$K$15:$K$5112),"7") -> 0 | AU16: =COUNTIFS((AllCalls26!$AJ$15:$AJ$5112),"I",(AllCalls26!$K$15:$K$5112),"8") -> 0 | AV16: =COUNTIFS((AllCalls26!$AJ$15:$AJ$5112),"I",(AllCalls26!$K$15:$K$5112),"9") -> 0 | AW16: =COUNTIFS((AllCalls26!$AJ$15:$AJ$5112),"I",(AllCalls26!$K$15:$K$5112),"10") -> 0 | AX16: =COUNTIFS((AllCalls26!$AJ$15:$AJ$5112),"I",(AllCalls26!$K$15:$K$5112),"11") -> 0 | AY16: =COUNTIFS((AllCalls26!$AJ$15:$AJ$5112),"I",(AllCalls26!$K$15:$K$5112),"12") -> 0 | AZ16: =SUM($AN16:$AY16) -> 86 | BA16: =(SUM($AZ16))/SUM($AZ$2) -> 0.64661654 | BB16: =SUM($J16,$X16,$AZ16) -> 367 | BC16: =(SUM(BB16))/SUM($BB$2) -> 0.36122047 | BD16: DR
A17: SFF Brody Jellyman | X17: 0 | Z17: 7 | AA17: 22 | AB17: 28 | AC17: 18 | AD17: 32 | AE17: 13 | AF17: 22 | AG17: 24 | AH17: 16 | AI17: 12 | AJ17: 20 | AK17: 29 | AL17: 243 | AM17: 0.39663866 | AN17: =COUNTIFS((AllCalls26!$AK$15:$AK$5112),"I",(AllCalls26!$K$15:$K$5112),"1") -> 3 | AO17: =COUNTIFS((AllCalls26!$AK$15:$AK$5112),"I",(AllCalls26!$K$15:$K$5112),"2") -> 7 | AP17: =COUNTIFS((AllCalls26!$AK$15:$AK$5112),"I",(AllCalls26!$K$15:$K$5112),"3") -> 12 | AQ17: =COUNTIFS((AllCalls26!$AK$15:$AK$5112),"I",(AllCalls26!$K$15:$K$5112),"4") -> 0 | AR17: =COUNTIFS((AllCalls26!$AK$15:$AK$5112),"I",(AllCalls26!$K$15:$K$5112),"5") -> 0 | AS17: =COUNTIFS((AllCalls26!$AK$15:$AK$5112),"I",(AllCalls26!$K$15:$K$5112),"6") -> 0 | AT17: =COUNTIFS((AllCalls26!$AK$15:$AK$5112),"I",(AllCalls26!$K$15:$K$5112),"7") -> 0 | AU17: =COUNTIFS((AllCalls26!$AK$15:$AK$5112),"I",(AllCalls26!$K$15:$K$5112),"8") -> 0 | AV17: =COUNTIFS((AllCalls26!$AK$15:$AK$5112),"I",(AllCalls26!$K$15:$K$5112),"9") -> 0 | AW17: =COUNTIFS((AllCalls26!$AK$15:$AK$5112),"I",(AllCalls26!$K$15:$K$5112),"10") -> 0 | AX17: =COUNTIFS((AllCalls26!$AK$15:$AK$5112),"I",(AllCalls26!$K$15:$K$5112),"11") -> 0 | AY17: =COUNTIFS((AllCalls26!$AK$15:$AK$5112),"I",(AllCalls26!$K$15:$K$5112),"12") -> 0 | AZ17: =SUM($AN17:$AY17) -> 22 | BA17: =(SUM($AN17:$AY17))/SUM($AN$2:$AY$2) -> 0.16541353 | BB17: =SUM($AZ17,$AL17) -> 265 | BC17: =(SUM(BB17))/SUM($AA$2:$AK$2,AZ2) -> 0.36401099 | BD17: DR
A18: SFF Darryn Pritchard | B18: 16 | C18: 34 | D18: 31 | E18: 13 | F18: 10 | G18: 17 | H18: 23 | I18: 22 | J18: =SUM($B18:$I18) -> 166 | K18: =(J18/$J$2) -> 0.51234568 | L18: 13 | M18: 30 | N18: 30 | O18: 21 | P18: 33 | Q18: 2 | R18: 22 | S18: 8 | T18: 13 | U18: 18 | V18: 20 | W18: 27 | X18: 237 | Y18: 0.45639864 | Z18: 2 | AA18: 6 | AB18: 26 | AC18: 19 | AD18: 22 | AE18: 17 | AF18: 23 | AG18: 27 | AH18: 20 | AI18: 12 | AJ18: 21 | AK18: 17 | AL18: 212 | AM18: 0.32515337 | AN18: =COUNTIFS((AllCalls26!$AL$15:$AL$5112),"I",(AllCalls26!$K$15:$K$5112),"1") -> 5 | AO18: =COUNTIFS((AllCalls26!$AL$15:$AL$5112),"I",(AllCalls26!$K$15:$K$5112),"2") -> 9 | AP18: =COUNTIFS((AllCalls26!$AL$15:$AL$5112),"I",(AllCalls26!$K$15:$K$5112),"3") -> 0 | AQ18: =COUNTIFS((AllCalls26!$AL$15:$AL$5112),"I",(AllCalls26!$K$15:$K$5112),"4") -> 0 | AR18: =COUNTIFS((AllCalls26!$AL$15:$AL$5112),"I",(AllCalls26!$K$15:$K$5112),"5") -> 0 | AS18: =COUNTIFS((AllCalls26!$AL$15:$AL$5112),"I",(AllCalls26!$K$15:$K$5112),"6") -> 0 | AT18: =COUNTIFS((AllCalls26!$AL$15:$AL$5112),"I",(AllCalls26!$K$15:$K$5112),"7") -> 0 | AU18: =COUNTIFS((AllCalls26!$AL$15:$AL$5112),"I",(AllCalls26!$K$15:$K$5112),"8") -> 0 | AV18: =COUNTIFS((AllCalls26!$AL$15:$AL$5112),"I",(AllCalls26!$K$15:$K$5112),"9") -> 0 | AW18: =COUNTIFS((AllCalls26!$AL$15:$AL$5112),"I",(AllCalls26!$K$15:$K$5112),"10") -> 0 | AX18: =COUNTIFS((AllCalls26!$AL$15:$AL$5112),"I",(AllCalls26!$K$15:$K$5112),"11") -> 0 | AY18: =COUNTIFS((AllCalls26!$AL$15:$AL$5112),"I",(AllCalls26!$K$15:$K$5112),"12") -> 0 | AZ18: =SUM($AN18:$AY18) -> 14 | BA18: =(SUM($AZ18))/SUM($AZ$2) -> 0.10526316 | BB18: =SUM($J18,$X18,$AZ18) -> 417 | BC18: =(SUM(BB18))/SUM($BB$2) -> 0.41043307 | BD18: DR*
A19: QFF Symon Maxwell | B19: 4 | C19: 21 | D19: 17 | E19: 15 | F19: 16 | G19: 28 | H19: 22 | I19: 17 | J19: =SUM($B19:$I19) -> 140 | K19: =(J19/$J$2) -> 0.43209877 | L19: 34 | M19: 22 | N19: 16 | O19: 21 | P19: 25 | Q19: 12 | R19: 18 | S19: 22 | T19: 15 | U19: 25 | V19: 23 | W19: 20 | X19: 253 | Y19: 0.44507361 | Z19: 28 | AA19: 15 | AB19: 17 | AC19: 21 | AD19: 24 | AE19: 19 | AF19: 25 | AG19: 18 | AH19: 8 | AI19: 16 | AJ19: 16 | AK19: 12 | AL19: 219 | AM19: 0.33588957 | AN19: =COUNTIFS((AllCalls26!$AM$15:$AM$5112),"I",(AllCalls26!$K$15:$K$5112),"1") -> 16 | AO19: =COUNTIFS((AllCalls26!$AM$15:$AM$5112),"I",(AllCalls26!$K$15:$K$5112),"2") -> 10 | AP19: =COUNTIFS((AllCalls26!$AM$15:$AM$5112),"I",(AllCalls26!$K$15:$K$5112),"3") -> 9 | AQ19: =COUNTIFS((AllCalls26!$AM$15:$AM$5112),"I",(AllCalls26!$K$15:$K$5112),"4") -> 0 | AR19: =COUNTIFS((AllCalls26!$AM$15:$AM$5112),"I",(AllCalls26!$K$15:$K$5112),"5") -> 0 | AS19: =COUNTIFS((AllCalls26!$AM$15:$AM$5112),"I",(AllCalls26!$K$15:$K$5112),"6") -> 0 | AT19: =COUNTIFS((AllCalls26!$AM$15:$AM$5112),"I",(AllCalls26!$K$15:$K$5112),"7") -> 0 | AU19: =COUNTIFS((AllCalls26!$AM$15:$AM$5112),"I",(AllCalls26!$K$15:$K$5112),"8") -> 0 | AV19: =COUNTIFS((AllCalls26!$AM$15:$AM$5112),"I",(AllCalls26!$K$15:$K$5112),"9") -> 0 | AW19: =COUNTIFS((AllCalls26!$AM$15:$AM$5112),"I",(AllCalls26!$K$15:$K$5112),"10") -> 0 | AX19: =COUNTIFS((AllCalls26!$AM$15:$AM$5112),"I",(AllCalls26!$K$15:$K$5112),"11") -> 0 | AY19: =COUNTIFS((AllCalls26!$AM$15:$AM$5112),"I",(AllCalls26!$K$15:$K$5112),"12") -> 0 | AZ19: =SUM($AN19:$AY19) -> 35 | BA19: =(SUM($AZ19))/SUM($AZ$2) -> 0.26315789 | BB19: =SUM($J19,$X19,$AZ19) -> 428 | BC19: =(SUM(BB19))/SUM($BB$2) -> 0.42125984
A20: QFF Ian Chapman | B20: 9 | C20: 23 | D20: 11 | E20: 14 | F20: 10 | G20: 23 | H20: 21 | I20: 23 | J20: =SUM($B20:$I20) -> 134 | K20: =(J20/$J$2) -> 0.41358025 | L20: 12 | M20: 23 | N20: 24 | O20: 16 | P20: 30 | Q20: 19 | R20: 22 | S20: 16 | T20: 20 | U20: 20 | V20: 25 | W20: 26 | X20: 253 | Y20: 0.4382786 | Z20: 22 | AA20: 27 | AB20: 33 | AC20: 16 | AD20: 32 | AE20: 19 | AF20: 25 | AG20: 12 | AH20: 16 | AI20: 17 | AJ20: 23 | AK20: 48 | AL20: 290 | AM20: 0.44478528 | AN20: =COUNTIFS((AllCalls26!$AN$15:$AN$5112),"I",(AllCalls26!$K$15:$K$5112),"1") -> 13 | AO20: =COUNTIFS((AllCalls26!$AN$15:$AN$5112),"I",(AllCalls26!$K$15:$K$5112),"2") -> 23 | AP20: =COUNTIFS((AllCalls26!$AN$15:$AN$5112),"I",(AllCalls26!$K$15:$K$5112),"3") -> 20 | AQ20: =COUNTIFS((AllCalls26!$AN$15:$AN$5112),"I",(AllCalls26!$K$15:$K$5112),"4") -> 0 | AR20: =COUNTIFS((AllCalls26!$AN$15:$AN$5112),"I",(AllCalls26!$K$15:$K$5112),"5") -> 0 | AS20: =COUNTIFS((AllCalls26!$AN$15:$AN$5112),"I",(AllCalls26!$K$15:$K$5112),"6") -> 0 | AT20: =COUNTIFS((AllCalls26!$AN$15:$AN$5112),"I",(AllCalls26!$K$15:$K$5112),"7") -> 0 | AU20: =COUNTIFS((AllCalls26!$AN$15:$AN$5112),"I",(AllCalls26!$K$15:$K$5112),"8") -> 0 | AV20: =COUNTIFS((AllCalls26!$AN$15:$AN$5112),"I",(AllCalls26!$K$15:$K$5112),"9") -> 0 | AW20: =COUNTIFS((AllCalls26!$AN$15:$AN$5112),"I",(AllCalls26!$K$15:$K$5112),"10") -> 0 | AX20: =COUNTIFS((AllCalls26!$AN$15:$AN$5112),"I",(AllCalls26!$K$15:$K$5112),"11") -> 0 | AY20: =COUNTIFS((AllCalls26!$AN$15:$AN$5112),"I",(AllCalls26!$K$15:$K$5112),"12") -> 0 | AZ20: =SUM($AN20:$AY20) -> 56 | BA20: =(SUM($AZ20))/SUM($AZ$2) -> 0.42105263 | BB20: =SUM($J20,$X20,$AZ20) -> 443 | BC20: =(SUM(BB20))/SUM($BB$2) -> 0.43602362 | BD20: DR
A21: QFF Melanie Yates | B21: 1 | C21: 3 | D21: 8 | E21: 7 | F21: 11 | G21: 10 | H21: 15 | I21: 11 | J21: =SUM($B21:$I21) -> 66 | K21: =(J21/$J$2) -> 0.2037037 | L21: 14 | M21: 9 | N21: 7 | O21: 8 | P21: 5 | Q21: 11 | R21: 11 | S21: 9 | T21: 7 | U21: 6 | V21: 13 | W21: 14 | X21: 114 | Y21: 0.20385051 | Z21: 5 | AA21: 7 | AB21: 13 | AC21: 9 | AD21: 14 | AE21: 4 | AF21: 7 | AG21: 10 | AH21: 8 | AI21: 5 | AJ21: 16 | AK21: 27 | AL21: 125 | AM21: 0.19171779 | AN21: =COUNTIFS((AllCalls26!$AO$15:$AO$5112),"I",(AllCalls26!$K$15:$K$5112),"1") -> 9 | AO21: =COUNTIFS((AllCalls26!$AO$15:$AO$5112),"I",(AllCalls26!$K$15:$K$5112),"2") -> 6 | AP21: =COUNTIFS((AllCalls26!$AO$15:$AO$5112),"I",(AllCalls26!$K$15:$K$5112),"3") -> 5 | AQ21: =COUNTIFS((AllCalls26!$AO$15:$AO$5112),"I",(AllCalls26!$K$15:$K$5112),"4") -> 0 | AR21: =COUNTIFS((AllCalls26!$AO$15:$AO$5112),"I",(AllCalls26!$K$15:$K$5112),"5") -> 0 | AS21: =COUNTIFS((AllCalls26!$AO$15:$AO$5112),"I",(AllCalls26!$K$15:$K$5112),"6") -> 0 | AT21: =COUNTIFS((AllCalls26!$AO$15:$AO$5112),"I",(AllCalls26!$K$15:$K$5112),"7") -> 0 | AU21: =COUNTIFS((AllCalls26!$AO$15:$AO$5112),"I",(AllCalls26!$K$15:$K$5112),"8") -> 0 | AV21: =COUNTIFS((AllCalls26!$AO$15:$AO$5112),"I",(AllCalls26!$K$15:$K$5112),"9") -> 0 | AW21: =COUNTIFS((AllCalls26!$AO$15:$AO$5112),"I",(AllCalls26!$K$15:$K$5112),"10") -> 0 | AX21: =COUNTIFS((AllCalls26!$AO$15:$AO$5112),"I",(AllCalls26!$K$15:$K$5112),"11") -> 0 | AY21: =COUNTIFS((AllCalls26!$AO$15:$AO$5112),"I",(AllCalls26!$K$15:$K$5112),"12") -> 0 | AZ21: =SUM($AN21:$AY21) -> 20 | BA21: =(SUM($AZ21))/SUM($AZ$2) -> 0.15037594 | BB21: =SUM($J21,$X21,$AZ21) -> 200 | BC21: =(SUM(BB21))/SUM($BB$2) -> 0.19685039 | BD21: DR
A22: QFF Maree Primrose | B22: 14 | C22: 34 | D22: 25 | E22: 11 | F22: 23 | G22: 24 | H22: 21 | I22: 28 | J22: =SUM($B22:$I22) -> 180 | K22: =(J22/$J$2) -> 0.55555556 | L22: 35 | M22: 33 | N22: 29 | O22: 22 | P22: 19 | Q22: 21 | R22: 14 | S22: 5 | T22: 11 | U22: 12 | V22: 13 | W22: 20 | X22: 234 | Y22: 0.46885617 | Z22: 27 | AA22: 14 | AB22: 26 | AC22: 12 | AD22: 26 | AE22: 7 | AF22: 13 | AG22: 15 | AH22: 14 | AI22: 10 | AJ22: 17 | AK22: 42 | AL22: 223 | AM22: 0.34202454 | AN22: =COUNTIFS((AllCalls26!$AP$15:$AP$5112),"I",(AllCalls26!$K$15:$K$5112),"1") -> 18 | AO22: =COUNTIFS((AllCalls26!$AP$15:$AP$5112),"I",(AllCalls26!$K$15:$K$5112),"2") -> 5 | AP22: =COUNTIFS((AllCalls26!$AP$15:$AP$5112),"I",(AllCalls26!$K$15:$K$5112),"3") -> 1 | AQ22: =COUNTIFS((AllCalls26!$AP$15:$AP$5112),"I",(AllCalls26!$K$15:$K$5112),"4") -> 0 | AR22: =COUNTIFS((AllCalls26!$AP$15:$AP$5112),"I",(AllCalls26!$K$15:$K$5112),"5") -> 0 | AS22: =COUNTIFS((AllCalls26!$AP$15:$AP$5112),"I",(AllCalls26!$K$15:$K$5112),"6") -> 0 | AT22: =COUNTIFS((AllCalls26!$AP$15:$AP$5112),"I",(AllCalls26!$K$15:$K$5112),"7") -> 0 | AU22: =COUNTIFS((AllCalls26!$AP$15:$AP$5112),"I",(AllCalls26!$K$15:$K$5112),"8") -> 0 | AV22: =COUNTIFS((AllCalls26!$AP$15:$AP$5112),"I",(AllCalls26!$K$15:$K$5112),"9") -> 0 | AW22: =COUNTIFS((AllCalls26!$AP$15:$AP$5112),"I",(AllCalls26!$K$15:$K$5112),"10") -> 0 | AX22: =COUNTIFS((AllCalls26!$AP$15:$AP$5112),"I",(AllCalls26!$K$15:$K$5112),"11") -> 0 | AY22: =COUNTIFS((AllCalls26!$AP$15:$AP$5112),"I",(AllCalls26!$K$15:$K$5112),"12") -> 0 | AZ22: =SUM($AN22:$AY22) -> 24 | BA22: =(SUM($AZ22))/SUM($AZ$2) -> 0.18045113 | BB22: =SUM($J22,$X22,$AZ22) -> 438 | BC22: =(SUM(BB22))/SUM($BB$2) -> 0.43110236
A23: QFF Russell Clarke | B23: 2 | C23: 11 | D23: 9 | E23: 8 | F23: 12 | G23: 21 | H23: 17 | I23: 16 | J23: =SUM($B23:$I23) -> 96 | K23: =(J23/$J$2) -> 0.2962963 | L23: 20 | M23: 16 | N23: 13 | O23: 13 | P23: 16 | Q23: 10 | R23: 10 | S23: 10 | T23: 3 | U23: 7 | V23: 9 | W23: 15 | X23: 142 | Y23: 0.26953567 | Z23: 11 | AA23: 7 | AB23: 12 | AC23: 4 | AD23: 13 | AE23: 6 | AF23: 3 | AG23: 12 | AH23: 12 | AI23: 5 | AJ23: 16 | AK23: 25 | AL23: 126 | AM23: 0.19325153 | AN23: =COUNTIFS((AllCalls26!$AQ$15:$AQ$5112),"I",(AllCalls26!$K$15:$K$5112),"1") -> 18 | AO23: =COUNTIFS((AllCalls26!$AQ$15:$AQ$5112),"I",(AllCalls26!$K$15:$K$5112),"2") -> 14 | AP23: =COUNTIFS((AllCalls26!$AQ$15:$AQ$5112),"I",(AllCalls26!$K$15:$K$5112),"3") -> 6 | AQ23: =COUNTIFS((AllCalls26!$AQ$15:$AQ$5112),"I",(AllCalls26!$K$15:$K$5112),"4") -> 0 | AR23: =COUNTIFS((AllCalls26!$AQ$15:$AQ$5112),"I",(AllCalls26!$K$15:$K$5112),"5") -> 0 | AS23: =COUNTIFS((AllCalls26!$AQ$15:$AQ$5112),"I",(AllCalls26!$K$15:$K$5112),"6") -> 0 | AT23: =COUNTIFS((AllCalls26!$AQ$15:$AQ$5112),"I",(AllCalls26!$K$15:$K$5112),"7") -> 0 | AU23: =COUNTIFS((AllCalls26!$AQ$15:$AQ$5112),"I",(AllCalls26!$K$15:$K$5112),"8") -> 0 | AV23: =COUNTIFS((AllCalls26!$AQ$15:$AQ$5112),"I",(AllCalls26!$K$15:$K$5112),"9") -> 0 | AW23: =COUNTIFS((AllCalls26!$AQ$15:$AQ$5112),"I",(AllCalls26!$K$15:$K$5112),"10") -> 0 | AX23: =COUNTIFS((AllCalls26!$AQ$15:$AQ$5112),"I",(AllCalls26!$K$15:$K$5112),"11") -> 0 | AY23: =COUNTIFS((AllCalls26!$AQ$15:$AQ$5112),"I",(AllCalls26!$K$15:$K$5112),"12") -> 0 | AZ23: =SUM($AN23:$AY23) -> 38 | BA23: =(SUM($AZ23))/SUM($AZ$2) -> 0.28571429 | BB23: =SUM($J23,$X23,$AZ23) -> 276 | BC23: =(SUM(BB23))/SUM($BB$2) -> 0.27165354
A24: QFF Andrew Bond | B24: 1 | C24: 14 | D24: 14 | E24: 9 | F24: 4 | G24: 14 | H24: 16 | I24: 17 | J24: =SUM($B24:$I24) -> 89 | K24: =(J24/$J$2) -> 0.27469136 | L24: 26 | M24: 12 | N24: 13 | O24: 6 | P24: 18 | Q24: 9 | R24: 11 | S24: 9 | T24: 13 | U24: 11 | V24: 11 | W24: 14 | X24: 153 | Y24: 0.27406569 | Z24: 15 | AA24: 10 | AB24: 20 | AC24: 0 | AD24: 5 | AE24: 4 | AF24: 0 | AG24: 0 | AH24: 0 | AI24: 0 | AJ24: 0 | AK24: 0 | AL24: 54 | AM24: 0.082822086 | AN24: =COUNTIFS((AllCalls26!$AR$15:$AR$5112),"I",(AllCalls26!$K$15:$K$5112),"1") -> 0 | AO24: =COUNTIFS((AllCalls26!$AR$15:$AR$5112),"I",(AllCalls26!$K$15:$K$5112),"2") -> 10 | AP24: =COUNTIFS((AllCalls26!$AR$15:$AR$5112),"I",(AllCalls26!$K$15:$K$5112),"3") -> 1 | AQ24: =COUNTIFS((AllCalls26!$AR$15:$AR$5112),"I",(AllCalls26!$K$15:$K$5112),"4") -> 0 | AR24: =COUNTIFS((AllCalls26!$AR$15:$AR$5112),"I",(AllCalls26!$K$15:$K$5112),"5") -> 0 | AS24: =COUNTIFS((AllCalls26!$AR$15:$AR$5112),"I",(AllCalls26!$K$15:$K$5112),"6") -> 0 | AT24: =COUNTIFS((AllCalls26!$AR$15:$AR$5112),"I",(AllCalls26!$K$15:$K$5112),"7") -> 0 | AU24: =COUNTIFS((AllCalls26!$AR$15:$AR$5112),"I",(AllCalls26!$K$15:$K$5112),"8") -> 0 | AV24: =COUNTIFS((AllCalls26!$AR$15:$AR$5112),"I",(AllCalls26!$K$15:$K$5112),"9") -> 0 | AW24: =COUNTIFS((AllCalls26!$AR$15:$AR$5112),"I",(AllCalls26!$K$15:$K$5112),"10") -> 0 | AX24: =COUNTIFS((AllCalls26!$AR$15:$AR$5112),"I",(AllCalls26!$K$15:$K$5112),"11") -> 0 | AY24: =COUNTIFS((AllCalls26!$AR$15:$AR$5112),"I",(AllCalls26!$K$15:$K$5112),"12") -> 0 | AZ24: =SUM($AN24:$AY24) -> 11 | BA24: =(SUM($AZ24))/SUM($AZ$2) -> 0.082706767 | BB24: =SUM($J24,$X24,$AZ24) -> 253 | BC24: =(SUM(BB24))/SUM($BB$2) -> 0.24901575
A25: QFF Alan Binnie | B25: 0 | C25: 0 | D25: 0 | E25: 0 | F25: 5 | G25: 3 | H25: 3 | I25: 7 | J25: =SUM($B25:$I25) -> 18 | K25: =(J25/SUM($F$2:$I$2)) -> 0.10526316 | L25: 9 | M25: 2 | N25: 8 | O25: 10 | P25: 10 | Q25: 6 | R25: 3 | S25: 6 | T25: 9 | U25: 13 | V25: 8 | W25: 16 | X25: 100 | Y25: 0.16164384 | Z25: 21 | AA25: 16 | AB25: 28 | AC25: 8 | AD25: 6 | AE25: 3 | AF25: 3 | AG25: 5 | AH25: 7 | AI25: 1 | AJ25: 5 | AK25: 37 | AL25: 140 | AM25: 0.21472393 | AN25: =COUNTIFS((AllCalls26!$AS$15:$AS$5112),"I",(AllCalls26!$K$15:$K$5112),"1") -> 17 | AO25: =COUNTIFS((AllCalls26!$AS$15:$AS$5112),"I",(AllCalls26!$K$15:$K$5112),"2") -> 8 | AP25: =COUNTIFS((AllCalls26!$AS$15:$AS$5112),"I",(AllCalls26!$K$15:$K$5112),"3") -> 4 | AQ25: =COUNTIFS((AllCalls26!$AS$15:$AS$5112),"I",(AllCalls26!$K$15:$K$5112),"4") -> 0 | AR25: =COUNTIFS((AllCalls26!$AS$15:$AS$5112),"I",(AllCalls26!$K$15:$K$5112),"5") -> 0 | AS25: =COUNTIFS((AllCalls26!$AS$15:$AS$5112),"I",(AllCalls26!$K$15:$K$5112),"6") -> 0 | AT25: =COUNTIFS((AllCalls26!$AS$15:$AS$5112),"I",(AllCalls26!$K$15:$K$5112),"7") -> 0 | AU25: =COUNTIFS((AllCalls26!$AS$15:$AS$5112),"I",(AllCalls26!$K$15:$K$5112),"8") -> 0 | AV25: =COUNTIFS((AllCalls26!$AS$15:$AS$5112),"I",(AllCalls26!$K$15:$K$5112),"9") -> 0 | AW25: =COUNTIFS((AllCalls26!$AS$15:$AS$5112),"I",(AllCalls26!$K$15:$K$5112),"10") -> 0 | AX25: =COUNTIFS((AllCalls26!$AS$15:$AS$5112),"I",(AllCalls26!$K$15:$K$5112),"11") -> 0 | AY25: =COUNTIFS((AllCalls26!$AS$15:$AS$5112),"I",(AllCalls26!$K$15:$K$5112),"12") -> 0 | AZ25: =SUM($AN25:$AY25) -> 29 | BA25: =(SUM($AZ25))/SUM($AZ$2) -> 0.21804511 | BB25: =SUM($J25,$X25,$AZ25) -> 147 | BC25: =(SUM(BB25))/SUM($AZ$2,$X$2,AL2) -> 0.109375 | BD25: DR
A26: QFF Josh Pennefather | B26: 12 | C26: 20 | D26: 13 | E26: 15 | F26: 17 | G26: 27 | H26: 16 | I26: 17 | J26: =SUM($B26:$I26) -> 137 | K26: =(J26/$J$2) -> 0.42283951 | L26: 26 | M26: 15 | N26: 14 | O26: 14 | P26: 21 | Q26: 8 | R26: 25 | S26: 7 | T26: 7 | U26: 13 | V26: 16 | W26: 25 | X26: 191 | Y26: 0.37146093 | Z26: 27 | AA26: 16 | AB26: 20 | AC26: 21 | AD26: 29 | AE26: 10 | AF26: 22 | AG26: 15 | AH26: 6 | AI26: 13 | AJ26: 36 | AK26: 41 | AL26: 256 | AM26: 0.39263804 | AN26: =COUNTIFS((AllCalls26!$AT$15:$AT$5112),"I",(AllCalls26!$K$15:$K$5112),"1") -> 15 | AO26: =COUNTIFS((AllCalls26!$AT$15:$AT$5112),"I",(AllCalls26!$K$15:$K$5112),"2") -> 10 | AP26: =COUNTIFS((AllCalls26!$AT$15:$AT$5112),"I",(AllCalls26!$K$15:$K$5112),"3") -> 12 | AQ26: =COUNTIFS((AllCalls26!$AT$15:$AT$5112),"I",(AllCalls26!$K$15:$K$5112),"4") -> 0 | AR26: =COUNTIFS((AllCalls26!$AT$15:$AT$5112),"I",(AllCalls26!$K$15:$K$5112),"5") -> 0 | AS26: =COUNTIFS((AllCalls26!$AT$15:$AT$5112),"I",(AllCalls26!$K$15:$K$5112),"6") -> 0 | AT26: =COUNTIFS((AllCalls26!$AT$15:$AT$5112),"I",(AllCalls26!$K$15:$K$5112),"7") -> 0 | AU26: =COUNTIFS((AllCalls26!$AT$15:$AT$5112),"I",(AllCalls26!$K$15:$K$5112),"8") -> 0 | AV26: =COUNTIFS((AllCalls26!$AT$15:$AT$5112),"I",(AllCalls26!$K$15:$K$5112),"9") -> 0 | AW26: =COUNTIFS((AllCalls26!$AT$15:$AT$5112),"I",(AllCalls26!$K$15:$K$5112),"10") -> 0 | AX26: =COUNTIFS((AllCalls26!$AT$15:$AT$5112),"I",(AllCalls26!$K$15:$K$5112),"11") -> 0 | AY26: =COUNTIFS((AllCalls26!$AT$15:$AT$5112),"I",(AllCalls26!$K$15:$K$5112),"12") -> 0 | AZ26: =SUM($AN26:$AY26) -> 37 | BA26: =(SUM($AZ26))/SUM($AZ$2) -> 0.27819549 | BB26: =SUM($J26,$X26,$AZ26) -> 365 | BC26: =(SUM(BB26))/SUM($BB$2) -> 0.35925197 | BD26: DR
A27: QFF Ben Killgour | B27: 8 | C27: 21 | D27: 18 | E27: 10 | F27: 13 | G27: 20 | H27: 9 | I27: 10 | J27: =SUM($B27:$I27) -> 109 | K27: =(J27/$J$2) -> 0.33641975 | L27: 14 | M27: 26 | N27: 24 | O27: 19 | P27: 22 | Q27: 18 | R27: 21 | S27: 20 | T27: 19 | U27: 13 | V27: 16 | W27: 19 | X27: 231 | Y27: 0.38505096 | Z27: 16 | AA27: 15 | AB27: 27 | AC27: 16 | AD27: 24 | AE27: 10 | AF27: 13 | AG27: 18 | AH27: 20 | AI27: 14 | AJ27: 10 | AK27: 11 | AL27: 194 | AM27: 0.29754601 | AN27: =COUNTIFS((AllCalls26!$AU$15:$AU$5112),"I",(AllCalls26!$K$15:$K$5112),"1") -> 16 | AO27: =COUNTIFS((AllCalls26!$AU$15:$AU$5112),"I",(AllCalls26!$K$15:$K$5112),"2") -> 16 | AP27: =COUNTIFS((AllCalls26!$AU$15:$AU$5112),"I",(AllCalls26!$K$15:$K$5112),"3") -> 5 | AQ27: =COUNTIFS((AllCalls26!$AU$15:$AU$5112),"I",(AllCalls26!$K$15:$K$5112),"4") -> 0 | AR27: =COUNTIFS((AllCalls26!$AU$15:$AU$5112),"I",(AllCalls26!$K$15:$K$5112),"5") -> 0 | AS27: =COUNTIFS((AllCalls26!$AU$15:$AU$5112),"I",(AllCalls26!$K$15:$K$5112),"6") -> 0 | AT27: =COUNTIFS((AllCalls26!$AU$15:$AU$5112),"I",(AllCalls26!$K$15:$K$5112),"7") -> 0 | AU27: =COUNTIFS((AllCalls26!$AU$15:$AU$5112),"I",(AllCalls26!$K$15:$K$5112),"8") -> 0 | AV27: =COUNTIFS((AllCalls26!$AU$15:$AU$5112),"I",(AllCalls26!$K$15:$K$5112),"9") -> 0 | AW27: =COUNTIFS((AllCalls26!$AU$15:$AU$5112),"I",(AllCalls26!$K$15:$K$5112),"10") -> 0 | AX27: =COUNTIFS((AllCalls26!$AU$15:$AU$5112),"I",(AllCalls26!$K$15:$K$5112),"11") -> 0 | AY27: =COUNTIFS((AllCalls26!$AU$15:$AU$5112),"I",(AllCalls26!$K$15:$K$5112),"12") -> 0 | AZ27: =SUM($AN27:$AY27) -> 37 | BA27: =(SUM($AZ27))/SUM($AZ$2) -> 0.27819549 | BB27: =SUM($J27,$X27,$AZ27) -> 377 | BC27: =(SUM(BB27))/SUM($BB$2) -> 0.37106299
A28: QFF Dallas Steele | B28: 0 | C28: 6 | D28: 5 | E28: 6 | F28: 11 | G28: 14 | H28: 20 | I28: 16 | J28: =SUM($B28:$I28) -> 78 | K28: =(J28/$J$2) -> 0.24074074 | L28: 17 | M28: 19 | N28: 13 | O28: 10 | P28: 6 | Q28: 5 | R28: 12 | S28: 16 | T28: 12 | U28: 9 | V28: 15 | W28: 6 | X28: 140 | Y28: 0.24688562 | Z28: 9 | AA28: 11 | AB28: 13 | AC28: 10 | AD28: 13 | AE28: 8 | AF28: 7 | AG28: 9 | AH28: 4 | AI28: 5 | AJ28: 9 | AK28: 14 | AL28: 112 | AM28: 0.17177914 | AN28: =COUNTIFS((AllCalls26!$AV$15:$AV$5112),"I",(AllCalls26!$K$15:$K$5112),"1") -> 15 | AO28: =COUNTIFS((AllCalls26!$AV$15:$AV$5112),"I",(AllCalls26!$K$15:$K$5112),"2") -> 7 | AP28: =COUNTIFS((AllCalls26!$AV$15:$AV$5112),"I",(AllCalls26!$K$15:$K$5112),"3") -> 2 | AQ28: =COUNTIFS((AllCalls26!$AV$15:$AV$5112),"I",(AllCalls26!$K$15:$K$5112),"4") -> 0 | AR28: =COUNTIFS((AllCalls26!$AV$15:$AV$5112),"I",(AllCalls26!$K$15:$K$5112),"5") -> 0 | AS28: =COUNTIFS((AllCalls26!$AV$15:$AV$5112),"I",(AllCalls26!$K$15:$K$5112),"6") -> 0 | AT28: =COUNTIFS((AllCalls26!$AV$15:$AV$5112),"I",(AllCalls26!$K$15:$K$5112),"7") -> 0 | AU28: =COUNTIFS((AllCalls26!$AV$15:$AV$5112),"I",(AllCalls26!$K$15:$K$5112),"8") -> 0 | AV28: =COUNTIFS((AllCalls26!$AV$15:$AV$5112),"I",(AllCalls26!$K$15:$K$5112),"9") -> 0 | AW28: =COUNTIFS((AllCalls26!$AV$15:$AV$5112),"I",(AllCalls26!$K$15:$K$5112),"10") -> 0 | AX28: =COUNTIFS((AllCalls26!$AV$15:$AV$5112),"I",(AllCalls26!$K$15:$K$5112),"11") -> 0 | AY28: =COUNTIFS((AllCalls26!$AV$15:$AV$5112),"I",(AllCalls26!$K$15:$K$5112),"12") -> 0 | AZ28: =SUM($AN28:$AY28) -> 24 | BA28: =(SUM($AZ28))/SUM($AZ$2) -> 0.18045113 | BB28: =SUM($J28,$X28,$AZ28) -> 242 | BC28: =(SUM(BB28))/SUM($BB$2) -> 0.23818898
A29: QFF Nick Grayson | B29: 0 | C29: 16 | D29: 20 | E29: 16 | F29: 17 | G29: 26 | H29: 21 | I29: 18 | J29: =SUM($B29:$I29) -> 134 | K29: =(J29/$J$2) -> 0.41358025 | L29: 21 | M29: 20 | N29: 22 | O29: 19 | P29: 24 | Q29: 26 | R29: 19 | S29: 29 | T29: 10 | U29: 24 | V29: 23 | W29: 25 | X29: 262 | Y29: 0.44847112 | Z29: 21 | AA29: 19 | AB29: 0 | AC29: 0 | AD29: 0 | AE29: 0 | AF29: 1 | AG29: 29 | AH29: 25 | AI29: 17 | AJ29: 18 | AK29: 54 | AL29: 184 | AM29: 0.28220859 | AN29: =COUNTIFS((AllCalls26!$AW$15:$AW$5112),"I",(AllCalls26!$K$15:$K$5112),"1") -> 22 | AO29: =COUNTIFS((AllCalls26!$AW$15:$AW$5112),"I",(AllCalls26!$K$15:$K$5112),"2") -> 25 | AP29: =COUNTIFS((AllCalls26!$AW$15:$AW$5112),"I",(AllCalls26!$K$15:$K$5112),"3") -> 18 | AQ29: =COUNTIFS((AllCalls26!$AW$15:$AW$5112),"I",(AllCalls26!$K$15:$K$5112),"4") -> 0 | AR29: =COUNTIFS((AllCalls26!$AW$15:$AW$5112),"I",(AllCalls26!$K$15:$K$5112),"5") -> 0 | AS29: =COUNTIFS((AllCalls26!$AW$15:$AW$5112),"I",(AllCalls26!$K$15:$K$5112),"6") -> 0 | AT29: =COUNTIFS((AllCalls26!$AW$15:$AW$5112),"I",(AllCalls26!$K$15:$K$5112),"7") -> 0 | AU29: =COUNTIFS((AllCalls26!$AW$15:$AW$5112),"I",(AllCalls26!$K$15:$K$5112),"8") -> 0 | AV29: =COUNTIFS((AllCalls26!$AW$15:$AW$5112),"I",(AllCalls26!$K$15:$K$5112),"9") -> 0 | AW29: =COUNTIFS((AllCalls26!$AW$15:$AW$5112),"I",(AllCalls26!$K$15:$K$5112),"10") -> 0 | AX29: =COUNTIFS((AllCalls26!$AW$15:$AW$5112),"I",(AllCalls26!$K$15:$K$5112),"11") -> 0 | AY29: =COUNTIFS((AllCalls26!$AW$15:$AW$5112),"I",(AllCalls26!$K$15:$K$5112),"12") -> 0 | AZ29: =SUM($AN29:$AY29) -> 65 | BA29: =(SUM($AZ29))/SUM($AZ$2) -> 0.4887218 | BB29: =SUM($J29,$X29,$AZ29) -> 461 | BC29: =(SUM(BB29))/SUM($BB$2) -> 0.45374016
A30: QFF Jason Court | B30: 0 | C30: 14 | D30: 12 | E30: 6 | F30: 13 | G30: 8 | H30: 14 | I30: 10 | J30: =SUM($B30:$I30) -> 77 | K30: =(J30/$J$2) -> 0.23765432 | L30: 0 | M30: 7 | N30: 6 | O30: 19 | P30: 25 | Q30: 17 | R30: 19 | S30: 7 | T30: 15 | U30: 16 | V30: 25 | W30: 9 | X30: 165 | Y30: 0.27406569 | Z30: 0 | AA30: 15 | AB30: 36 | AC30: 27 | AD30: 29 | AE30: 19 | AF30: 17 | AG30: 12 | AH30: 30 | AI30: 16 | AJ30: 14 | AK30: 17 | AL30: 232 | AM30: 0.35582822 | AN30: =COUNTIFS((AllCalls26!$AX$15:$AX$5112),"I",(AllCalls26!$K$15:$K$5112),"1") -> 0 | AO30: =COUNTIFS((AllCalls26!$AX$15:$AX$5112),"I",(AllCalls26!$K$15:$K$5112),"2") -> 20 | AP30: =COUNTIFS((AllCalls26!$AX$15:$AX$5112),"I",(AllCalls26!$K$15:$K$5112),"3") -> 10 | AQ30: =COUNTIFS((AllCalls26!$AX$15:$AX$5112),"I",(AllCalls26!$K$15:$K$5112),"4") -> 0 | AR30: =COUNTIFS((AllCalls26!$AX$15:$AX$5112),"I",(AllCalls26!$K$15:$K$5112),"5") -> 0 | AS30: =COUNTIFS((AllCalls26!$AX$15:$AX$5112),"I",(AllCalls26!$K$15:$K$5112),"6") -> 0 | AT30: =COUNTIFS((AllCalls26!$AX$15:$AX$5112),"I",(AllCalls26!$K$15:$K$5112),"7") -> 0 | AU30: =COUNTIFS((AllCalls26!$AX$15:$AX$5112),"I",(AllCalls26!$K$15:$K$5112),"8") -> 0 | AV30: =COUNTIFS((AllCalls26!$AX$15:$AX$5112),"I",(AllCalls26!$K$15:$K$5112),"9") -> 0 | AW30: =COUNTIFS((AllCalls26!$AX$15:$AX$5112),"I",(AllCalls26!$K$15:$K$5112),"10") -> 0 | AX30: =COUNTIFS((AllCalls26!$AX$15:$AX$5112),"I",(AllCalls26!$K$15:$K$5112),"11") -> 0 | AY30: =COUNTIFS((AllCalls26!$AX$15:$AX$5112),"I",(AllCalls26!$K$15:$K$5112),"12") -> 0 | AZ30: =SUM($AN30:$AY30) -> 30 | BA30: =(SUM($AZ30))/SUM($AZ$2) -> 0.22556391 | BB30: =SUM($J30,$X30,$AZ30) -> 272 | BC30: =(SUM(BB30))/SUM($BB$2) -> 0.26771654
A31: QFF Crystal McConchie | C31: 0 | D31: 1 | E31: 1 | F31: 0 | G31: 4 | H31: 7 | I31: 6 | J31: =SUM($B31:$I31) -> 19 | K31: =(J31/$J$2) -> 0.058641975 | L31: 12 | M31: 10 | N31: 3 | O31: 4 | P31: 12 | Q31: 8 | R31: 14 | S31: 16 | T31: 9 | U31: 15 | V31: 11 | W31: 12 | X31: 126 | Y31: 0.16421291 | Z31: 12 | AA31: 20 | AB31: 19 | AC31: 7 | AD31: 19 | AE31: 5 | AF31: 11 | AG31: 6 | AH31: 18 | AI31: 12 | AJ31: 12 | AK31: 39 | AL31: 180 | AM31: 0.27607362 | AN31: =COUNTIFS((AllCalls26!$AY$15:$AY$5112),"I",(AllCalls26!$K$15:$K$5112),"1") -> 16 | AO31: =COUNTIFS((AllCalls26!$AY$15:$AY$5112),"I",(AllCalls26!$K$15:$K$5112),"2") -> 12 | AP31: =COUNTIFS((AllCalls26!$AY$15:$AY$5112),"I",(AllCalls26!$K$15:$K$5112),"3") -> 11 | AQ31: =COUNTIFS((AllCalls26!$AY$15:$AY$5112),"I",(AllCalls26!$K$15:$K$5112),"4") -> 0 | AR31: =COUNTIFS((AllCalls26!$AY$15:$AY$5112),"I",(AllCalls26!$K$15:$K$5112),"5") -> 0 | AS31: =COUNTIFS((AllCalls26!$AY$15:$AY$5112),"I",(AllCalls26!$K$15:$K$5112),"6") -> 0 | AT31: =COUNTIFS((AllCalls26!$AY$15:$AY$5112),"I",(AllCalls26!$K$15:$K$5112),"7") -> 0 | AU31: =COUNTIFS((AllCalls26!$AY$15:$AY$5112),"I",(AllCalls26!$K$15:$K$5112),"8") -> 0 | AV31: =COUNTIFS((AllCalls26!$AY$15:$AY$5112),"I",(AllCalls26!$K$15:$K$5112),"9") -> 0 | AW31: =COUNTIFS((AllCalls26!$AY$15:$AY$5112),"I",(AllCalls26!$K$15:$K$5112),"10") -> 0 | AX31: =COUNTIFS((AllCalls26!$AY$15:$AY$5112),"I",(AllCalls26!$K$15:$K$5112),"11") -> 0 | AY31: =COUNTIFS((AllCalls26!$AY$15:$AY$5112),"I",(AllCalls26!$K$15:$K$5112),"12") -> 0 | AZ31: =SUM($AN31:$AY31) -> 39 | BA31: =(SUM($AZ31))/SUM($AZ$2) -> 0.29323308 | BB31: =SUM($J31,$X31,$AZ31) -> 184 | BC31: =(SUM(BB31))/SUM($BB$2) -> 0.18110236
A32: QFF Hendri de Bruin | J32: =SUM(B33:I33) -> 70
A33: FF Jimmy Doyle | B33: 9 | C33: 13 | D33: 12 | E33: 0 | F33: 0 | G33: 10 | H33: 11 | I33: 15 | J33: =SUM($B33:$I33) -> 70 | K33: =(J33/$J$2) -> 0.21604938 | L33: 24 | M33: 16 | N33: 16 | O33: 14 | P33: 20 | Q33: 19 | R33: 17 | S33: 0 | T33: 0 | U33: 8 | V33: 9 | W33: 2 | X33: 145 | Y33: 0.24348811 | Z33: 1 | AA33: 0 | AB33: 9 | AC33: 7 | AD33: 4 | AE33: 6 | AF33: 13 | AG33: 14 | AH33: 18 | AI33: 7 | AJ33: 19 | AK33: 37 | AL33: 135 | AM33: 0.20705521 | AN33: =COUNTIFS((AllCalls26!$BA$15:$BA$5112),"I",(AllCalls26!$K$15:$K$5112),"1") -> 13 | AO33: =COUNTIFS((AllCalls26!$BA$15:$BA$5112),"I",(AllCalls26!$K$15:$K$5112),"2") -> 13 | AP33: =COUNTIFS((AllCalls26!$BA$15:$BA$5112),"I",(AllCalls26!$K$15:$K$5112),"3") -> 10 | AQ33: =COUNTIFS((AllCalls26!$BA$15:$BA$5112),"I",(AllCalls26!$K$15:$K$5112),"4") -> 0 | AR33: =COUNTIFS((AllCalls26!$BA$15:$BA$5112),"I",(AllCalls26!$K$15:$K$5112),"5") -> 0 | AS33: =COUNTIFS((AllCalls26!$BA$15:$BA$5112),"I",(AllCalls26!$K$15:$K$5112),"6") -> 0 | AT33: =COUNTIFS((AllCalls26!$BA$15:$BA$5112),"I",(AllCalls26!$K$15:$K$5112),"7") -> 0 | AU33: =COUNTIFS((AllCalls26!$BA$15:$BA$5112),"I",(AllCalls26!$K$15:$K$5112),"8") -> 0 | AV33: =COUNTIFS((AllCalls26!$BA$15:$BA$5112),"I",(AllCalls26!$K$15:$K$5112),"9") -> 0 | AW33: =COUNTIFS((AllCalls26!$BA$15:$BA$5112),"I",(AllCalls26!$K$15:$K$5112),"10") -> 0 | AX33: =COUNTIFS((AllCalls26!$BA$15:$BA$5112),"I",(AllCalls26!$K$15:$K$5112),"11") -> 0 | AY33: =COUNTIFS((AllCalls26!$BA$15:$BA$5112),"I",(AllCalls26!$K$15:$K$5112),"12") -> 0 | AZ33: =SUM($AN33:$AY33) -> 36 | BA33: =(SUM($AZ33))/SUM($AZ$2) -> 0.27067669 | BB33: =SUM($J33,$X33,$AZ33) -> 251 | BC33: =(SUM(BB33))/SUM($BB$2) -> 0.24704724
A34: FF Dimmy Bell-Kainiu | B34: 6 | C34: 24 | D34: 31 | E34: 18 | F34: 21 | G34: 25 | H34: 27 | I34: 21 | J34: =SUM($B34:$I34) -> 173 | K34: =(J34/$J$2) -> 0.53395062 | L34: 21 | M34: 14 | N34: 13 | O34: 9 | P34: 8 | Q34: 3 | R34: 6 | S34: 7 | T34: 5 | U34: 8 | V34: 5 | W34: 8 | X34: 107 | Y34: 0.31710079 | Z34: 2 | AA34: 9 | AB34: 21 | AC34: 15 | AD34: 34 | AE34: 7 | AF34: 17 | AG34: 15 | AH34: 16 | AI34: 4 | AJ34: 23 | AK34: 44 | AL34: 207 | AM34: 0.31748466 | AN34: =COUNTIFS((AllCalls26!$BB$15:$BB$5112),"I",(AllCalls26!$K$15:$K$5112),"1") -> 14 | AO34: =COUNTIFS((AllCalls26!$BB$15:$BB$5112),"I",(AllCalls26!$K$15:$K$5112),"2") -> 14 | AP34: =COUNTIFS((AllCalls26!$BB$15:$BB$5112),"I",(AllCalls26!$K$15:$K$5112),"3") -> 7 | AQ34: =COUNTIFS((AllCalls26!$BB$15:$BB$5112),"I",(AllCalls26!$K$15:$K$5112),"4") -> 0 | AR34: =COUNTIFS((AllCalls26!$BB$15:$BB$5112),"I",(AllCalls26!$K$15:$K$5112),"5") -> 0 | AS34: =COUNTIFS((AllCalls26!$BB$15:$BB$5112),"I",(AllCalls26!$K$15:$K$5112),"6") -> 0 | AT34: =COUNTIFS((AllCalls26!$BB$15:$BB$5112),"I",(AllCalls26!$K$15:$K$5112),"7") -> 0 | AU34: =COUNTIFS((AllCalls26!$BB$15:$BB$5112),"I",(AllCalls26!$K$15:$K$5112),"8") -> 0 | AV34: =COUNTIFS((AllCalls26!$BB$15:$BB$5112),"I",(AllCalls26!$K$15:$K$5112),"9") -> 0 | AW34: =COUNTIFS((AllCalls26!$BB$15:$BB$5112),"I",(AllCalls26!$K$15:$K$5112),"10") -> 0 | AX34: =COUNTIFS((AllCalls26!$BB$15:$BB$5112),"I",(AllCalls26!$K$15:$K$5112),"11") -> 0 | AY34: =COUNTIFS((AllCalls26!$BB$15:$BB$5112),"I",(AllCalls26!$K$15:$K$5112),"12") -> 0 | AZ34: =SUM($AN34:$AY34) -> 35 | BA34: =(SUM($AZ34))/SUM($AZ$2) -> 0.26315789 | BB34: =SUM($J34,$X34,$AZ34) -> 315 | BC34: =(SUM(BB34))/SUM($BB$2) -> 0.31003937
A35: FF Mitch Court | B35: 0 | C35: 6 | D35: 5 | E35: 3 | F35: 10 | G35: 8 | H35: 5 | I35: 3 | J35: =SUM($B35:$I35) -> 40 | K35: =(J35/$J$2) -> 0.12345679 | L35: 6 | M35: 10 | N35: 3 | O35: 6 | P35: 0 | Q35: 0 | R35: 0 | S35: 2 | T35: 0 | U35: 0 | V35: 0 | W35: 2 | X35: 29 | Y35: 0.078142695 | Z35: 5 | AA35: 8 | AB35: 18 | AC35: 8 | AD35: 0 | AE35: 11 | AF35: 17 | AG35: 12 | AH35: 18 | AI35: 9 | AJ35: 15 | AK35: 11 | AL35: 132 | AM35: 0.20245399 | AN35: =COUNTIFS((AllCalls26!$BC$15:$BC$5112),"I",(AllCalls26!$K$15:$K$5112),"1") -> 15 | AO35: =COUNTIFS((AllCalls26!$BC$15:$BC$5112),"I",(AllCalls26!$K$15:$K$5112),"2") -> 2 | AP35: =COUNTIFS((AllCalls26!$BC$15:$BC$5112),"I",(AllCalls26!$K$15:$K$5112),"3") -> 8 | AQ35: =COUNTIFS((AllCalls26!$BC$15:$BC$5112),"I",(AllCalls26!$K$15:$K$5112),"4") -> 0 | AR35: =COUNTIFS((AllCalls26!$BC$15:$BC$5112),"I",(AllCalls26!$K$15:$K$5112),"5") -> 0 | AS35: =COUNTIFS((AllCalls26!$BC$15:$BC$5112),"I",(AllCalls26!$K$15:$K$5112),"6") -> 0 | AT35: =COUNTIFS((AllCalls26!$BC$15:$BC$5112),"I",(AllCalls26!$K$15:$K$5112),"7") -> 0 | AU35: =COUNTIFS((AllCalls26!$BC$15:$BC$5112),"I",(AllCalls26!$K$15:$K$5112),"8") -> 0 | AV35: =COUNTIFS((AllCalls26!$BC$15:$BC$5112),"I",(AllCalls26!$K$15:$K$5112),"9") -> 0 | AW35: =COUNTIFS((AllCalls26!$BC$15:$BC$5112),"I",(AllCalls26!$K$15:$K$5112),"10") -> 0 | AX35: =COUNTIFS((AllCalls26!$BC$15:$BC$5112),"I",(AllCalls26!$K$15:$K$5112),"11") -> 0 | AY35: =COUNTIFS((AllCalls26!$BC$15:$BC$5112),"I",(AllCalls26!$K$15:$K$5112),"12") -> 0 | AZ35: =SUM($AN35:$AY35) -> 25 | BA35: =(SUM($AZ35))/SUM($AZ$2) -> 0.18796992 | BB35: =SUM($J35,$X35,$AZ35) -> 94 | BC35: =(SUM(BB35))/SUM($BB$2) -> 0.092519685 | BD35: *
A36: FF Jamie O'Hare | F36: 2 | G36: 2 | H36: 7 | I36: 2 | J36: =SUM($B36:$I36) -> 13 | K36: =(J36/$J$2) -> 0.040123457 | L36: 8 | M36: 2 | N36: 0 | O36: 2 | P36: 3 | Q36: 0 | R36: 1 | S36: 7 | T36: 11 | U36: 7 | V36: 12 | W36: 9 | X36: 62 | Y36: 0.10273973 | Z36: 14 | AA36: 10 | AB36: 6 | AC36: 8 | AD36: 5 | AE36: 2 | AF36: 11 | AG36: 9 | AH36: 4 | AI36: 8 | AJ36: 6 | AK36: 24 | AL36: 107 | AM36: 0.16411043 | AN36: =COUNTIFS((AllCalls26!$BD$15:$BD$5112),"I",(AllCalls26!$K$15:$K$5112),"1") -> 9 | AO36: =COUNTIFS((AllCalls26!$BD$15:$BD$5112),"I",(AllCalls26!$K$15:$K$5112),"2") -> 3 | AP36: =COUNTIFS((AllCalls26!$BD$15:$BD$5112),"I",(AllCalls26!$K$15:$K$5112),"3") -> 2 | AQ36: =COUNTIFS((AllCalls26!$BD$15:$BD$5112),"I",(AllCalls26!$K$15:$K$5112),"4") -> 0 | AR36: =COUNTIFS((AllCalls26!$BD$15:$BD$5112),"I",(AllCalls26!$K$15:$K$5112),"5") -> 0 | AS36: =COUNTIFS((AllCalls26!$BD$15:$BD$5112),"I",(AllCalls26!$K$15:$K$5112),"6") -> 0 | AT36: =COUNTIFS((AllCalls26!$BD$15:$BD$5112),"I",(AllCalls26!$K$15:$K$5112),"7") -> 0 | AU36: =COUNTIFS((AllCalls26!$BD$15:$BD$5112),"I",(AllCalls26!$K$15:$K$5112),"8") -> 0 | AV36: =COUNTIFS((AllCalls26!$BD$15:$BD$5112),"I",(AllCalls26!$K$15:$K$5112),"9") -> 0 | AW36: =COUNTIFS((AllCalls26!$BD$15:$BD$5112),"I",(AllCalls26!$K$15:$K$5112),"10") -> 0 | AX36: =COUNTIFS((AllCalls26!$BD$15:$BD$5112),"I",(AllCalls26!$K$15:$K$5112),"11") -> 0 | AY36: =COUNTIFS((AllCalls26!$BD$15:$BD$5112),"I",(AllCalls26!$K$15:$K$5112),"12") -> 0 | AZ36: =SUM($AN36:$AY36) -> 14 | BA36: =(SUM($AZ36))/SUM($AZ$2) -> 0.10526316 | BB36: =SUM($J36,$X36,$AZ36) -> 89 | BC36: =(SUM(BB36))/SUM($BB$2) -> 0.087598425 | BD36: *
A37: FF Kaitlyn Evans | J37: 0 | N37: - | O37: 3 | P37: 0 | Q37: 2 | R37: 2 | S37: 1 | T37: 3 | U37: 10 | V37: 11 | W37: 12 | X37: 44 | Y37: 0.10837438 | Z37: 4 | AA37: 3 | AB37: 13 | AC37: 5 | AD37: 3 | AE37: 2 | AF37: 9 | AG37: 9 | AH37: 11 | AI37: 6 | AJ37: 7 | AK37: 10 | AL37: 82 | AM37: 0.12576687 | AN37: =COUNTIFS((AllCalls26!$BE$15:$BE$5112),"I",(AllCalls26!$K$15:$K$5112),"1") -> 4 | AO37: =COUNTIFS((AllCalls26!$BE$15:$BE$5112),"I",(AllCalls26!$K$15:$K$5112),"2") -> 1 | AP37: =COUNTIFS((AllCalls26!$BE$15:$BE$5112),"I",(AllCalls26!$K$15:$K$5112),"3") -> 4 | AQ37: =COUNTIFS((AllCalls26!$BE$15:$BE$5112),"I",(AllCalls26!$K$15:$K$5112),"4") -> 0 | AR37: =COUNTIFS((AllCalls26!$BE$15:$BE$5112),"I",(AllCalls26!$K$15:$K$5112),"5") -> 0 | AS37: =COUNTIFS((AllCalls26!$BE$15:$BE$5112),"I",(AllCalls26!$K$15:$K$5112),"6") -> 0 | AT37: =COUNTIFS((AllCalls26!$BE$15:$BE$5112),"I",(AllCalls26!$K$15:$K$5112),"7") -> 0 | AU37: =COUNTIFS((AllCalls26!$BE$15:$BE$5112),"I",(AllCalls26!$K$15:$K$5112),"8") -> 0 | AV37: =COUNTIFS((AllCalls26!$BE$15:$BE$5112),"I",(AllCalls26!$K$15:$K$5112),"9") -> 0 | AW37: =COUNTIFS((AllCalls26!$BE$15:$BE$5112),"I",(AllCalls26!$K$15:$K$5112),"10") -> 0 | AX37: =COUNTIFS((AllCalls26!$BE$15:$BE$5112),"I",(AllCalls26!$K$15:$K$5112),"11") -> 0 | AY37: =COUNTIFS((AllCalls26!$BE$15:$BE$5112),"I",(AllCalls26!$K$15:$K$5112),"12") -> 0 | AZ37: =SUM($AN37:$AY37) -> 9 | BA37: =(SUM($AZ37))/SUM($AZ$2) -> 0.067669173 | BB37: =SUM($J37,$X37,$AZ37) -> 53 | BC37: =(SUM(BB37))/SUM($BB$2) -> 0.052165354 | BD37: *
A38: FF Jaime Moore | U38: 0 | V38: 9 | W38: 17 | X38: 26 | Y38: 0.18439716 | Z38: 7 | AA38: 12 | AB38: 18 | AC38: 16 | AD38: 21 | AE38: 7 | AF38: 18 | AG38: 9 | AH38: 8 | AI38: 13 | AJ38: 15 | AK38: 9 | AL38: 153 | AM38: 0.23466258 | AN38: =COUNTIFS((AllCalls26!$BF$15:$BF$5112),"I",(AllCalls26!$K$15:$K$5112),"1") -> 7 | AO38: =COUNTIFS((AllCalls26!$BF$15:$BF$5112),"I",(AllCalls26!$K$15:$K$5112),"2") -> 13 | AP38: =COUNTIFS((AllCalls26!$BF$15:$BF$5112),"I",(AllCalls26!$K$15:$K$5112),"3") -> 5 | AQ38: =COUNTIFS((AllCalls26!$BF$15:$BF$5112),"I",(AllCalls26!$K$15:$K$5112),"4") -> 0 | AR38: =COUNTIFS((AllCalls26!$BF$15:$BF$5112),"I",(AllCalls26!$K$15:$K$5112),"5") -> 0 | AS38: =COUNTIFS((AllCalls26!$BF$15:$BF$5112),"I",(AllCalls26!$K$15:$K$5112),"6") -> 0 | AT38: =COUNTIFS((AllCalls26!$BF$15:$BF$5112),"I",(AllCalls26!$K$15:$K$5112),"7") -> 0 | AU38: =COUNTIFS((AllCalls26!$BF$15:$BF$5112),"I",(AllCalls26!$K$15:$K$5112),"8") -> 0 | AV38: =COUNTIFS((AllCalls26!$BF$15:$BF$5112),"I",(AllCalls26!$K$15:$K$5112),"9") -> 0 | AW38: =COUNTIFS((AllCalls26!$BF$15:$BF$5112),"I",(AllCalls26!$K$15:$K$5112),"10") -> 0 | AX38: =COUNTIFS((AllCalls26!$BF$15:$BF$5112),"I",(AllCalls26!$K$15:$K$5112),"11") -> 0 | AY38: =COUNTIFS((AllCalls26!$BF$15:$BF$5112),"I",(AllCalls26!$K$15:$K$5112),"12") -> 0 | AZ38: =SUM($AN38:$AY38) -> 25 | BA38: =(SUM($AZ38))/SUM($AZ$2) -> 0.18796992 | BB38: =SUM($J38,$X38,$AZ38) -> 51 | BC38: =(SUM(BB38,X38))/SUM($AZ$2,$V$2:$W$2) -> 0.33189655
