Workbook

Sheet Call Stats
B4: Call event type

Sheet Summary
A1: Musters | B1: 3 | C1: 4 | D1: 4 | E1: 5 | F1: 4 | G1: 4 | H1: 4 | I1: 2 | J1: =SUM(B1:I1) -> 30 | K1: 2023 | L1: 3 | M1: 4 | N1: 4 | O1: 5 | P1: 4 | Q1: 4 | R1: 5 | S1: 5 | T1: 5 | U1: 4 | V1: 4 | W1: 3 | X1: 50 | Y1: 2024 | Z1: =(Musters!Z1) -> 3 | AA1: =(Musters!AA1) -> 4 | AB1: =(Musters!AB1) -> 5 | AC1: =(Musters!AC1) -> 4 | AD1: =(Musters!AD1) -> 4 | AE1: =(Musters!AE1) -> 5 | AF1: =(Musters!AF1) -> 4 | AG1: =(Musters!AG1) -> 4 | ... AK1: =(Musters!AK1) -> 3 | AL1: =SUM(Z1:AK1) -> 49 | AM1: 2025 | AN1: Total Calls | AO1: Total
A2: Monthly Call Count | B2: 32 | C2: 46 | D2: 47 | E2: 28 | F2: 38 | G2: 46 | H2: 43 | I2: 44 | J2: =SUM(B2:I2) -> 324 | L2: 58 | M2: 48 | N2: 47 | O2: 38 | P2: 55 | Q2: 43 | R2: 44 | S2: 49 | T2: 36 | U2: 42 | V2: 47 | W2: 52 | X2: =SUM($L$2:$W$2) -> 559 | Z2: =AllCalls25!$D$3 -> 57 | AA2: =AllCalls25!$D$4 -> 48 | AB2: =AllCalls25!$D$5 -> 70 | AC2: =AllCalls25!$D$6 -> 42 | AD2: =AllCalls25!$D$7 -> 68 | AE2: =AllCalls25!$D$8 -> 35 | AF2: =AllCalls25!$D$9 -> 56 | AG2: =AllCalls25!$D$10 -> 53 | AH2: =AllCalls25!$D$11 -> 47 | AI2: =AllCalls25!$D$12 -> 39 | AJ2: =AllCalls25!$D$13 -> 58 | AK2: =AllCalls25!$D$14 -> 79 | AL2: =SUM(Z2:AK2) -> 652 | AN2: =SUM($J2,$X2,AL2) -> 1535
A3: Month | B3: May | C3: June | D3: July | E3: August | F3: September | G3: October | H3: November | I3: December | J3: Sum | K3: Totals | L3: January | M3: Febuary | N3: March | O3: April | P3: May | Q3: June | R3: July | S3: August | T3: September | U3: October | V3: November | W3: December | X3: Sum | Y3: Totals | Z3: January | AA3: Febuary | AB3: March | AC3: April | AD3: May | AE3: June | AF3: July | AG3: August | AH3: September | AI3: October | AJ3: November | AK3: December | AL3: Sum | AM3: Totals | AN3: Total Calls | AO3: Average Call Attendance
A4: CFO John Robinson | B4: 21 | C4: 25 | D4: 16 | E4: 15 | F4: 11 | G4: 20 | H4: 18 | I4: 25 | J4: =SUM($B4:$I4) -> 151 | K4: =(J4/$J$2) -> 0.46604938 | L4: 34 | M4: 22 | N4: 22 | O4: 19 | P4: 24 | Q4: 19 | R4: 27 | S4: 18 | T4: 18 | U4: 17 | V4: 16 | W4: 21 | X4: 257 | Y4: 0.46206116 | Z4: =COUNTIFS((AllCalls25!$X$15:$X$5631),"I",(AllCalls25!$K$15:$K$5631),"1") -> 35 | AA4: =COUNTIFS((AllCalls25!$X$15:$X$5631),"I",(AllCalls25!$K$15:$K$5631),"2") -> 27 | AB4: =COUNTIFS((AllCalls25!$X$15:$X$5631),"I",(AllCalls25!$K$15:$K$5631),"3") -> 36 | AC4: =COUNTIFS((AllCalls25!$X$15:$X$5631),"I",(AllCalls25!$K$15:$K$5631),"4") -> 20 | AD4: =COUNTIFS((AllCalls25!$X$15:$X$5631),"I",(AllCalls25!$K$15:$K$5631),"5") -> 29 | AE4: =COUNTIFS((AllCalls25!$X$15:$X$5631),"I",(AllCalls25!$K$15:$K$5631),"6") -> 16 | AF4: =COUNTIFS((AllCalls25!$X$15:$X$5631),"I",(AllCalls25!$K$15:$K$5631),"7") -> 21 | AG4: =COUNTIFS((AllCalls25!$X$15:$X$5631),"I",(AllCalls25!$K$15:$K$5631),"8") -> 18 | AH4: =COUNTIFS((AllCalls25!$X$15:$X$5631),"I",(AllCalls25!$K$15:$K$5631),"9") -> 22 | AI4: =COUNTIFS((AllCalls25!$X$15:$X$5631),"I",(AllCalls25!$K$15:$K$5631),"10") -> 9 | AJ4: =COUNTIFS((AllCalls25!$X$15:$X$5631),"I",(AllCalls25!$K$15:$K$5631),"11") -> 24 | AK4: =COUNTIFS((AllCalls25!$X$15:$X$5631),"I",(AllCalls25!$K$15:$K$5631),"12") -> 50 | AL4: =SUM($Z4:$AK4) -> 307 | AM4: =(SUM($AL4))/SUM($AL$2) -> 0.4708589 | AN4: =SUM($J4,$X4,$AL4) -> 715 | AO4: =(SUM(AN4))/SUM($AN$2) -> 0.46579805 | AP4: OF
A5: DCFO Bharat Ravji | B5: 14 | C5: 13 | D5: 21 | E5: 15 | F5: 2 | G5: 14 | H5: 26 | I5: 20 | J5: =SUM($B5:$I5) -> 125 | K5: =(J5/$J$2) -> 0.38580247 | L5: 40 | M5: 24 | N5: 17 | O5: 26 | P5: 29 | Q5: 14 | R5: 29 | S5: 24 | T5: 2 | U5: 17 | V5: 19 | W5: 2 | X5: 243 | Y5: 0.41676104 | Z5: =COUNTIFS((AllCalls25!$Y$15:$Y$5631),"I",(AllCalls25!$K$15:$K$5631),"1") -> 21 | AA5: =COUNTIFS((AllCalls25!$Y$15:$Y$5631),"I",(AllCalls25!$K$15:$K$5631),"2") -> 32 | AB5: =COUNTIFS((AllCalls25!$Y$15:$Y$5631),"I",(AllCalls25!$K$15:$K$5631),"3") -> 43 | AC5: =COUNTIFS((AllCalls25!$Y$15:$Y$5631),"I",(AllCalls25!$K$15:$K$5631),"4") -> 26 | AD5: =COUNTIFS((AllCalls25!$Y$15:$Y$5631),"I",(AllCalls25!$K$15:$K$5631),"5") -> 37 | AE5: =COUNTIFS((AllCalls25!$Y$15:$Y$5631),"I",(AllCalls25!$K$15:$K$5631),"6") -> 18 | AF5: =COUNTIFS((AllCalls25!$Y$15:$Y$5631),"I",(AllCalls25!$K$15:$K$5631),"7") -> 35 | AG5: =COUNTIFS((AllCalls25!$Y$15:$Y$5631),"I",(AllCalls25!$K$15:$K$5631),"8") -> 33 | AH5: =COUNTIFS((AllCalls25!$Y$15:$Y$5631),"I",(AllCalls25!$K$15:$K$5631),"9") -> 0 | AI5: =COUNTIFS((AllCalls25!$Y$15:$Y$5631),"I",(AllCalls25!$K$15:$K$5631),"10") -> 19 | AJ5: =COUNTIFS((AllCalls25!$Y$15:$Y$5631),"I",(AllCalls25!$K$15:$K$5631),"11") -> 39 | AK5: =COUNTIFS((AllCalls25!$Y$15:$Y$5631),"I",(AllCalls25!$K$15:$K$5631),"12") -> 57 | AL5: =SUM($Z5:$AK5) -> 360 | AM5: =(SUM($AL5))/SUM($AL$2) -> 0.55214724 | AN5: =SUM($J5,$X5,$AL5) -> 728 | AO5: =(SUM(AN5))/SUM($AN$2) -> 0.4742671 | AP5: OF
A6: SSO Darcy Hart | B6: 4 | C6: 10 | D6: 10 | E6: 9 | F6: 12 | G6: 18 | H6: 12 | I6: 16 | J6: =SUM($B6:$I6) -> 91 | K6: =(J6/$J$2) -> 0.2808642 | L6: 18 | M6: 13 | N6: 8 | O6: 8 | P6: 10 | Q6: 5 | R6: 17 | S6: 21 | T6: 11 | U6: 17 | V6: 7 | W6: 30 | X6: 165 | Y6: 0.28992072 | Z6: =COUNTIFS((AllCalls25!$Z$15:$Z$5631),"I",(AllCalls25!$K$15:$K$5631),"1") -> 16 | AA6: =COUNTIFS((AllCalls25!$Z$15:$Z$5631),"I",(AllCalls25!$K$15:$K$5631),"2") -> 13 | AB6: =COUNTIFS((AllCalls25!$Z$15:$Z$5631),"I",(AllCalls25!$K$15:$K$5631),"3") -> 11 | AC6: =COUNTIFS((AllCalls25!$Z$15:$Z$5631),"I",(AllCalls25!$K$15:$K$5631),"4") -> 18 | AD6: =COUNTIFS((AllCalls25!$Z$15:$Z$5631),"I",(AllCalls25!$K$15:$K$5631),"5") -> 21 | AE6: =COUNTIFS((AllCalls25!$Z$15:$Z$5631),"I",(AllCalls25!$K$15:$K$5631),"6") -> 6 | AF6: =COUNTIFS((AllCalls25!$Z$15:$Z$5631),"I",(AllCalls25!$K$15:$K$5631),"7") -> 19 | AG6: =COUNTIFS((AllCalls25!$Z$15:$Z$5631),"I",(AllCalls25!$K$15:$K$5631),"8") -> 13 | AH6: =COUNTIFS((AllCalls25!$Z$15:$Z$5631),"I",(AllCalls25!$K$15:$K$5631),"9") -> 12 | AI6: =COUNTIFS((AllCalls25!$Z$15:$Z$5631),"I",(AllCalls25!$K$15:$K$5631),"10") -> 11 | AJ6: =COUNTIFS((AllCalls25!$Z$15:$Z$5631),"I",(AllCalls25!$K$15:$K$5631),"11") -> 13 | AK6: =COUNTIFS((AllCalls25!$Z$15:$Z$5631),"I",(AllCalls25!$K$15:$K$5631),"12") -> 16 | AL6: =SUM($Z6:$AK6) -> 169 | AM6: =(SUM($AL6))/SUM($AL$2) -> 0.25920245 | AN6: =SUM($J6,$X6,$AL6) -> 425 | AO6: =(SUM(AN6))/SUM($AN$2) -> 0.27687296 | AP6: OF
A7: SSO Vaughan Wood | B7: 21 | C7: 15 | D7: 34 | E7: 9 | F7: 13 | G7: 14 | H7: 26 | I7: 22 | J7: =SUM($B7:$I7) -> 154 | K7: =(J7/$J$2) -> 0.47530864 | L7: 50 | M7: 27 | N7: 17 | O7: 26 | P7: 27 | Q7: 23 | R7: 36 | S7: 27 | T7: 20 | U7: 20 | V7: 30 | W7: 34 | X7: 337 | Y7: 0.55605889 | Z7: =COUNTIFS((AllCalls25!$AA$15:$AA$5631),"I",(AllCalls25!$K$15:$K$5631),"1") -> 30 | AA7: =COUNTIFS((AllCalls25!$AA$15:$AA$5631),"I",(AllCalls25!$K$15:$K$5631),"2") -> 33 | AB7: =COUNTIFS((AllCalls25!$AA$15:$AA$5631),"I",(AllCalls25!$K$15:$K$5631),"3") -> 39 | AC7: =COUNTIFS((AllCalls25!$AA$15:$AA$5631),"I",(AllCalls25!$K$15:$K$5631),"4") -> 24 | AD7: =COUNTIFS((AllCalls25!$AA$15:$AA$5631),"I",(AllCalls25!$K$15:$K$5631),"5") -> 21 | AE7: =COUNTIFS((AllCalls25!$AA$15:$AA$5631),"I",(AllCalls25!$K$15:$K$5631),"6") -> 21 | AF7: =COUNTIFS((AllCalls25!$AA$15:$AA$5631),"I",(AllCalls25!$K$15:$K$5631),"7") -> 43 | AG7: =COUNTIFS((AllCalls25!$AA$15:$AA$5631),"I",(AllCalls25!$K$15:$K$5631),"8") -> 33 | AH7: =COUNTIFS((AllCalls25!$AA$15:$AA$5631),"I",(AllCalls25!$K$15:$K$5631),"9") -> 39 | AI7: =COUNTIFS((AllCalls25!$AA$15:$AA$5631),"I",(AllCalls25!$K$15:$K$5631),"10") -> 29 | AJ7: =COUNTIFS((AllCalls25!$AA$15:$AA$5631),"I",(AllCalls25!$K$15:$K$5631),"11") -> 49 | AK7: =COUNTIFS((AllCalls25!$AA$15:$AA$5631),"I",(AllCalls25!$K$15:$K$5631),"12") -> 70 | AL7: =SUM($Z7:$AK7) -> 431 | AM7: =(SUM($AL7))/SUM($AL$2) -> 0.66104294 | AN7: =SUM($J7,$X7,$AL7) -> 922 | AO7: =(SUM(AN7))/SUM($AN$2) -> 0.60065147 | AP7: OF
A8: SO Richard Jellyman | B8: 8 | C8: 23 | D8: 22 | E8: 10 | F8: 10 | G8: 25 | H8: 13 | I8: 10 | J8: =SUM($B8:$I8) -> 121 | K8: =(J8/$J$2) -> 0.37345679 | L8: 3 | M8: 11 | N8: 19 | O8: 8 | P8: 12 | Q8: 2 | R8: 14 | S8: 20 | T8: 6 | U8: 6 | V8: 21 | W8: 23 | X8: 145 | Y8: 0.30124575 | Z8: =COUNTIFS((AllCalls25!$AB$15:$AB$5631),"I",(AllCalls25!$K$15:$K$5631),"1") -> 19 | AA8: =COUNTIFS((AllCalls25!$AB$15:$AB$5631),"I",(AllCalls25!$K$15:$K$5631),"2") -> 15 | AB8: =COUNTIFS((AllCalls25!$AB$15:$AB$5631),"I",(AllCalls25!$K$15:$K$5631),"3") -> 26 | AC8: =COUNTIFS((AllCalls25!$AB$15:$AB$5631),"I",(AllCalls25!$K$15:$K$5631),"4") -> 26 | AD8: =COUNTIFS((AllCalls25!$AB$15:$AB$5631),"I",(AllCalls25!$K$15:$K$5631),"5") -> 40 | AE8: =COUNTIFS((AllCalls25!$AB$15:$AB$5631),"I",(AllCalls25!$K$15:$K$5631),"6") -> 18 | AF8: =COUNTIFS((AllCalls25!$AB$15:$AB$5631),"I",(AllCalls25!$K$15:$K$5631),"7") -> 29 | AG8: =COUNTIFS((AllCalls25!$AB$15:$AB$5631),"I",(AllCalls25!$K$15:$K$5631),"8") -> 0 | AH8: =COUNTIFS((AllCalls25!$AB$15:$AB$5631),"I",(AllCalls25!$K$15:$K$5631),"9") -> 16 | AI8: =COUNTIFS((AllCalls25!$AB$15:$AB$5631),"I",(AllCalls25!$K$15:$K$5631),"10") -> 9 | AJ8: =COUNTIFS((AllCalls25!$AB$15:$AB$5631),"I",(AllCalls25!$K$15:$K$5631),"11") -> 8 | AK8: =COUNTIFS((AllCalls25!$AB$15:$AB$5631),"I",(AllCalls25!$K$15:$K$5631),"12") -> 28 | AL8: =SUM($Z8:$AK8) -> 234 | AM8: =(SUM($AL8))/SUM($AL$2) -> 0.35889571 | AN8: =SUM($J8,$X8,$AL8) -> 500 | AO8: =(SUM(AN8))/SUM($AN$2) -> 0.3257329 | AP8: OF
A9: SO Richard Irving | B9: 18 | C9: 17 | D9: 21 | E9: 7 | F9: 18 | G9: 10 | H9: 7 | I9: 7 | J9: =SUM($B9:$I9) -> 105 | K9: =(J9/$J$2) -> 0.32407407 | L9: 12 | M9: 13 | N9: 2 | O9: 10 | P9: 32 | Q9: 3 | R9: 4 | S9: 12 | T9: 14 | U9: 4 | V9: 5 | W9: 25 | X9: 136 | Y9: 0.27293318 | Z9: =COUNTIFS((AllCalls25!$AC$15:$AC$5631),"I",(AllCalls25!$K$15:$K$5631),"1") -> 13 | AA9: =COUNTIFS((AllCalls25!$AC$15:$AC$5631),"I",(AllCalls25!$K$15:$K$5631),"2") -> 7 | AB9: =COUNTIFS((AllCalls25!$AC$15:$AC$5631),"I",(AllCalls25!$K$15:$K$5631),"3") -> 11 | AC9: =COUNTIFS((AllCalls25!$AC$15:$AC$5631),"I",(AllCalls25!$K$15:$K$5631),"4") -> 8 | AD9: =COUNTIFS((AllCalls25!$AC$15:$AC$5631),"I",(AllCalls25!$K$15:$K$5631),"5") -> 19 | AE9: =COUNTIFS((AllCalls25!$AC$15:$AC$5631),"I",(AllCalls25!$K$15:$K$5631),"6") -> 12 | AF9: =COUNTIFS((AllCalls25!$AC$15:$AC$5631),"I",(AllCalls25!$K$15:$K$5631),"7") -> 18 | AG9: =COUNTIFS((AllCalls25!$AC$15:$AC$5631),"I",(AllCalls25!$K$15:$K$5631),"8") -> 5 | AH9: =COUNTIFS((AllCalls25!$AC$15:$AC$5631),"I",(AllCalls25!$K$15:$K$5631),"9") -> 8 | AI9: =COUNTIFS((AllCalls25!$AC$15:$AC$5631),"I",(AllCalls25!$K$15:$K$5631),"10") -> 2 | AJ9: =COUNTIFS((AllCalls25!$AC$15:$AC$5631),"I",(AllCalls25!$K$15:$K$5631),"11") -> 19 | AK9: =COUNTIFS((AllCalls25!$AC$15:$AC$5631),"I",(AllCalls25!$K$15:$K$5631),"12") -> 6 | AL9: =SUM($Z9:$AK9) -> 128 | AM9: =(SUM($AL9))/SUM($AL$2) -> 0.19631902 | AN9: =SUM($J9,$X9,$AL9) -> 369 | AO9: =(SUM(AN9))/SUM($AN$2) -> 0.24039088 | AP9: OF
A10: SO Darryn Pritchard | B10: 16 | C10: 34 | D10: 31 | E10: 13 | F10: 10 | G10: 17 | H10: 23 | I10: 22 | J10: =SUM($B10:$I10) -> 166 | K10: =(J10/$J$2) -> 0.51234568 | L10: 13 | M10: 30 | N10: 30 | O10: 21 | P10: 33 | Q10: 2 | R10: 22 | S10: 8 | T10: 13 | U10: 18 | V10: 20 | W10: 27 | X10: 237 | Y10: 0.45639864 | Z10: =COUNTIFS((AllCalls25!$AD$15:$AD$5631),"I",(AllCalls25!$K$15:$K$5631),"1") -> 2 | AA10: =COUNTIFS((AllCalls25!$AD$15:$AD$5631),"I",(AllCalls25!$K$15:$K$5631),"2") -> 6 | AB10: =COUNTIFS((AllCalls25!$AD$15:$AD$5631),"I",(AllCalls25!$K$15:$K$5631),"3") -> 26 | AC10: =COUNTIFS((AllCalls25!$AD$15:$AD$5631),"I",(AllCalls25!$K$15:$K$5631),"4") -> 19 | AD10: =COUNTIFS((AllCalls25!$AD$15:$AD$5631),"I",(AllCalls25!$K$15:$K$5631),"5") -> 22 | AE10: =COUNTIFS((AllCalls25!$AD$15:$AD$5631),"I",(AllCalls25!$K$15:$K$5631),"6") -> 17 | AF10: =COUNTIFS((AllCalls25!$AD$15:$AD$5631),"I",(AllCalls25!$K$15:$K$5631),"7") -> 23 | AG10: =COUNTIFS((AllCalls25!$AD$15:$AD$5631),"I",(AllCalls25!$K$15:$K$5631),"8") -> 27 | AH10: =COUNTIFS((AllCalls25!$AD$15:$AD$5631),"I",(AllCalls25!$K$15:$K$5631),"9") -> 20 | AI10: =COUNTIFS((AllCalls25!$AD$15:$AD$5631),"I",(AllCalls25!$K$15:$K$5631),"10") -> 12 | AJ10: =COUNTIFS((AllCalls25!$AD$15:$AD$5631),"I",(AllCalls25!$K$15:$K$5631),"11") -> 21 | AK10: =COUNTIFS((AllCalls25!$AD$15:$AD$5631),"I",(AllCalls25!$K$15:$K$5631),"12") -> 17 | AL10: =SUM($Z10:$AK10) -> 212 | AM10: =(SUM($AL10))/SUM($AL$2) -> 0.32515337 | AN10: =SUM($J10,$X10,$AL10) -> 615 | AO10: =(SUM(AN10))/SUM($AN$2) -> 0.40065147 | AP10: OF
A11: SO Jon White | B11: 7 | C11: 0 | D11: 13 | E11: 11 | F11: 14 | G11: 30 | H11: 14 | I11: 22 | J11: =SUM($B11:$I11) -> 111 | K11: =(J11/$J$2) -> 0.34259259 | L11: 27 | M11: 21 | N11: 19 | O11: 17 | P11: 20 | Q11: 18 | R11: 18 | S11: 20 | T11: 14 | U11: 21 | V11: 17 | W11: 18 | X11: 230 | Y11: 0.38618347 | Z11: =COUNTIFS((AllCalls25!$AE$15:$AE$5631),"I",(AllCalls25!$K$15:$K$5631),"1") -> 13 | AA11: =COUNTIFS((AllCalls25!$AE$15:$AE$5631),"I",(AllCalls25!$K$15:$K$5631),"2") -> 0 | AB11: =COUNTIFS((AllCalls25!$AE$15:$AE$5631),"I",(AllCalls25!$K$15:$K$5631),"3") -> 3 | AC11: =COUNTIFS((AllCalls25!$AE$15:$AE$5631),"I",(AllCalls25!$K$15:$K$5631),"4") -> 8 | AD11: =COUNTIFS((AllCalls25!$AE$15:$AE$5631),"I",(AllCalls25!$K$15:$K$5631),"5") -> 28 | AE11: =COUNTIFS((AllCalls25!$AE$15:$AE$5631),"I",(AllCalls25!$K$15:$K$5631),"6") -> 14 | AF11: =COUNTIFS((AllCalls25!$AE$15:$AE$5631),"I",(AllCalls25!$K$15:$K$5631),"7") -> 14 | AG11: =COUNTIFS((AllCalls25!$AE$15:$AE$5631),"I",(AllCalls25!$K$15:$K$5631),"8") -> 23 | AH11: =COUNTIFS((AllCalls25!$AE$15:$AE$5631),"I",(AllCalls25!$K$15:$K$5631),"9") -> 16 | AI11: =COUNTIFS((AllCalls25!$AE$15:$AE$5631),"I",(AllCalls25!$K$15:$K$5631),"10") -> 11 | AJ11: =COUNTIFS((AllCalls25!$AE$15:$AE$5631),"I",(AllCalls25!$K$15:$K$5631),"11") -> 18 | AK11: =COUNTIFS((AllCalls25!$AE$15:$AE$5631),"I",(AllCalls25!$K$15:$K$5631),"12") -> 39 | AL11: =SUM($Z11:$AK11) -> 187 | AM11: =(SUM($AL11))/SUM($AL$2) -> 0.28680982 | AN11: =SUM($J11,$X11,$AL11) -> 528 | AO11: =(SUM(AN11))/SUM($AN$2) -> 0.34397394 | AP11: OF
A12: SFF Brent Reynolds | B12: 7 | C12: 11 | D12: 11 | E12: 11 | F12: 6 | G12: 9 | H12: 5 | I12: 10 | J12: =SUM($B12:$I12) -> 70 | K12: =(J12/$J$2) -> 0.21604938 | L12: 12 | M12: 11 | N12: 5 | O12: 10 | P12: 9 | Q12: 4 | R12: 10 | S12: 4 | T12: 5 | U12: 21 | V12: 25 | W12: 27 | X12: 143 | Y12: 0.2412231 | Z12: =COUNTIFS((AllCalls25!$AF$15:$AF$5631),"I",(AllCalls25!$K$15:$K$5631),"1") -> 14 | AA12: =COUNTIFS((AllCalls25!$AF$15:$AF$5631),"I",(AllCalls25!$K$15:$K$5631),"2") -> 4 | AB12: =COUNTIFS((AllCalls25!$AF$15:$AF$5631),"I",(AllCalls25!$K$15:$K$5631),"3") -> 15 | AC12: =COUNTIFS((AllCalls25!$AF$15:$AF$5631),"I",(AllCalls25!$K$15:$K$5631),"4") -> 17 | AD12: =COUNTIFS((AllCalls25!$AF$15:$AF$5631),"I",(AllCalls25!$K$15:$K$5631),"5") -> 22 | AE12: =COUNTIFS((AllCalls25!$AF$15:$AF$5631),"I",(AllCalls25!$K$15:$K$5631),"6") -> 9 | AF12: =COUNTIFS((AllCalls25!$AF$15:$AF$5631),"I",(AllCalls25!$K$15:$K$5631),"7") -> 17 | AG12: =COUNTIFS((AllCalls25!$AF$15:$AF$5631),"I",(AllCalls25!$K$15:$K$5631),"8") -> 7 | AH12: =COUNTIFS((AllCalls25!$AF$15:$AF$5631),"I",(AllCalls25!$K$15:$K$5631),"9") -> 3 | AI12: =COUNTIFS((AllCalls25!$AF$15:$AF$5631),"I",(AllCalls25!$K$15:$K$5631),"10") -> 8 | AJ12: =COUNTIFS((AllCalls25!$AF$15:$AF$5631),"I",(AllCalls25!$K$15:$K$5631),"11") -> 14 | AK12: =COUNTIFS((AllCalls25!$AF$15:$AF$5631),"I",(AllCalls25!$K$15:$K$5631),"12") -> 3 | AL12: =SUM($Z12:$AK12) -> 133 | AM12: =(SUM($AL12))/SUM($AL$2) -> 0.20398773 | AN12: =SUM($J12,$X12,$AL12) -> 346 | AO12: =(SUM(AN12))/SUM($AN$2) -> 0.22540717 | AP12: DR*
A13: SFF Joseph O'Neill-Gregory | B13: 8 | C13: 17 | D13: 19 | E13: 4 | F13: 1 | G13: 22 | H13: 14 | I13: 12 | J13: =SUM($B13:$I13) -> 97 | K13: =(J13/$J$2) -> 0.29938272 | L13: 21 | M13: 13 | N13: 3 | O13: 15 | P13: 16 | Q13: 12 | R13: 5 | S13: 0 | T13: 3 | U13: 13 | V13: 14 | W13: 19 | X13: 134 | Y13: 0.26160815 | Z13: =COUNTIFS((AllCalls25!$AG$15:$AG$5631),"I",(AllCalls25!$K$15:$K$5631),"1") -> 16 | AA13: =COUNTIFS((AllCalls25!$AG$15:$AG$5631),"I",(AllCalls25!$K$15:$K$5631),"2") -> 11 | AB13: =COUNTIFS((AllCalls25!$AG$15:$AG$5631),"I",(AllCalls25!$K$15:$K$5631),"3") -> 8 | AC13: =COUNTIFS((AllCalls25!$AG$15:$AG$5631),"I",(AllCalls25!$K$15:$K$5631),"4") -> 5 | AD13: =COUNTIFS((AllCalls25!$AG$15:$AG$5631),"I",(AllCalls25!$K$15:$K$5631),"5") -> 14 | AE13: =COUNTIFS((AllCalls25!$AG$15:$AG$5631),"I",(AllCalls25!$K$15:$K$5631),"6") -> 10 | AF13: =COUNTIFS((AllCalls25!$AG$15:$AG$5631),"I",(AllCalls25!$K$15:$K$5631),"7") -> 11 | AG13: =COUNTIFS((AllCalls25!$AG$15:$AG$5631),"I",(AllCalls25!$K$15:$K$5631),"8") -> 13 | AH13: =COUNTIFS((AllCalls25!$AG$15:$AG$5631),"I",(AllCalls25!$K$15:$K$5631),"9") -> 3 | AI13: =COUNTIFS((AllCalls25!$AG$15:$AG$5631),"I",(AllCalls25!$K$15:$K$5631),"10") -> 6 | AJ13: =COUNTIFS((AllCalls25!$AG$15:$AG$5631),"I",(AllCalls25!$K$15:$K$5631),"11") -> 8 | AK13: =COUNTIFS((AllCalls25!$AG$15:$AG$5631),"I",(AllCalls25!$K$15:$K$5631),"12") -> 37 | AL13: =SUM($Z13:$AK13) -> 142 | AM13: =(SUM($AL13))/SUM($AL$2) -> 0.21779141 | AN13: =SUM($J13,$X13,$AL13) -> 373 | AO13: =(SUM(AN13))/SUM($AN$2) -> 0.24299674 | AP13: DR
A14: SFF Grant Robertson | B14: 22 | C14: 33 | D14: 27 | E14: 12 | F14: 18 | G14: 21 | H14: 11 | I14: 16 | J14: =SUM($B14:$I14) -> 160 | K14: =(J14/$J$2) -> 0.49382716 | L14: 24 | M14: 20 | N14: 24 | O14: 23 | P14: 33 | Q14: 21 | R14: 27 | S14: 28 | T14: 25 | U14: 29 | V14: 21 | W14: 24 | X14: 299 | Y14: 0.5198188 | Z14: =COUNTIFS((AllCalls25!$AH$15:$AH$5631),"I",(AllCalls25!$K$15:$K$5631),"1") -> 32 | AA14: =COUNTIFS((AllCalls25!$AH$15:$AH$5631),"I",(AllCalls25!$K$15:$K$5631),"2") -> 32 | AB14: =COUNTIFS((AllCalls25!$AH$15:$AH$5631),"I",(AllCalls25!$K$15:$K$5631),"3") -> 33 | AC14: =COUNTIFS((AllCalls25!$AH$15:$AH$5631),"I",(AllCalls25!$K$15:$K$5631),"4") -> 30 | AD14: =COUNTIFS((AllCalls25!$AH$15:$AH$5631),"I",(AllCalls25!$K$15:$K$5631),"5") -> 31 | AE14: =COUNTIFS((AllCalls25!$AH$15:$AH$5631),"I",(AllCalls25!$K$15:$K$5631),"6") -> 12 | AF14: =COUNTIFS((AllCalls25!$AH$15:$AH$5631),"I",(AllCalls25!$K$15:$K$5631),"7") -> 40 | AG14: =COUNTIFS((AllCalls25!$AH$15:$AH$5631),"I",(AllCalls25!$K$15:$K$5631),"8") -> 38 | AH14: =COUNTIFS((AllCalls25!$AH$15:$AH$5631),"I",(AllCalls25!$K$15:$K$5631),"9") -> 32 | AI14: =COUNTIFS((AllCalls25!$AH$15:$AH$5631),"I",(AllCalls25!$K$15:$K$5631),"10") -> 28 | AJ14: =COUNTIFS((AllCalls25!$AH$15:$AH$5631),"I",(AllCalls25!$K$15:$K$5631),"11") -> 38 | AK14: =COUNTIFS((AllCalls25!$AH$15:$AH$5631),"I",(AllCalls25!$K$15:$K$5631),"12") -> 61 | AL14: =SUM($Z14:$AK14) -> 407 | AM14: =(SUM($AL14))/SUM($AL$2) -> 0.62423313 | AN14: =SUM($J14,$X14,$AL14) -> 866 | AO14: =(SUM(AN14))/SUM($AN$2) -> 0.56416938 | AP14: DR*
A15: SFF William O'Connell | B15: 9 | C15: 11 | D15: 13 | E15: 9 | F15: 13 | G15: 12 | H15: 7 | I15: 13 | J15: =SUM($B15:$I15) -> 87 | K15: =(J15/$J$2) -> 0.26851852 | L15: 15 | M15: 20 | N15: 11 | O15: 6 | P15: 15 | Q15: 12 | R15: 12 | S15: 16 | T15: 12 | U15: 15 | V15: 26 | W15: 19 | X15: 179 | Y15: 0.30124575 | Z15: =COUNTIFS((AllCalls25!$AI$15:$AI$5631),"I",(AllCalls25!$K$15:$K$5631),"1") -> 23 | AA15: =COUNTIFS((AllCalls25!$AI$15:$AI$5631),"I",(AllCalls25!$K$15:$K$5631),"2") -> 14 | AB15: =COUNTIFS((AllCalls25!$AI$15:$AI$5631),"I",(AllCalls25!$K$15:$K$5631),"3") -> 19 | AC15: =COUNTIFS((AllCalls25!$AI$15:$AI$5631),"I",(AllCalls25!$K$15:$K$5631),"4") -> 12 | AD15: =COUNTIFS((AllCalls25!$AI$15:$AI$5631),"I",(AllCalls25!$K$15:$K$5631),"5") -> 19 | AE15: =COUNTIFS((AllCalls25!$AI$15:$AI$5631),"I",(AllCalls25!$K$15:$K$5631),"6") -> 13 | AF15: =COUNTIFS((AllCalls25!$AI$15:$AI$5631),"I",(AllCalls25!$K$15:$K$5631),"7") -> 8 | AG15: =COUNTIFS((AllCalls25!$AI$15:$AI$5631),"I",(AllCalls25!$K$15:$K$5631),"8") -> 25 | AH15: =COUNTIFS((AllCalls25!$AI$15:$AI$5631),"I",(AllCalls25!$K$15:$K$5631),"9") -> 10 | AI15: =COUNTIFS((AllCalls25!$AI$15:$AI$5631),"I",(AllCalls25!$K$15:$K$5631),"10") -> 17 | AJ15: =COUNTIFS((AllCalls25!$AI$15:$AI$5631),"I",(AllCalls25!$K$15:$K$5631),"11") -> 11 | AK15: =COUNTIFS((AllCalls25!$AI$15:$AI$5631),"I",(AllCalls25!$K$15:$K$5631),"12") -> 47 | AL15: =SUM($Z15:$AK15) -> 218 | AM15: =(SUM($AL15))/SUM($AL$2) -> 0.33435583 | AN15: =SUM($J15,$X15,$AL15) -> 484 | AO15: =(SUM(AN15))/SUM($AN$2) -> 0.31530945 | AP15: DR*
A16: SFF Robert Mayo | B16: 9 | C16: 15 | D16: 13 | E16: 12 | F16: 12 | G16: 11 | H16: 17 | I16: 3 | J16: =SUM($B16:$I16) -> 92 | K16: =(J16/$J$2) -> 0.28395062 | L16: 20 | M16: 15 | N16: 16 | O16: 14 | P16: 27 | Q16: 17 | R16: 10 | S16: 15 | T16: 13 | U16: 9 | V16: 16 | W16: 17 | X16: 189 | Y16: 0.3182333 | Z16: =COUNTIFS((AllCalls25!$AJ$15:$AJ$5631),"I",(AllCalls25!$K$15:$K$5631),"1") -> 30 | AA16: =COUNTIFS((AllCalls25!$AJ$15:$AJ$5631),"I",(AllCalls25!$K$15:$K$5631),"2") -> 31 | AB16: =COUNTIFS((AllCalls25!$AJ$15:$AJ$5631),"I",(AllCalls25!$K$15:$K$5631),"3") -> 38 | AC16: =COUNTIFS((AllCalls25!$AJ$15:$AJ$5631),"I",(AllCalls25!$K$15:$K$5631),"4") -> 24 | AD16: =COUNTIFS((AllCalls25!$AJ$15:$AJ$5631),"I",(AllCalls25!$K$15:$K$5631),"5") -> 41 | AE16: =COUNTIFS((AllCalls25!$AJ$15:$AJ$5631),"I",(AllCalls25!$K$15:$K$5631),"6") -> 25 | AF16: =COUNTIFS((AllCalls25!$AJ$15:$AJ$5631),"I",(AllCalls25!$K$15:$K$5631),"7") -> 33 | AG16: =COUNTIFS((AllCalls25!$AJ$15:$AJ$5631),"I",(AllCalls25!$K$15:$K$5631),"8") -> 37 | AH16: =COUNTIFS((AllCalls25!$AJ$15:$AJ$5631),"I",(AllCalls25!$K$15:$K$5631),"9") -> 32 | AI16: =COUNTIFS((AllCalls25!$AJ$15:$AJ$5631),"I",(AllCalls25!$K$15:$K$5631),"10") -> 22 | AJ16: =COUNTIFS((AllCalls25!$AJ$15:$AJ$5631),"I",(AllCalls25!$K$15:$K$5631),"11") -> 46 | AK16: =COUNTIFS((AllCalls25!$AJ$15:$AJ$5631),"I",(AllCalls25!$K$15:$K$5631),"12") -> 33 | AL16: =SUM($Z16:$AK16) -> 392 | AM16: =(SUM($AL16))/SUM($AL$2) -> 0.60122699 | AN16: =SUM($J16,$X16,$AL16) -> 673 | AO16: =(SUM(AN16))/SUM($AN$2) -> 0.43843648 | AP16: DR
A17: SFF Brody Jellyman | X17: 0 | Z17: =COUNTIFS((AllCalls25!$AK$15:$AK$5631),"I",(AllCalls25!$K$15:$K$5631),"1") -> 7 | AA17: =COUNTIFS((AllCalls25!$AK$15:$AK$5631),"I",(AllCalls25!$K$15:$K$5631),"2") -> 22 | AB17: =COUNTIFS((AllCalls25!$AK$15:$AK$5631),"I",(AllCalls25!$K$15:$K$5631),"3") -> 28 | AC17: =COUNTIFS((AllCalls25!$AK$15:$AK$5631),"I",(AllCalls25!$K$15:$K$5631),"4") -> 18 | AD17: =COUNTIFS((AllCalls25!$AK$15:$AK$5631),"I",(AllCalls25!$K$15:$K$5631),"5") -> 32 | AE17: =COUNTIFS((AllCalls25!$AK$15:$AK$5631),"I",(AllCalls25!$K$15:$K$5631),"6") -> 13 | AF17: =COUNTIFS((AllCalls25!$AK$15:$AK$5631),"I",(AllCalls25!$K$15:$K$5631),"7") -> 22 | AG17: =COUNTIFS((AllCalls25!$AK$15:$AK$5631),"I",(AllCalls25!$K$15:$K$5631),"8") -> 24 | AH17: =COUNTIFS((AllCalls25!$AK$15:$AK$5631),"I",(AllCalls25!$K$15:$K$5631),"9") -> 16 | AI17: =COUNTIFS((AllCalls25!$AK$15:$AK$5631),"I",(AllCalls25!$K$15:$K$5631),"10") -> 12 | AJ17: =COUNTIFS((AllCalls25!$AK$15:$AK$5631),"I",(AllCalls25!$K$15:$K$5631),"11") -> 20 | AK17: =COUNTIFS((AllCalls25!$AK$15:$AK$5631),"I",(AllCalls25!$K$15:$K$5631),"12") -> 29 | AL17: =SUM($Z17:$AK17) -> 243 | AM17: =(SUM($AA17:$AK17))/SUM($AA$2:$AK$2) -> 0.39663866 | AN17: =SUM($AL17) -> 243 | AO17: =(SUM(AA17:AK17))/SUM($AA$2:$AK$2) -> 0.39663866 | AP17: DR
A18: QFF Symon Maxwell | B18: 4 | C18: 21 | D18: 17 | E18: 15 | F18: 16 | G18: 28 | H18: 22 | I18: 17 | J18: =SUM($B18:$I18) -> 140 | K18: =(J18/$J$2) -> 0.43209877 | L18: 34 | M18: 22 | N18: 16 | O18: 21 | P18: 25 | Q18: 12 | R18: 18 | S18: 22 | T18: 15 | U18: 25 | V18: 23 | W18: 20 | X18: 253 | Y18: 0.44507361 | Z18: =COUNTIFS((AllCalls25!$AL$15:$AL$5631),"I",(AllCalls25!$K$15:$K$5631),"1") -> 28 | AA18: =COUNTIFS((AllCalls25!$AL$15:$AL$5631),"I",(AllCalls25!$K$15:$K$5631),"2") -> 15 | AB18: =COUNTIFS((AllCalls25!$AL$15:$AL$5631),"I",(AllCalls25!$K$15:$K$5631),"3") -> 17 | AC18: =COUNTIFS((AllCalls25!$AL$15:$AL$5631),"I",(AllCalls25!$K$15:$K$5631),"4") -> 21 | AD18: =COUNTIFS((AllCalls25!$AL$15:$AL$5631),"I",(AllCalls25!$K$15:$K$5631),"5") -> 24 | AE18: =COUNTIFS((AllCalls25!$AL$15:$AL$5631),"I",(AllCalls25!$K$15:$K$5631),"6") -> 19 | AF18: =COUNTIFS((AllCalls25!$AL$15:$AL$5631),"I",(AllCalls25!$K$15:$K$5631),"7") -> 25 | AG18: =COUNTIFS((AllCalls25!$AL$15:$AL$5631),"I",(AllCalls25!$K$15:$K$5631),"8") -> 18 | AH18: =COUNTIFS((AllCalls25!$AL$15:$AL$5631),"I",(AllCalls25!$K$15:$K$5631),"9") -> 8 | AI18: =COUNTIFS((AllCalls25!$AL$15:$AL$5631),"I",(AllCalls25!$K$15:$K$5631),"10") -> 16 | AJ18: =COUNTIFS((AllCalls25!$AL$15:$AL$5631),"I",(AllCalls25!$K$15:$K$5631),"11") -> 16 | AK18: =COUNTIFS((AllCalls25!$AL$15:$AL$5631),"I",(AllCalls25!$K$15:$K$5631),"12") -> 12 | AL18: =SUM($Z18:$AK18) -> 219 | AM18: =(SUM($AL18))/SUM($AL$2) -> 0.33588957 | AN18: =SUM($J18,$X18,$AL18) -> 612 | AO18: =(SUM(AN18))/SUM($AN$2) -> 0.39869707
A19: QFF Ian Chapman | B19: 9 | C19: 23 | D19: 11 | E19: 14 | F19: 10 | G19: 23 | H19: 21 | I19: 23 | J19: =SUM($B19:$I19) -> 134 | K19: =(J19/$J$2) -> 0.41358025 | L19: 12 | M19: 23 | N19: 24 | O19: 16 | P19: 30 | Q19: 19 | R19: 22 | S19: 16 | T19: 20 | U19: 20 | V19: 25 | W19: 26 | X19: 253 | Y19: 0.4382786 | Z19: =COUNTIFS((AllCalls25!$AM$15:$AM$5631),"I",(AllCalls25!$K$15:$K$5631),"1") -> 22 | AA19: =COUNTIFS((AllCalls25!$AM$15:$AM$5631),"I",(AllCalls25!$K$15:$K$5631),"2") -> 27 | AB19: =COUNTIFS((AllCalls25!$AM$15:$AM$5631),"I",(AllCalls25!$K$15:$K$5631),"3") -> 33 | AC19: =COUNTIFS((AllCalls25!$AM$15:$AM$5631),"I",(AllCalls25!$K$15:$K$5631),"4") -> 16 | AD19: =COUNTIFS((AllCalls25!$AM$15:$AM$5631),"I",(AllCalls25!$K$15:$K$5631),"5") -> 32 | AE19: =COUNTIFS((AllCalls25!$AM$15:$AM$5631),"I",(AllCalls25!$K$15:$K$5631),"6") -> 19 | AF19: =COUNTIFS((AllCalls25!$AM$15:$AM$5631),"I",(AllCalls25!$K$15:$K$5631),"7") -> 25 | AG19: =COUNTIFS((AllCalls25!$AM$15:$AM$5631),"I",(AllCalls25!$K$15:$K$5631),"8") -> 12 | AH19: =COUNTIFS((AllCalls25!$AM$15:$AM$5631),"I",(AllCalls25!$K$15:$K$5631),"9") -> 16 | AI19: =COUNTIFS((AllCalls25!$AM$15:$AM$5631),"I",(AllCalls25!$K$15:$K$5631),"10") -> 17 | AJ19: =COUNTIFS((AllCalls25!$AM$15:$AM$5631),"I",(AllCalls25!$K$15:$K$5631),"11") -> 23 | AK19: =COUNTIFS((AllCalls25!$AM$15:$AM$5631),"I",(AllCalls25!$K$15:$K$5631),"12") -> 48 | AL19: =SUM($Z19:$AK19) -> 290 | AM19: =(SUM($AL19))/SUM($AL$2) -> 0.44478528 | AN19: =SUM($J19,$X19,$AL19) -> 677 | AO19: =(SUM(AN19))/SUM($AN$2) -> 0.44104235 | AP19: DR
A20: QFF Melanie Yates | B20: 1 | C20: 3 | D20: 8 | E20: 7 | F20: 11 | G20: 10 | H20: 15 | I20: 11 | J20: =SUM($B20:$I20) -> 66 | K20: =(J20/$J$2) -> 0.2037037 | L20: 14 | M20: 9 | N20: 7 | O20: 8 | P20: 5 | Q20: 11 | R20: 11 | S20: 9 | T20: 7 | U20: 6 | V20: 13 | W20: 14 | X20: 114 | Y20: 0.20385051 | Z20: =COUNTIFS((AllCalls25!$AN$15:$AN$5631),"I",(AllCalls25!$K$15:$K$5631),"1") -> 5 | AA20: =COUNTIFS((AllCalls25!$AN$15:$AN$5631),"I",(AllCalls25!$K$15:$K$5631),"2") -> 7 | AB20: =COUNTIFS((AllCalls25!$AN$15:$AN$5631),"I",(AllCalls25!$K$15:$K$5631),"3") -> 13 | AC20: =COUNTIFS((AllCalls25!$AN$15:$AN$5631),"I",(AllCalls25!$K$15:$K$5631),"4") -> 9 | AD20: =COUNTIFS((AllCalls25!$AN$15:$AN$5631),"I",(AllCalls25!$K$15:$K$5631),"5") -> 14 | AE20: =COUNTIFS((AllCalls25!$AN$15:$AN$5631),"I",(AllCalls25!$K$15:$K$5631),"6") -> 4 | AF20: =COUNTIFS((AllCalls25!$AN$15:$AN$5631),"I",(AllCalls25!$K$15:$K$5631),"7") -> 7 | AG20: =COUNTIFS((AllCalls25!$AN$15:$AN$5631),"I",(AllCalls25!$K$15:$K$5631),"8") -> 10 | AH20: =COUNTIFS((AllCalls25!$AN$15:$AN$5631),"I",(AllCalls25!$K$15:$K$5631),"9") -> 8 | AI20: =COUNTIFS((AllCalls25!$AN$15:$AN$5631),"I",(AllCalls25!$K$15:$K$5631),"10") -> 5 | AJ20: =COUNTIFS((AllCalls25!$AN$15:$AN$5631),"I",(AllCalls25!$K$15:$K$5631),"11") -> 16 | AK20: =COUNTIFS((AllCalls25!$AN$15:$AN$5631),"I",(AllCalls25!$K$15:$K$5631),"12") -> 27 | AL20: =SUM($Z20:$AK20) -> 125 | AM20: =(SUM($AL20))/SUM($AL$2) -> 0.19171779 | AN20: =SUM($J20,$X20,$AL20) -> 305 | AO20: =(SUM(AN20))/SUM($AN$2) -> 0.19869707 | AP20: DR
A21: QFF Maree Primrose | B21: 14 | C21: 34 | D21: 25 | E21: 11 | F21: 23 | G21: 24 | H21: 21 | I21: 28 | J21: =SUM($B21:$I21) -> 180 | K21: =(J21/$J$2) -> 0.55555556 | L21: 35 | M21: 33 | N21: 29 | O21: 22 | P21: 19 | Q21: 21 | R21: 14 | S21: 5 | T21: 11 | U21: 12 | V21: 13 | W21: 20 | X21: 234 | Y21: 0.46885617 | Z21: =COUNTIFS((AllCalls25!$AO$15:$AO$5631),"I",(AllCalls25!$K$15:$K$5631),"1") -> 27 | AA21: =COUNTIFS((AllCalls25!$AO$15:$AO$5631),"I",(AllCalls25!$K$15:$K$5631),"2") -> 14 | AB21: =COUNTIFS((AllCalls25!$AO$15:$AO$5631),"I",(AllCalls25!$K$15:$K$5631),"3") -> 26 | AC21: =COUNTIFS((AllCalls25!$AO$15:$AO$5631),"I",(AllCalls25!$K$15:$K$5631),"4") -> 12 | AD21: =COUNTIFS((AllCalls25!$AO$15:$AO$5631),"I",(AllCalls25!$K$15:$K$5631),"5") -> 26 | AE21: =COUNTIFS((AllCalls25!$AO$15:$AO$5631),"I",(AllCalls25!$K$15:$K$5631),"6") -> 7 | AF21: =COUNTIFS((AllCalls25!$AO$15:$AO$5631),"I",(AllCalls25!$K$15:$K$5631),"7") -> 13 | AG21: =COUNTIFS((AllCalls25!$AO$15:$AO$5631),"I",(AllCalls25!$K$15:$K$5631),"8") -> 15 | AH21: =COUNTIFS((AllCalls25!$AO$15:$AO$5631),"I",(AllCalls25!$K$15:$K$5631),"9") -> 14 | AI21: =COUNTIFS((AllCalls25!$AO$15:$AO$5631),"I",(AllCalls25!$K$15:$K$5631),"10") -> 10 | AJ21: =COUNTIFS((AllCalls25!$AO$15:$AO$5631),"I",(AllCalls25!$K$15:$K$5631),"11") -> 17 | AK21: =COUNTIFS((AllCalls25!$AO$15:$AO$5631),"I",(AllCalls25!$K$15:$K$5631),"12") -> 42 | AL21: =SUM($Z21:$AK21) -> 223 | AM21: =(SUM($AL21))/SUM($AL$2) -> 0.34202454 | AN21: =SUM($J21,$X21,$AL21) -> 637 | AO21: =(SUM(AN21))/SUM($AN$2) -> 0.41498371
A22: QFF Russell Clarke | B22: 2 | C22: 11 | D22: 9 | E22: 8 | F22: 12 | G22: 21 | H22: 17 | I22: 16 | J22: =SUM($B22:$I22) -> 96 | K22: =(J22/$J$2) -> 0.2962963 | L22: 20 | M22: 16 | N22: 13 | O22: 13 | P22: 16 | Q22: 10 | R22: 10 | S22: 10 | T22: 3 | U22: 7 | V22: 9 | W22: 15 | X22: 142 | Y22: 0.26953567 | Z22: =COUNTIFS((AllCalls25!$AP$15:$AP$5631),"I",(AllCalls25!$K$15:$K$5631),"1") -> 11 | AA22: =COUNTIFS((AllCalls25!$AP$15:$AP$5631),"I",(AllCalls25!$K$15:$K$5631),"2") -> 7 | AB22: =COUNTIFS((AllCalls25!$AP$15:$AP$5631),"I",(AllCalls25!$K$15:$K$5631),"3") -> 12 | AC22: =COUNTIFS((AllCalls25!$AP$15:$AP$5631),"I",(AllCalls25!$K$15:$K$5631),"4") -> 4 | AD22: =COUNTIFS((AllCalls25!$AP$15:$AP$5631),"I",(AllCalls25!$K$15:$K$5631),"5") -> 13 | AE22: =COUNTIFS((AllCalls25!$AP$15:$AP$5631),"I",(AllCalls25!$K$15:$K$5631),"6") -> 6 | AF22: =COUNTIFS((AllCalls25!$AP$15:$AP$5631),"I",(AllCalls25!$K$15:$K$5631),"7") -> 3 | AG22: =COUNTIFS((AllCalls25!$AP$15:$AP$5631),"I",(AllCalls25!$K$15:$K$5631),"8") -> 12 | AH22: =COUNTIFS((AllCalls25!$AP$15:$AP$5631),"I",(AllCalls25!$K$15:$K$5631),"9") -> 12 | AI22: =COUNTIFS((AllCalls25!$AP$15:$AP$5631),"I",(AllCalls25!$K$15:$K$5631),"10") -> 5 | AJ22: =COUNTIFS((AllCalls25!$AP$15:$AP$5631),"I",(AllCalls25!$K$15:$K$5631),"11") -> 16 | AK22: =COUNTIFS((AllCalls25!$AP$15:$AP$5631),"I",(AllCalls25!$K$15:$K$5631),"12") -> 25 | AL22: =SUM($Z22:$AK22) -> 126 | AM22: =(SUM($AL22))/SUM($AL$2) -> 0.19325153 | AN22: =SUM($J22,$X22,$AL22) -> 364 | AO22: =(SUM(AN22))/SUM($AN$2) -> 0.23713355
A23: QFF Andrew Bond | B23: 1 | C23: 14 | D23: 14 | E23: 9 | F23: 4 | G23: 14 | H23: 16 | I23: 17 | J23: =SUM($B23:$I23) -> 89 | K23: =(J23/$J$2) -> 0.27469136 | L23: 26 | M23: 12 | N23: 13 | O23: 6 | P23: 18 | Q23: 9 | R23: 11 | S23: 9 | T23: 13 | U23: 11 | V23: 11 | W23: 14 | X23: 153 | Y23: 0.27406569 | Z23: =COUNTIFS((AllCalls25!$AQ$15:$AQ$5631),"I",(AllCalls25!$K$15:$K$5631),"1") -> 15 | AA23: =COUNTIFS((AllCalls25!$AQ$15:$AQ$5631),"I",(AllCalls25!$K$15:$K$5631),"2") -> 10 | AB23: =COUNTIFS((AllCalls25!$AQ$15:$AQ$5631),"I",(AllCalls25!$K$15:$K$5631),"3") -> 20 | AC23: =COUNTIFS((AllCalls25!$AQ$15:$AQ$5631),"I",(AllCalls25!$K$15:$K$5631),"4") -> 0 | AD23: =COUNTIFS((AllCalls25!$AQ$15:$AQ$5631),"I",(AllCalls25!$K$15:$K$5631),"5") -> 5 | AE23: =COUNTIFS((AllCalls25!$AQ$15:$AQ$5631),"I",(AllCalls25!$K$15:$K$5631),"6") -> 4 | AF23: =COUNTIFS((AllCalls25!$AQ$15:$AQ$5631),"I",(AllCalls25!$K$15:$K$5631),"7") -> 0 | AG23: =COUNTIFS((AllCalls25!$AQ$15:$AQ$5631),"I",(AllCalls25!$K$15:$K$5631),"8") -> 0 | AH23: =COUNTIFS((AllCalls25!$AQ$15:$AQ$5631),"I",(AllCalls25!$K$15:$K$5631),"9") -> 0 | AI23: =COUNTIFS((AllCalls25!$AQ$15:$AQ$5631),"I",(AllCalls25!$K$15:$K$5631),"10") -> 0 | AJ23: =COUNTIFS((AllCalls25!$AQ$15:$AQ$5631),"I",(AllCalls25!$K$15:$K$5631),"11") -> 0 | AK23: =COUNTIFS((AllCalls25!$AQ$15:$AQ$5631),"I",(AllCalls25!$K$15:$K$5631),"12") -> 0 | AL23: =SUM($Z23:$AK23) -> 54 | AM23: =(SUM($AL23))/SUM($AL$2) -> 0.082822086 | AN23: =SUM($J23,$X23,$AL23) -> 296 | AO23: =(SUM(AN23))/SUM($AN$2) -> 0.19283388
A24: QFF Alan Binnie | B24: 0 | C24: 0 | D24: 0 | E24: 0 | F24: 5 | G24: 3 | H24: 3 | I24: 7 | J24: =SUM($B24:$I24) -> 18 | K24: =(J24/$J$2) -> 0.055555556 | L24: 9 | M24: 2 | N24: 8 | O24: 10 | P24: 10 | Q24: 6 | R24: 3 | S24: 6 | T24: 9 | U24: 13 | V24: 8 | W24: 16 | X24: 100 | Y24: 0.16164384 | Z24: =COUNTIFS((AllCalls25!$AR$15:$AR$5631),"I",(AllCalls25!$K$15:$K$5631),"1") -> 21 | AA24: =COUNTIFS((AllCalls25!$AR$15:$AR$5631),"I",(AllCalls25!$K$15:$K$5631),"2") -> 16 | AB24: =COUNTIFS((AllCalls25!$AR$15:$AR$5631),"I",(AllCalls25!$K$15:$K$5631),"3") -> 28 | AC24: =COUNTIFS((AllCalls25!$AR$15:$AR$5631),"I",(AllCalls25!$K$15:$K$5631),"4") -> 8 | AD24: =COUNTIFS((AllCalls25!$AR$15:$AR$5631),"I",(AllCalls25!$K$15:$K$5631),"5") -> 6 | AE24: =COUNTIFS((AllCalls25!$AR$15:$AR$5631),"I",(AllCalls25!$K$15:$K$5631),"6") -> 3 | AF24: =COUNTIFS((AllCalls25!$AR$15:$AR$5631),"I",(AllCalls25!$K$15:$K$5631),"7") -> 3 | AG24: =COUNTIFS((AllCalls25!$AR$15:$AR$5631),"I",(AllCalls25!$K$15:$K$5631),"8") -> 5 | AH24: =COUNTIFS((AllCalls25!$AR$15:$AR$5631),"I",(AllCalls25!$K$15:$K$5631),"9") -> 7 | AI24: =COUNTIFS((AllCalls25!$AR$15:$AR$5631),"I",(AllCalls25!$K$15:$K$5631),"10") -> 1 | AJ24: =COUNTIFS((AllCalls25!$AR$15:$AR$5631),"I",(AllCalls25!$K$15:$K$5631),"11") -> 5 | AK24: =COUNTIFS((AllCalls25!$AR$15:$AR$5631),"I",(AllCalls25!$K$15:$K$5631),"12") -> 37 | AL24: =SUM($Z24:$AK24) -> 140 | AM24: =(SUM($AL24))/SUM($AL$2) -> 0.21472393 | AN24: =SUM($J24,$X24,$AL24) -> 258 | AO24: =(SUM(AN24))/SUM($AL$2,$X$2,$F$2:$I$2) -> 0.18668596 | AP24: DR
A25: QFF Josh Pennefather | B25: 12 | C25: 20 | D25: 13 | E25: 15 | F25: 17 | G25: 27 | H25: 16 | I25: 17 | J25: =SUM($B25:$I25) -> 137 | K25: =(J25/$J$2) -> 0.42283951 | L25: 26 | M25: 15 | N25: 14 | O25: 14 | P25: 21 | Q25: 8 | R25: 25 | S25: 7 | T25: 7 | U25: 13 | V25: 16 | W25: 25 | X25: 191 | Y25: 0.37146093 | Z25: =COUNTIFS((AllCalls25!$AS$15:$AS$5631),"I",(AllCalls25!$K$15:$K$5631),"1") -> 27 | AA25: =COUNTIFS((AllCalls25!$AS$15:$AS$5631),"I",(AllCalls25!$K$15:$K$5631),"2") -> 16 | AB25: =COUNTIFS((AllCalls25!$AS$15:$AS$5631),"I",(AllCalls25!$K$15:$K$5631),"3") -> 20 | AC25: =COUNTIFS((AllCalls25!$AS$15:$AS$5631),"I",(AllCalls25!$K$15:$K$5631),"4") -> 21 | AD25: =COUNTIFS((AllCalls25!$AS$15:$AS$5631),"I",(AllCalls25!$K$15:$K$5631),"5") -> 29 | AE25: =COUNTIFS((AllCalls25!$AS$15:$AS$5631),"I",(AllCalls25!$K$15:$K$5631),"6") -> 10 | AF25: =COUNTIFS((AllCalls25!$AS$15:$AS$5631),"I",(AllCalls25!$K$15:$K$5631),"7") -> 22 | AG25: =COUNTIFS((AllCalls25!$AS$15:$AS$5631),"I",(AllCalls25!$K$15:$K$5631),"8") -> 15 | AH25: =COUNTIFS((AllCalls25!$AS$15:$AS$5631),"I",(AllCalls25!$K$15:$K$5631),"9") -> 6 | AI25: =COUNTIFS((AllCalls25!$AS$15:$AS$5631),"I",(AllCalls25!$K$15:$K$5631),"10") -> 13 | AJ25: =COUNTIFS((AllCalls25!$AS$15:$AS$5631),"I",(AllCalls25!$K$15:$K$5631),"11") -> 36 | AK25: =COUNTIFS((AllCalls25!$AS$15:$AS$5631),"I",(AllCalls25!$K$15:$K$5631),"12") -> 41 | AL25: =SUM($Z25:$AK25) -> 256 | AM25: =(SUM($AL25))/SUM($AL$2) -> 0.39263804 | AN25: =SUM($J25,$X25,$AL25) -> 584 | AO25: =(SUM(AN25))/SUM($AN$2) -> 0.38045603 | AP25: DR
A26: QFF Ben Killgour | B26: 8 | C26: 21 | D26: 18 | E26: 10 | F26: 13 | G26: 20 | H26: 9 | I26: 10 | J26: =SUM($B26:$I26) -> 109 | K26: =(J26/$J$2) -> 0.33641975 | L26: 14 | M26: 26 | N26: 24 | O26: 19 | P26: 22 | Q26: 18 | R26: 21 | S26: 20 | T26: 19 | U26: 13 | V26: 16 | W26: 19 | X26: 231 | Y26: 0.38505096 | Z26: =COUNTIFS((AllCalls25!$AT$15:$AT$5631),"I",(AllCalls25!$K$15:$K$5631),"1") -> 16 | AA26: =COUNTIFS((AllCalls25!$AT$15:$AT$5631),"I",(AllCalls25!$K$15:$K$5631),"2") -> 15 | AB26: =COUNTIFS((AllCalls25!$AT$15:$AT$5631),"I",(AllCalls25!$K$15:$K$5631),"3") -> 27 | AC26: =COUNTIFS((AllCalls25!$AT$15:$AT$5631),"I",(AllCalls25!$K$15:$K$5631),"4") -> 16 | AD26: =COUNTIFS((AllCalls25!$AT$15:$AT$5631),"I",(AllCalls25!$K$15:$K$5631),"5") -> 24 | AE26: =COUNTIFS((AllCalls25!$AT$15:$AT$5631),"I",(AllCalls25!$K$15:$K$5631),"6") -> 10 | AF26: =COUNTIFS((AllCalls25!$AT$15:$AT$5631),"I",(AllCalls25!$K$15:$K$5631),"7") -> 13 | AG26: =COUNTIFS((AllCalls25!$AT$15:$AT$5631),"I",(AllCalls25!$K$15:$K$5631),"8") -> 18 | AH26: =COUNTIFS((AllCalls25!$AT$15:$AT$5631),"I",(AllCalls25!$K$15:$K$5631),"9") -> 20 | AI26: =COUNTIFS((AllCalls25!$AT$15:$AT$5631),"I",(AllCalls25!$K$15:$K$5631),"10") -> 14 | AJ26: =COUNTIFS((AllCalls25!$AT$15:$AT$5631),"I",(AllCalls25!$K$15:$K$5631),"11") -> 10 | AK26: =COUNTIFS((AllCalls25!$AT$15:$AT$5631),"I",(AllCalls25!$K$15:$K$5631),"12") -> 11 | AL26: =SUM($Z26:$AK26) -> 194 | AM26: =(SUM($AL26))/SUM($AL$2) -> 0.29754601 | AN26: =SUM($J26,$X26,$AL26) -> 534 | AO26: =(SUM(AN26))/SUM($AN$2) -> 0.34788274
A27: QFF Dallas Steele | B27: 0 | C27: 6 | D27: 5 | E27: 6 | F27: 11 | G27: 14 | H27: 20 | I27: 16 | J27: =SUM($B27:$I27) -> 78 | K27: =(J27/$J$2) -> 0.24074074 | L27: 17 | M27: 19 | N27: 13 | O27: 10 | P27: 6 | Q27: 5 | R27: 12 | S27: 16 | T27: 12 | U27: 9 | V27: 15 | W27: 6 | X27: 140 | Y27: 0.24688562 | Z27: =COUNTIFS((AllCalls25!$AU$15:$AU$5631),"I",(AllCalls25!$K$15:$K$5631),"1") -> 9 | AA27: =COUNTIFS((AllCalls25!$AU$15:$AU$5631),"I",(AllCalls25!$K$15:$K$5631),"2") -> 11 | AB27: =COUNTIFS((AllCalls25!$AU$15:$AU$5631),"I",(AllCalls25!$K$15:$K$5631),"3") -> 13 | AC27: =COUNTIFS((AllCalls25!$AU$15:$AU$5631),"I",(AllCalls25!$K$15:$K$5631),"4") -> 10 | AD27: =COUNTIFS((AllCalls25!$AU$15:$AU$5631),"I",(AllCalls25!$K$15:$K$5631),"5") -> 13 | AE27: =COUNTIFS((AllCalls25!$AU$15:$AU$5631),"I",(AllCalls25!$K$15:$K$5631),"6") -> 8 | AF27: =COUNTIFS((AllCalls25!$AU$15:$AU$5631),"I",(AllCalls25!$K$15:$K$5631),"7") -> 7 | AG27: =COUNTIFS((AllCalls25!$AU$15:$AU$5631),"I",(AllCalls25!$K$15:$K$5631),"8") -> 9 | AH27: =COUNTIFS((AllCalls25!$AU$15:$AU$5631),"I",(AllCalls25!$K$15:$K$5631),"9") -> 4 | AI27: =COUNTIFS((AllCalls25!$AU$15:$AU$5631),"I",(AllCalls25!$K$15:$K$5631),"10") -> 5 | AJ27: =COUNTIFS((AllCalls25!$AU$15:$AU$5631),"I",(AllCalls25!$K$15:$K$5631),"11") -> 9 | AK27: =COUNTIFS((AllCalls25!$AU$15:$AU$5631),"I",(AllCalls25!$K$15:$K$5631),"12") -> 14 | AL27: =SUM($Z27:$AK27) -> 112 | AM27: =(SUM($AL27))/SUM($AL$2) -> 0.17177914 | AN27: =SUM($J27,$X27,$AL27) -> 330 | AO27: =(SUM(AN27))/SUM($AN$2) -> 0.21498371
A28: QFF Nick Grayson | B28: 0 | C28: 16 | D28: 20 | E28: 16 | F28: 17 | G28: 26 | H28: 21 | I28: 18 | J28: =SUM($B28:$I28) -> 134 | K28: =(J28/$J$2) -> 0.41358025 | L28: 21 | M28: 20 | N28: 22 | O28: 19 | P28: 24 | Q28: 26 | R28: 19 | S28: 29 | T28: 10 | U28: 24 | V28: 23 | W28: 25 | X28: 262 | Y28: 0.44847112 | Z28: =COUNTIFS((AllCalls25!$AV$15:$AV$5631),"I",(AllCalls25!$K$15:$K$5631),"1") -> 21 | AA28: =COUNTIFS((AllCalls25!$AV$15:$AV$5631),"I",(AllCalls25!$K$15:$K$5631),"2") -> 19 | AB28: =COUNTIFS((AllCalls25!$AV$15:$AV$5631),"I",(AllCalls25!$K$15:$K$5631),"3") -> 0 | AC28: =COUNTIFS((AllCalls25!$AV$15:$AV$5631),"I",(AllCalls25!$K$15:$K$5631),"4") -> 0 | AD28: =COUNTIFS((AllCalls25!$AV$15:$AV$5631),"I",(AllCalls25!$K$15:$K$5631),"5") -> 0 | AE28: =COUNTIFS((AllCalls25!$AV$15:$AV$5631),"I",(AllCalls25!$K$15:$K$5631),"6") -> 0 | AF28: =COUNTIFS((AllCalls25!$AV$15:$AV$5631),"I",(AllCalls25!$K$15:$K$5631),"7") -> 1 | AG28: =COUNTIFS((AllCalls25!$AV$15:$AV$5631),"I",(AllCalls25!$K$15:$K$5631),"8") -> 29 | AH28: =COUNTIFS((AllCalls25!$AV$15:$AV$5631),"I",(AllCalls25!$K$15:$K$5631),"9") -> 25 | AI28: =COUNTIFS((AllCalls25!$AV$15:$AV$5631),"I",(AllCalls25!$K$15:$K$5631),"10") -> 17 | AJ28: =COUNTIFS((AllCalls25!$AV$15:$AV$5631),"I",(AllCalls25!$K$15:$K$5631),"11") -> 18 | AK28: =COUNTIFS((AllCalls25!$AV$15:$AV$5631),"I",(AllCalls25!$K$15:$K$5631),"12") -> 54 | AL28: =SUM($Z28:$AK28) -> 184 | AM28: =(SUM($AL28))/SUM($AL$2) -> 0.28220859 | AN28: =SUM($J28,$X28,$AL28) -> 580 | AO28: =(SUM(AN28))/SUM($AN$2) -> 0.37785016
A29: QFF Jason Court | B29: 0 | C29: 14 | D29: 12 | E29: 6 | F29: 13 | G29: 8 | H29: 14 | I29: 10 | J29: =SUM($B29:$I29) -> 77 | K29: =(J29/$J$2) -> 0.23765432 | L29: 0 | M29: 7 | N29: 6 | O29: 19 | P29: 25 | Q29: 17 | R29: 19 | S29: 7 | T29: 15 | U29: 16 | V29: 25 | W29: 9 | X29: 165 | Y29: 0.27406569 | Z29: =COUNTIFS((AllCalls25!$AW$15:$AW$5631),"I",(AllCalls25!$K$15:$K$5631),"1") -> 0 | AA29: =COUNTIFS((AllCalls25!$AW$15:$AW$5631),"I",(AllCalls25!$K$15:$K$5631),"2") -> 15 | AB29: =COUNTIFS((AllCalls25!$AW$15:$AW$5631),"I",(AllCalls25!$K$15:$K$5631),"3") -> 36 | AC29: =COUNTIFS((AllCalls25!$AW$15:$AW$5631),"I",(AllCalls25!$K$15:$K$5631),"4") -> 27 | AD29: =COUNTIFS((AllCalls25!$AW$15:$AW$5631),"I",(AllCalls25!$K$15:$K$5631),"5") -> 29 | AE29: =COUNTIFS((AllCalls25!$AW$15:$AW$5631),"I",(AllCalls25!$K$15:$K$5631),"6") -> 19 | AF29: =COUNTIFS((AllCalls25!$AW$15:$AW$5631),"I",(AllCalls25!$K$15:$K$5631),"7") -> 17 | AG29: =COUNTIFS((AllCalls25!$AW$15:$AW$5631),"I",(AllCalls25!$K$15:$K$5631),"8") -> 12 | AH29: =COUNTIFS((AllCalls25!$AW$15:$AW$5631),"I",(AllCalls25!$K$15:$K$5631),"9") -> 30 | AI29: =COUNTIFS((AllCalls25!$AW$15:$AW$5631),"I",(AllCalls25!$K$15:$K$5631),"10") -> 16 | AJ29: =COUNTIFS((AllCalls25!$AW$15:$AW$5631),"I",(AllCalls25!$K$15:$K$5631),"11") -> 14 | AK29: =COUNTIFS((AllCalls25!$AW$15:$AW$5631),"I",(AllCalls25!$K$15:$K$5631),"12") -> 17 | AL29: =SUM($Z29:$AK29) -> 232 | AM29: =(SUM($AL29))/SUM($AL$2) -> 0.35582822 | AN29: =SUM($J29,$X29,$AL29) -> 474 | AO29: =(SUM(AN29))/SUM($AN$2) -> 0.30879479
A30: QFF Crystal McConchie | C30: 0 | D30: 1 | E30: 1 | F30: 0 | G30: 4 | H30: 7 | I30: 6 | J30: =SUM($B30:$I30) -> 19 | K30: =(J30/$J$2) -> 0.058641975 | L30: 12 | M30: 10 | N30: 3 | O30: 4 | P30: 12 | Q30: 8 | R30: 14 | S30: 16 | T30: 9 | U30: 15 | V30: 11 | W30: 12 | X30: 126 | Y30: 0.16421291 | Z30: =COUNTIFS((AllCalls25!$AX$15:$AX$5631),"I",(AllCalls25!$K$15:$K$5631),"1") -> 12 | AA30: =COUNTIFS((AllCalls25!$AX$15:$AX$5631),"I",(AllCalls25!$K$15:$K$5631),"2") -> 20 | AB30: =COUNTIFS((AllCalls25!$AX$15:$AX$5631),"I",(AllCalls25!$K$15:$K$5631),"3") -> 19 | AC30: =COUNTIFS((AllCalls25!$AX$15:$AX$5631),"I",(AllCalls25!$K$15:$K$5631),"4") -> 7 | AD30: =COUNTIFS((AllCalls25!$AX$15:$AX$5631),"I",(AllCalls25!$K$15:$K$5631),"5") -> 19 | AE30: =COUNTIFS((AllCalls25!$AX$15:$AX$5631),"I",(AllCalls25!$K$15:$K$5631),"6") -> 5 | AF30: =COUNTIFS((AllCalls25!$AX$15:$AX$5631),"I",(AllCalls25!$K$15:$K$5631),"7") -> 11 | AG30: =COUNTIFS((AllCalls25!$AX$15:$AX$5631),"I",(AllCalls25!$K$15:$K$5631),"8") -> 6 | AH30: =COUNTIFS((AllCalls25!$AX$15:$AX$5631),"I",(AllCalls25!$K$15:$K$5631),"9") -> 18 | AI30: =COUNTIFS((AllCalls25!$AX$15:$AX$5631),"I",(AllCalls25!$K$15:$K$5631),"10") -> 12 | AJ30: =COUNTIFS((AllCalls25!$AX$15:$AX$5631),"I",(AllCalls25!$K$15:$K$5631),"11") -> 12 | AK30: =COUNTIFS((AllCalls25!$AX$15:$AX$5631),"I",(AllCalls25!$K$15:$K$5631),"12") -> 39 | AL30: =SUM($Z30:$AK30) -> 180 | AM30: =(SUM($AL30))/SUM($AL$2) -> 0.27607362 | AN30: =SUM($J30,$X30,$AL30) -> 325 | AO30: =(SUM(AN30))/SUM($AN$2) -> 0.21172638
A31: FF Jimmy Doyle | B31: 9 | C31: 13 | D31: 12 | E31: 0 | F31: 0 | G31: 10 | H31: 11 | I31: 15 | J31: =SUM($B31:$I31) -> 70 | K31: =(J31/$J$2) -> 0.21604938 | L31: 24 | M31: 16 | N31: 16 | O31: 14 | P31: 20 | Q31: 19 | R31: 17 | S31: 0 | T31: 0 | U31: 8 | V31: 9 | W31: 2 | X31: 145 | Y31: 0.24348811 | Z31: =COUNTIFS((AllCalls25!$AY$15:$AY$5631),"I",(AllCalls25!$K$15:$K$5631),"1") -> 1 | AA31: =COUNTIFS((AllCalls25!$AY$15:$AY$5631),"I",(AllCalls25!$K$15:$K$5631),"2") -> 0 | AB31: =COUNTIFS((AllCalls25!$AY$15:$AY$5631),"I",(AllCalls25!$K$15:$K$5631),"3") -> 9 | AC31: =COUNTIFS((AllCalls25!$AY$15:$AY$5631),"I",(AllCalls25!$K$15:$K$5631),"4") -> 7 | AD31: =COUNTIFS((AllCalls25!$AY$15:$AY$5631),"I",(AllCalls25!$K$15:$K$5631),"5") -> 4 | AE31: =COUNTIFS((AllCalls25!$AY$15:$AY$5631),"I",(AllCalls25!$K$15:$K$5631),"6") -> 6 | AF31: =COUNTIFS((AllCalls25!$AY$15:$AY$5631),"I",(AllCalls25!$K$15:$K$5631),"7") -> 13 | AG31: =COUNTIFS((AllCalls25!$AY$15:$AY$5631),"I",(AllCalls25!$K$15:$K$5631),"8") -> 14 | AH31: =COUNTIFS((AllCalls25!$AY$15:$AY$5631),"I",(AllCalls25!$K$15:$K$5631),"9") -> 18 | AI31: =COUNTIFS((AllCalls25!$AY$15:$AY$5631),"I",(AllCalls25!$K$15:$K$5631),"10") -> 7 | AJ31: =COUNTIFS((AllCalls25!$AY$15:$AY$5631),"I",(AllCalls25!$K$15:$K$5631),"11") -> 19 | AK31: =COUNTIFS((AllCalls25!$AY$15:$AY$5631),"I",(AllCalls25!$K$15:$K$5631),"12") -> 37 | AL31: =SUM($Z31:$AK31) -> 135 | AM31: =(SUM($AL31))/SUM($AL$2) -> 0.20705521 | AN31: =SUM($J31,$X31,$AL31) -> 350 | AO31: =(SUM(AN31))/SUM($AN$2) -> 0.22801303
A32: FF Dimmy Bell-Kainiu | B32: 6 | C32: 24 | D32: 31 | E32: 18 | F32: 21 | G32: 25 | H32: 27 | I32: 21 | J32: =SUM($B32:$I32) -> 173 | K32: =(J32/$J$2) -> 0.53395062 | L32: 21 | M32: 14 | N32: 13 | O32: 9 | P32: 8 | Q32: 3 | R32: 6 | S32: 7 | T32: 5 | U32: 8 | V32: 5 | W32: 8 | X32: 107 | Y32: 0.31710079 | Z32: =COUNTIFS((AllCalls25!$AZ$15:$AZ$5631),"I",(AllCalls25!$K$15:$K$5631),"1") -> 2 | AA32: =COUNTIFS((AllCalls25!$AZ$15:$AZ$5631),"I",(AllCalls25!$K$15:$K$5631),"2") -> 9 | AB32: =COUNTIFS((AllCalls25!$AZ$15:$AZ$5631),"I",(AllCalls25!$K$15:$K$5631),"3") -> 21 | AC32: =COUNTIFS((AllCalls25!$AZ$15:$AZ$5631),"I",(AllCalls25!$K$15:$K$5631),"4") -> 15 | AD32: =COUNTIFS((AllCalls25!$AZ$15:$AZ$5631),"I",(AllCalls25!$K$15:$K$5631),"5") -> 34 | AE32: =COUNTIFS((AllCalls25!$AZ$15:$AZ$5631),"I",(AllCalls25!$K$15:$K$5631),"6") -> 7 | AF32: =COUNTIFS((AllCalls25!$AZ$15:$AZ$5631),"I",(AllCalls25!$K$15:$K$5631),"7") -> 17 | AG32: =COUNTIFS((AllCalls25!$AZ$15:$AZ$5631),"I",(AllCalls25!$K$15:$K$5631),"8") -> 15 | AH32: =COUNTIFS((AllCalls25!$AZ$15:$AZ$5631),"I",(AllCalls25!$K$15:$K$5631),"9") -> 16 | AI32: =COUNTIFS((AllCalls25!$AZ$15:$AZ$5631),"I",(AllCalls25!$K$15:$K$5631),"10") -> 4 | AJ32: =COUNTIFS((AllCalls25!$AZ$15:$AZ$5631),"I",(AllCalls25!$K$15:$K$5631),"11") -> 23 | AK32: =COUNTIFS((AllCalls25!$AZ$15:$AZ$5631),"I",(AllCalls25!$K$15:$K$5631),"12") -> 44 | AL32: =SUM($Z32:$AK32) -> 207 | AM32: =(SUM($AL32))/SUM($AL$2) -> 0.31748466 | AN32: =SUM($J32,$X32,$AL32) -> 487 | AO32: =(SUM(AN32))/SUM($AN$2) -> 0.31726384
A33: FF Mitch Court | B33: 0 | C33: 6 | D33: 5 | E33: 3 | F33: 10 | G33: 8 | H33: 5 | I33: 3 | J33: =SUM($B33:$I33) -> 40 | K33: =(J33/$J$2) -> 0.12345679 | L33: 6 | M33: 10 | N33: 3 | O33: 6 | P33: 0 | Q33: 0 | R33: 0 | S33: 2 | T33: 0 | U33: 0 | V33: 0 | W33: 2 | X33: 29 | Y33: 0.078142695 | Z33: =COUNTIFS((AllCalls25!$BA$15:$BA$5631),"I",(AllCalls25!$K$15:$K$5631),"1") -> 5 | AA33: =COUNTIFS((AllCalls25!$BA$15:$BA$5631),"I",(AllCalls25!$K$15:$K$5631),"2") -> 8 | AB33: =COUNTIFS((AllCalls25!$BA$15:$BA$5631),"I",(AllCalls25!$K$15:$K$5631),"3") -> 18 | AC33: =COUNTIFS((AllCalls25!$BA$15:$BA$5631),"I",(AllCalls25!$K$15:$K$5631),"4") -> 8 | AD33: =COUNTIFS((AllCalls25!$BA$15:$BA$5631),"I",(AllCalls25!$K$15:$K$5631),"5") -> 0 | AE33: =COUNTIFS((AllCalls25!$BA$15:$BA$5631),"I",(AllCalls25!$K$15:$K$5631),"6") -> 11 | AF33: =COUNTIFS((AllCalls25!$BA$15:$BA$5631),"I",(AllCalls25!$K$15:$K$5631),"7") -> 17 | AG33: =COUNTIFS((AllCalls25!$BA$15:$BA$5631),"I",(AllCalls25!$K$15:$K$5631),"8") -> 12 | AH33: =COUNTIFS((AllCalls25!$BA$15:$BA$5631),"I",(AllCalls25!$K$15:$K$5631),"9") -> 18 | AI33: =COUNTIFS((AllCalls25!$BA$15:$BA$5631),"I",(AllCalls25!$K$15:$K$5631),"10") -> 9 | AJ33: =COUNTIFS((AllCalls25!$BA$15:$BA$5631),"I",(AllCalls25!$K$15:$K$5631),"11") -> 15 | AK33: =COUNTIFS((AllCalls25!$BA$15:$BA$5631),"I",(AllCalls25!$K$15:$K$5631),"12") -> 11 | AL33: =SUM($Z33:$AK33) -> 132 | AM33: =(SUM($AL33))/SUM($AL$2) -> 0.20245399 | AN33: =SUM($J33,$X33,$AL33) -> 201 | AO33: =(SUM(AN33))/SUM($AN$2) -> 0.13094463 | AP33: *
A34: FF Jamie O'Hare | F34: 2 | G34: 2 | H34: 7 | I34: 2 | J34: =SUM($B34:$I34) -> 13 | K34: =(J34/$J$2) -> 0.040123457 | L34: 8 | M34: 2 | N34: 0 | O34: 2 | P34: 3 | Q34: 0 | R34: 1 | S34: 7 | T34: 11 | U34: 7 | V34: 12 | W34: 9 | X34: 62 | Y34: 0.10273973 | Z34: =COUNTIFS((AllCalls25!$BB$15:$BB$5631),"I",(AllCalls25!$K$15:$K$5631),"1") -> 14 | AA34: =COUNTIFS((AllCalls25!$BB$15:$BB$5631),"I",(AllCalls25!$K$15:$K$5631),"2") -> 10 | AB34: =COUNTIFS((AllCalls25!$BB$15:$BB$5631),"I",(AllCalls25!$K$15:$K$5631),"3") -> 6 | AC34: =COUNTIFS((AllCalls25!$BB$15:$BB$5631),"I",(AllCalls25!$K$15:$K$5631),"4") -> 8 | AD34: =COUNTIFS((AllCalls25!$BB$15:$BB$5631),"I",(AllCalls25!$K$15:$K$5631),"5") -> 5 | AE34: =COUNTIFS((AllCalls25!$BB$15:$BB$5631),"I",(AllCalls25!$K$15:$K$5631),"6") -> 2 | AF34: =COUNTIFS((AllCalls25!$BB$15:$BB$5631),"I",(AllCalls25!$K$15:$K$5631),"7") -> 11 | AG34: =COUNTIFS((AllCalls25!$BB$15:$BB$5631),"I",(AllCalls25!$K$15:$K$5631),"8") -> 9 | AH34: =COUNTIFS((AllCalls25!$BB$15:$BB$5631),"I",(AllCalls25!$K$15:$K$5631),"9") -> 4 | AI34: =COUNTIFS((AllCalls25!$BB$15:$BB$5631),"I",(AllCalls25!$K$15:$K$5631),"10") -> 8 | AJ34: =COUNTIFS((AllCalls25!$BB$15:$BB$5631),"I",(AllCalls25!$K$15:$K$5631),"11") -> 6 | AK34: =COUNTIFS((AllCalls25!$BB$15:$BB$5631),"I",(AllCalls25!$K$15:$K$5631),"12") -> 24 | AL34: =SUM($Z34:$AK34) -> 107 | AM34: =(SUM($AL34))/SUM($AL$2) -> 0.16411043 | AN34: =SUM($J34,$X34,$AL34) -> 182 | AO34: =(SUM(AN34))/SUM($AN$2) -> 0.11856678 | AP34: *
A35: FF Kaitlyn Evans | J35: 0 | N35: - | O35: 3 | P35: 0 | Q35: 2 | R35: 2 | S35: 1 | T35: 3 | U35: 10 | V35: 11 | W35: 12 | X35: 44 | Y35: 0.10837438 | Z35: =COUNTIFS((AllCalls25!$BC$15:$BC$5631),"I",(AllCalls25!$K$15:$K$5631),"1") -> 4 | AA35: =COUNTIFS((AllCalls25!$BC$15:$BC$5631),"I",(AllCalls25!$K$15:$K$5631),"2") -> 3 | AB35: =COUNTIFS((AllCalls25!$BC$15:$BC$5631),"I",(AllCalls25!$K$15:$K$5631),"3") -> 13 | AC35: =COUNTIFS((AllCalls25!$BC$15:$BC$5631),"I",(AllCalls25!$K$15:$K$5631),"4") -> 5 | AD35: =COUNTIFS((AllCalls25!$BC$15:$BC$5631),"I",(AllCalls25!$K$15:$K$5631),"5") -> 3 | AE35: =COUNTIFS((AllCalls25!$BC$15:$BC$5631),"I",(AllCalls25!$K$15:$K$5631),"6") -> 2 | AF35: =COUNTIFS((AllCalls25!$BC$15:$BC$5631),"I",(AllCalls25!$K$15:$K$5631),"7") -> 9 | AG35: =COUNTIFS((AllCalls25!$BC$15:$BC$5631),"I",(AllCalls25!$K$15:$K$5631),"8") -> 9 | AH35: =COUNTIFS((AllCalls25!$BC$15:$BC$5631),"I",(AllCalls25!$K$15:$K$5631),"9") -> 11 | AI35: =COUNTIFS((AllCalls25!$BC$15:$BC$5631),"I",(AllCalls25!$K$15:$K$5631),"10") -> 6 | AJ35: =COUNTIFS((AllCalls25!$BC$15:$BC$5631),"I",(AllCalls25!$K$15:$K$5631),"11") -> 7 | AK35: =COUNTIFS((AllCalls25!$BC$15:$BC$5631),"I",(AllCalls25!$K$15:$K$5631),"12") -> 10 | AL35: =SUM($Z35:$AK35) -> 82 | AM35: =(SUM($AL35))/SUM($AL$2) -> 0.12576687 | AN35: =SUM($J35,$X35,$AL35) -> 126 | AO35: =(SUM(AN35))/SUM($AN$2) -> 0.082084691 | AP35: *
A36: FF Jaime Moore | U36: 0 | V36: 9 | W36: 17 | X36: 26 | Y36: 0.18439716 | Z36: =COUNTIFS((AllCalls25!$BD$15:$BD$5631),"I",(AllCalls25!$K$15:$K$5631),"1") -> 7 | AA36: =COUNTIFS((AllCalls25!$BD$15:$BD$5631),"I",(AllCalls25!$K$15:$K$5631),"2") -> 12 | AB36: =COUNTIFS((AllCalls25!$BD$15:$BD$5631),"I",(AllCalls25!$K$15:$K$5631),"3") -> 18 | AC36: =COUNTIFS((AllCalls25!$BD$15:$BD$5631),"I",(AllCalls25!$K$15:$K$5631),"4") -> 16 | AD36: =COUNTIFS((AllCalls25!$BD$15:$BD$5631),"I",(AllCalls25!$K$15:$K$5631),"5") -> 21 | AE36: =COUNTIFS((AllCalls25!$BD$15:$BD$5631),"I",(AllCalls25!$K$15:$K$5631),"6") -> 7 | AF36: =COUNTIFS((AllCalls25!$BD$15:$BD$5631),"I",(AllCalls25!$K$15:$K$5631),"7") -> 18 | AG36: =COUNTIFS((AllCalls25!$BD$15:$BD$5631),"I",(AllCalls25!$K$15:$K$5631),"8") -> 9 | AH36: =COUNTIFS((AllCalls25!$BD$15:$BD$5631),"I",(AllCalls25!$K$15:$K$5631),"9") -> 8 | AI36: =COUNTIFS((AllCalls25!$BD$15:$BD$5631),"I",(AllCalls25!$K$15:$K$5631),"10") -> 13 | AJ36: =COUNTIFS((AllCalls25!$BD$15:$BD$5631),"I",(AllCalls25!$K$15:$K$5631),"11") -> 15 | AK36: =COUNTIFS((AllCalls25!$BD$15:$BD$5631),"I",(AllCalls25!$K$15:$K$5631),"12") -> 9 | AL36: =SUM($Z36:$AK36) -> 153 | AM36: =(SUM($AL36))/SUM($AL$2) -> 0.23466258 | AN36: =SUM($J36,$X36,$AL36) -> 179 | AO36: =(SUM(AN36,X36))/SUM($AL$2,$V$2:$W$2) -> 0.27296937
A37: FF Torrens Butcher | U37: 0 | V37: 3 | W37: 9 | X37: 12 | Y37: 0.085106383 | Z37: =COUNTIFS((AllCalls25!$BE$15:$BE$5631),"I",(AllCalls25!$K$15:$K$5631),"1") -> 5 | AA37: =COUNTIFS((AllCalls25!$BE$15:$BE$5631),"I",(AllCalls25!$K$15:$K$5631),"2") -> 8 | AB37: =COUNTIFS((AllCalls25!$BE$15:$BE$5631),"I",(AllCalls25!$K$15:$K$5631),"3") -> 15 | AC37: =COUNTIFS((AllCalls25!$BE$15:$BE$5631),"I",(AllCalls25!$K$15:$K$5631),"4") -> 17 | AD37: =COUNTIFS((AllCalls25!$BE$15:$BE$5631),"I",(AllCalls25!$K$15:$K$5631),"5") -> 30 | AE37: =COUNTIFS((AllCalls25!$BE$15:$BE$5631),"I",(AllCalls25!$K$15:$K$5631),"6") -> 11 | AF37: =COUNTIFS((AllCalls25!$BE$15:$BE$5631),"I",(AllCalls25!$K$15:$K$5631),"7") -> 22 | AG37: =COUNTIFS((AllCalls25!$BE$15:$BE$5631),"I",(AllCalls25!$K$15:$K$5631),"8") -> 14 | AH37: =COUNTIFS((AllCalls25!$BE$15:$BE$5631),"I",(AllCalls25!$K$15:$K$5631),"9") -> 22 | AI37: =COUNTIFS((AllCalls25!$BE$15:$BE$5631),"I",(AllCalls25!$K$15:$K$5631),"10") -> 9 | AJ37: =COUNTIFS((AllCalls25!$BE$15:$BE$5631),"I",(AllCalls25!$K$15:$K$5631),"11") -> 6 | AK37: =COUNTIFS((AllCalls25!$BE$15:$BE$5631),"I",(AllCalls25!$K$15:$K$5631),"12") -> 34 | AL37: =SUM($Z37:$AK37) -> 193 | AM37: =(SUM($AL37))/SUM($AL$2) -> 0.29601227 | AN37: =SUM($J37,$X37,$AL37) -> 205 | AO37: =(SUM(AN37,X37))/SUM($AL$2,$V$2:$W$2) -> 0.28894807
A38: FF Matt Humber | U38: 0 | V38: 7 | W38: 15 | X38: 22 | Y38: 0.15602837 | Z38: =COUNTIFS((AllCalls25!$BF$15:$BF$5631),"I",(AllCalls25!$K$15:$K$5631),"1") -> 21 | AA38: =COUNTIFS((AllCalls25!$BF$15:$BF$5631),"I",(AllCalls25!$K$15:$K$5631),"2") -> 24 | AB38: =COUNTIFS((AllCalls25!$BF$15:$BF$5631),"I",(AllCalls25!$K$15:$K$5631),"3") -> 29 | AC38: =COUNTIFS((AllCalls25!$BF$15:$BF$5631),"I",(AllCalls25!$K$15:$K$5631),"4") -> 18 | AD38: =COUNTIFS((AllCalls25!$BF$15:$BF$5631),"I",(AllCalls25!$K$15:$K$5631),"5") -> 39 | AE38: =COUNTIFS((AllCalls25!$BF$15:$BF$5631),"I",(AllCalls25!$K$15:$K$5631),"6") -> 16 | AF38: =COUNTIFS((AllCalls25!$BF$15:$BF$5631),"I",(AllCalls25!$K$15:$K$5631),"7") -> 11 | AG38: =COUNTIFS((AllCalls25!$BF$15:$BF$5631),"I",(AllCalls25!$K$15:$K$5631),"8") -> 27 | AH38: =COUNTIFS((AllCalls25!$BF$15:$BF$5631),"I",(AllCalls25!$K$15:$K$5631),"9") -> 23 | AI38: =COUNTIFS((AllCalls25!$BF$15:$BF$5631),"I",(AllCalls25!$K$15:$K$5631),"10") -> 19 | AJ38: =COUNTIFS((AllCalls25!$BF$15:$BF$5631),"I",(AllCalls25!$K$15:$K$5631),"11") -> 18 | AK38: =COUNTIFS((AllCalls25!$BF$15:$BF$5631),"I",(AllCalls25!$K$15:$K$5631),"12") -> 42 | AL38: =SUM($Z38:$AK38) -> 287 | AM38: =(SUM($AL38))/SUM($AL$2) -> 0.44018405 | AN38: =SUM($J38,$X38,$AL38) -> 309 | AO38: =(SUM(AN38,X38))/SUM($AL$2,$V$2:$W$2) -> 0.44074567
A39: RFF Leone Humber | H39: 0 | I39: 2 | J39: =SUM($B39:$I39) -> 2 | K39: =(J39/$J$2) -> 0.0061728395 | L39: 2 | M39: 20 | N39: 21 | O39: 8 | P39: 9 | Q39: 0 | R39: 1 | S39: 0 | T39: 0 | U39: 0 | V39: 0 | W39: 9 | X39: 70 | Y39: 0.10404624 | Z39: =COUNTIFS((AllCalls25!$BG$15:$BG$5631),"I",(AllCalls25!$K$15:$K$5631),"1") -> 15 | AA39: =COUNTIFS((AllCalls25!$BG$15:$BG$5631),"I",(AllCalls25!$K$15:$K$5631),"2") -> 12 | AB39: =COUNTIFS((AllCalls25!$BG$15:$BG$5631),"I",(AllCalls25!$K$15:$K$5631),"3") -> 12 | AC39: =COUNTIFS((AllCalls25!$BG$15:$BG$5631),"I",(AllCalls25!$K$15:$K$5631),"4") -> 10 | AD39: =COUNTIFS((AllCalls25!$BG$15:$BG$5631),"I",(AllCalls25!$K$15:$K$5631),"5") -> 15 | AE39: =COUNTIFS((AllCalls25!$BG$15:$BG$5631),"I",(AllCalls25!$K$15:$K$5631),"6") -> 6 | AF39: =COUNTIFS((AllCalls25!$BG$15:$BG$5631),"I",(AllCalls25!$K$15:$K$5631),"7") -> 8 | AG39: =COUNTIFS((AllCalls25!$BG$15:$BG$5631),"I",(AllCalls25!$K$15:$K$5631),"8") -> 0 | AH39: =COUNTIFS((AllCalls25!$BG$15:$BG$5631),"I",(AllCalls25!$K$15:$K$5631),"9") -> 0 | AI39: =COUNTIFS((AllCalls25!$BG$15:$BG$5631),"I",(AllCalls25!$K$15:$K$5631),"10") -> 0 | AJ39: =COUNTIFS((AllCalls25!$BG$15:$BG$5631),"I",(AllCalls25!$K$15:$K$5631),"11") -> 0 | AK39: =COUNTIFS((AllCalls25!$BG$15:$BG$5631),"I",(AllCalls25!$K$15:$K$5631),"12") -> 0 | AL39: =SUM($Z39:$AK39) -> 78 | AM39: =(SUM($AL39))/SUM($AL$2) -> 0.1196319 | AN39: =SUM($J39,$X39,$AL39) -> 150 | AO39: =(SUM(AN39))/SUM($AN$2) -> 0.09771987
A40: RFF Joel Robbins | AE40: =COUNTIFS((AllCalls25!$BH$15:$BH$5631),"I",(AllCalls25!$K$15:$K$5631),"6") -> 1 | AF40: =COUNTIFS((AllCalls25!$BH$15:$BH$5631),"I",(AllCalls25!$K$15:$K$5631),"7") -> 0 | AG40: =COUNTIFS((AllCalls25!$BH$15:$BH$5631),"I",(AllCalls25!$K$15:$K$5631),"8") -> 2 | AH40: =COUNTIFS((AllCalls25!$BH$15:$BH$5631),"I",(AllCalls25!$K$15:$K$5631),"9") -> 20 | AI40: =COUNTIFS((AllCalls25!$BH$15:$BH$5631),"I",(AllCalls25!$K$15:$K$5631),"10") -> 25 | AJ40: =COUNTIFS((AllCalls25!$BH$15:$BH$5631),"I",(AllCalls25!$K$15:$K$5631),"11") -> 35 | AK40: =COUNTIFS((AllCalls25!$BH$15:$BH$5631),"I",(AllCalls25!$K$15:$K$5631),"12") -> 56 | AL40: =SUM($Z40:$AK40) -> 139 | AM40: =(SUM($AE40:$AK40))/SUM($AE$2:$AK$2) -> 0.37874659 | AN40: =SUM($J40,$X40,$AL40) -> 139 | AO40: =(SUM(AN40,X40))/SUM($AL$2,$V$2:$W$2) -> 0.18508655
...

Sheet Musters
A1: Musters | B1: 3 | C1: 4 | D1: 4 | E1: 5 | F1: 4 | G1: 4 | H1: 4 | I1: 2 | J1: =SUM(B1:I1) -> 30 | K1: 2023 | L1: 3 | M1: 4 | N1: 4 | O1: 5 | P1: 4 | Q1: 4 | R1: 5 | S1: 5 | T1: 5 | U1: 4 | V1: 4 | W1: 3 | X1: 50 | Y1: 2024 | Z1: =AllMusters25!$E$3 -> 3 | AA1: =AllMusters25!$E$4 -> 4 | AB1: =AllMusters25!$E$5 -> 5 | AC1: =AllMusters25!$E$6 -> 4 | AD1: =AllMusters25!$E$7 -> 4 | AE1: =AllMusters25!$E$8 -> 5 | AF1: =AllMusters25!$E$9 -> 4 | AG1: =AllMusters25!$E$10 -> 4 | AH1: =AllMusters25!$E$11 -> 5 | AI1: =AllMusters25!$E$12 -> 4 | AJ1: =AllMusters25!$E$13 -> 4 | AK1: =AllMusters25!$E$14 -> 3 | AL1: =SUM(Z1:AK1) -> 49 | AM1: 2025 | AN1: Total Musters | AO1: Total
A2: Monthly Call Count | B2: 32 | C2: 46 | D2: 47 | E2: 28 | F2: 38 | G2: 46 | H2: 43 | I2: 44 | J2: =SUM(B2:I2) -> 324 | L2: 58 | M2: 48 | N2: 47 | O2: 38 | P2: 55 | Q2: 43 | R2: 44 | S2: 49 | T2: 36 | U2: 42 | V2: 47 | W2: 52 | X2: 559 | Z2: =Summary!Z2 -> 57 | AA2: =Summary!AA2 -> 48 | AB2: =Summary!AB2 -> 70 | AC2: =Summary!AC2 -> 42 | AD2: =Summary!AD2 -> 68 | AE2: =Summary!AE2 -> 35 | AF2: =Summary!AF2 -> 56 | AG2: =Summary!AG2 -> 53 | ... AK2: =Summary!AK2 -> 79 | AL2: =SUM(Z2:AK2) -> 652 | AN2: =SUM(AL1,X1,J1) -> 129 | AO2: Average
A3: Month | B3: May | C3: June | D3: July | E3: August | F3: September | G3: October | H3: November | I3: December | J3: Sum | K3: Totals | L3: January | M3: Febuary | N3: March | O3: April | P3: May | Q3: June | R3: July | S3: August | T3: September | U3: October | V3: Novober | W3: December | X3: Sum | Y3: Totals | Z3: January | AA3: Febuary | AB3: March | AC3: April | AD3: May | AE3: June | AF3: July | AG3: August | AH3: September | AI3: October | AJ3: Novober | AK3: December | AL3: Sum | AM3: Totals | AN3: Total Musters
A4: CFO John Robinson | B4: 3 | C4: 4 | D4: 4 | E4: 5 | F4: 4 | G4: 4 | H4: 4 | I4: 2 | J4: =SUM(B4:I4) -> 30 | K4: 1 | L4: 3 | M4: 4 | N4: 4 | O4: 5 | P4: 4 | Q4: 4 | R4: 5 | S4: 5 | T4: 5 | U4: 4 | V4: 4 | W4: 3 | X4: 50 | Y4: 1 | Z4: =COUNTIFS(AllMusters25!$J$15:$J$147,"I",(AllMusters25!$F$15:$F$147),"1") -> 3 | AA4: =COUNTIFS(AllMusters25!$J$15:$J$147,"I",(AllMusters25!$F$15:$F$147),"2") -> 4 | AB4: =COUNTIFS(AllMusters25!$J$15:$J$147,"I",(AllMusters25!$F$15:$F$147),"3") -> 5 | AC4: =COUNTIFS(AllMusters25!$J$15:$J$147,"I",(AllMusters25!$F$15:$F$147),"4") -> 3 | AD4: =COUNTIFS(AllMusters25!$J$15:$J$147,"I",(AllMusters25!$F$15:$F$147),"5") -> 4 | AE4: =COUNTIFS(AllMusters25!$J$15:$J$147,"I",(AllMusters25!$F$15:$F$147),"6") -> 5 | AF4: =COUNTIFS(AllMusters25!$J$15:$J$147,"I",(AllMusters25!$F$15:$F$147),"7") -> 4 | AG4: =COUNTIFS(AllMusters25!$J$15:$J$147,"I",(AllMusters25!$F$15:$F$147),"8") -> 3 | AH4: =COUNTIFS(AllMusters25!$J$15:$J$147,"I",(AllMusters25!$F$15:$F$147),"9") -> 5 | AI4: =COUNTIFS(AllMusters25!$J$15:$J$147,"I",(AllMusters25!$F$15:$F$147),"10") -> 3 | AJ4: =COUNTIFS(AllMusters25!$J$15:$J$147,"I",(AllMusters25!$F$15:$F$147),"11") -> 3 | AK4: =COUNTIFS(AllMusters25!$J$15:$J$147,"I",(AllMusters25!$F$15:$F$147),"12") -> 3 | AL4: =(SUM($Z4:$AK4)) -> 45 | AM4: =(SUM(AL4))/SUM($AL$1) -> 0.91836735 | AN4: =SUM(J4,X4,AL4) -> 125 | AO4: =(SUM(AN4))/SUM($AN$2) -> 0.96899225
